Workbook

Sheet GCF_2024
A1: 45382 | D1: Veiklos laikotarpis, metais | E1: Strategija | F1: Grynųjų aktyvų vertė, mln. Eur [6] | G1: Dalyvių skaičius | I1: Grąža | P1: Rizika [3] | S1: Išlaidų rodikliai (2023 m.)
A2: Pensijų kaupimo bendrovės pavadinimas | B2: Fondo kodas | C2: Pensijų fondo pavadinimas | E2: rizikingų aktyvų dalis fonde, proc. [5] | I2: vieneto vertės pokytis nuo metų pradžios, proc. [1] | J2: vidutinis metinis vieneto vertės pokytis [10] per praėjusius 3 metus, proc. | K2: vidutinis metinis vieneto vertės pokytis [10] per praėjusius 4 metus, proc. | L2: lyginamojo indekso vertės pokytis nuo metų pradžios, proc. [2] | M2: vidutinis lyginamojo indekso vertės pokytis [10] per praėjusius 3 metus, proc. | N2: vidutinis lyginamojo indekso vertės pokytis [10] per praėjusius 4 metus, proc. | P2: vieneto vertės standartinis nuokrypis, per praėjusius 3 metus, proc. | Q2: lyginamojo indekso standartinis nuokrypis, per praėjusius 3 metus, proc. | S2: BAR, proc. [8] | T2: Sąlyginis BIK, proc. [9] | U2: Tikėtinas sąlyginis BIK, proc. [9]
A3: Tikslinės pensijų fondų dalyvių grupės pensijų fondai, 1996-2002 | G3: Svertinis vidurkis [4]: | I3: 9.0110159 | J3: 7.9482267 | K3: 14.56622 | L3: 10.301576 | M3: 8.8862377 | N3: 16.217609
A4: Luminor investicijų valdymas UAB | B4: LMN-96/02 | C4: Luminor 1996–2002 tikslinės grupės pensijų fondas | D4: 5 m. 3 mėn. | E4: 90 | F4: 17.964447 | G4: 14666 | I4: 9.3551729 | J4: 5.3357527 | K4: 13.503407 | L4: 9.3137391 | M4: 7.3169505 | N4: 14.888145 | P4: 11.018596 | Q4: 11.916672 | S4: 0.49 | T4: 0.7 | U4: -
A5: UAB „SB Asset Management“ | B5: INV-96/02 | C5: INVL pensija 1996–2002 Index Plus | D5: 5 m. 3 mėn. | E5: 97 | F5: 39.140957 | G5: 19859 | I5: 8.4422422 | J5: 7.5337095 | K5: 14.692618 | L5: 10.532328 | M5: 8.4953354 | N5: 16.782549 | P5: 10.539487 | Q5: 12.892925 | S5: 0.5 | T5: - | U5: 1.2
A6: UAB „SEB investicijų valdymas“ | B6: SBN-96/02 | C6: SEB 1996–2002 metų tikslinės grupės pensijų kaupimo fondas | D6: 5 m. 3 mėn. | E6: 98 | F6: 48.911384 | G6: 21723 | I6: 8.4727969 | J6: 7.0704201 | K6: 14.459195 | L6: 10.762943 | M6: 9.963111 | N6: 17.556549 | P6: 11.84815 | Q6: 13.470594 | S6: 0.5 | T6: - | U6: 0.89
A7: UAB „Swedbank investicijų valdymas“ | B7: SWD-96/02 | C7: Swedbank pensija 1996–2002 [7] | D7: 5 m. 3 mėn. | E7: 97 | F7: 114.85712 | G7: 49488 | I7: 8.6797912 | J7: 8.7683209 | K7: 14.711747 | L7: 10.189152 | M7: 8.8112656 | N7: 15.907326 | P7: 13.122368 | Q7: 13.255328 | S7: 0.5 | T7: - | U7: 0.8413
A8: Allianz Lietuva gyvybės draudimas UAB | B8: AVI-96/02 | C8: Allianz Y3 1996–2002 tikslinės grupės pensijų fondas | D8: 5 m. 3 mėn. | E8: 90 | F8: 39.886673 | G8: 20316 | I8: 10.714975 | J8: 8.2465053 | K8: 14.633044 | L8: 10.278026 | M8: 8.8719815 | N8: 15.513608 | P8: 11.869462 | Q8: 13.043972 | S8: 0.5 | T8: 1.11 | U8: -
A9: Goindex, UAB [11] | B9: GOX-96/02 | C9: Goindex pensija 1996–2002 tikslinės grupės pensijų fondas | D9: 1 m. 8 mėn. | E9: 100 | F9: 10.36854 | G9: 5820 | I9: 10.214951 | J9: Veikia trumpiau | K9: Veikia trumpiau | L9: 10.193305 | M9: Veikia trumpiau | N9: Veikia trumpiau | P9: Veikia trumpiau | Q9: Veikia trumpiau | S9: 0.44 | T9: 0.57 | U9: -
A10: Tikslinės pensijų fondų dalyvių grupės pensijų fondai, 1989-1995 | G10: Svertinis vidurkis [4]: | I10: 8.6104816 | J10: 7.9523501 | K10: 14.69681 | L10: 10.316087 | M10: 8.9039091 | N10: 16.272016
A11: Luminor investicijų valdymas UAB | B11: LMN-89/95 | C11: Luminor 1989–1995 tikslinės grupės pensijų fondas | D11: 5 m. 3 mėn. | E11: 90 | F11: 60.414197 | G11: 18922 | I11: 9.4199596 | J11: 5.3723646 | K11: 13.377642 | L11: 9.3137391 | M11: 7.3169505 | N11: 14.888145 | P11: 10.943007 | Q11: 11.916672 | S11: 0.49 | T11: 0.71 | U11: -
A12: UAB „SB Asset Management“ | B12: INV-89/95 | C12: INVL pensija 1989–1995 Index Plus | D12: 5 m. 3 mėn. | E12: 97 | F12: 146.24354 | G12: 36626 | I12: 8.1441264 | J12: 7.6409375 | K12: 14.83333 | L12: 10.532328 | M12: 8.4953354 | N12: 16.782549 | P12: 10.240636 | Q12: 12.892925 | S12: 0.5 | T12: - | U12: 1.37
A13: UAB „SEB investicijų valdymas“ | B13: SBN-89/95 | C13: SEB 1989–1995 metų tikslinės grupės pensijų kaupimo fondas | D13: 5 m. 3 mėn. | E13: 98 | F13: 184.13743 | G13: 46062 | I13: 8.286264 | J13: 6.8928547 | K13: 14.402024 | L13: 10.762943 | M13: 9.963111 | N13: 17.556549 | P13: 11.799116 | Q13: 13.470594 | S13: 0.5 | T13: - | U13: 0.88
A14: UAB „Swedbank investicijų valdymas“ | B14: SWD-89/95 | C14: Swedbank pensija 1989–1995 [7] | D14: 5 m. 3 mėn. | E14: 97 | F14: 385.96674 | G14: 95911 | I14: 8.3343684 | J14: 8.8546465 | K14: 14.952957 | L14: 10.189152 | M14: 8.8112656 | N14: 15.907326 | P14: 12.776216 | Q14: 13.255328 | S14: 0.5 | T14: - | U14: 0.8223
A15: Allianz Lietuva gyvybės draudimas UAB | B15: AVI-89/95 | C15: Allianz Y2 1989–1995 tikslinės grupės pensijų fondas | D15: 5 m. 3 mėn. | E15: 90 | F15: 114.4883 | G15: 33894 | I15: 10.03871 | J15: 8.3737571 | K15: 14.829122 | L15: 10.278026 | M15: 8.8719815 | N15: 15.513608 | P15: 11.732258 | Q15: 13.043972 | S15: 0.5 | T15: 0.94 | U15: -
A16: Goindex, UAB | B16: GOX-89/95 | C16: Goindex pensija 1989–1995 tikslinės grupės pensijų fondas | D16: 1 m. 8 mėn. | E16: 100 | F16: 13.813249 | G16: 4333 | I16: 10.207002 | J16: Veikia trumpiau | K16: Veikia trumpiau | L16: 10.193305 | M16: Veikia trumpiau | N16: Veikia trumpiau | P16: Veikia trumpiau | Q16: Veikia trumpiau | S16: 0.44 | T16: 0.56 | U16: -
A17: Tikslinės pensijų fondų dalyvių grupės pensijų fondai, 1982-1988 | G17: Svertinis vidurkis [4]: | I17: 8.5770439 | J17: 7.8543104 | K17: 14.725251 | L17: 10.343093 | M17: 8.9575176 | N17: 16.363271
A18: Luminor investicijų valdymas UAB | B18: LMN-82/88 | C18: Luminor 1982–1988 tikslinės grupės pensijų fondas | D18: 5 m. 3 mėn. | E18: 90 | F18: 117.31882 | G18: 26132 | I18: 9.4285341 | J18: 5.5212436 | K18: 13.322932 | L18: 9.3137391 | M18: 7.3169505 | N18: 14.888145 | P18: 10.883094 | Q18: 11.916672 | S18: 0.49 | T18: 0.72 | U18: -
A19: UAB „SB Asset Management“ | B19: INV-82/88 | C19: INVL pensija 1982–1988 Index Plus | D19: 5 m. 3 mėn. | E19: 97 | F19: 253.84621 | G19: 44292 | I19: 8.0577493 | J19: 7.7350641 | K19: 14.867413 | L19: 10.532328 | M19: 8.4953354 | N19: 16.782549 | P19: 10.174667 | Q19: 12.892925 | S19: 0.5 | T19: - | U19: 1.38
A20: UAB „SEB investicijų valdymas“ | B20: SBN-82/88 | C20: SEB 1982–1988 metų tikslinės grupės pensijų kaupimo fondas | D20: 5 m. 3 mėn. | E20: 98 | F20: 404.37064 | G20: 73986 | I20: 8.2377735 | J20: 6.8457942 | K20: 14.40298 | L20: 10.762943 | M20: 9.963111 | N20: 17.556549 | P20: 11.741186 | Q20: 13.470594 | S20: 0.5 | T20: - | U20: 0.88
A21: UAB „Swedbank investicijų valdymas“ | B21: SWD-82/88 | C21: Swedbank pensija 1982–1988 [7] | D21: 5 m. 3 mėn. | E21: 97 | F21: 547.78486 | G21: 113847 | I21: 8.2984487 | J21: 9.0033483 | K21: 15.18448 | L21: 10.189152 | M21: 8.8112656 | N21: 15.907326 | P21: 12.734842 | Q21: 13.255328 | S21: 0.5 | T21: - | U21: 0.8251
A22: Allianz Lietuva gyvybės draudimas UAB | B22: AVI-82/88 | C22: Allianz Y1 1982–1988 tikslinės grupės pensijų fondas | D22: 5 m. 3 mėn. | E22: 90 | F22: 195.5342 | G22: 47768 | I22: 10.105182 | J22: 8.2755753 | K22: 14.762019 | L22: 10.278026 | M22: 8.8719815 | N22: 15.513608 | P22: 11.691745 | Q22: 13.043972 | S22: 0.5 | T22: 0.98 | U22: -
A23: Goindex, UAB | B23: GOX-82/88 | C23: Goindex pensija 1982–1988 tikslinės grupės pensijų fondas | D23: 1 m. 8 mėn. | E23: 100 | F23: 14.132639 | G23: 3162 | I23: 10.199052 | J23: Veikia trumpiau | K23: Veikia trumpiau | L23: 10.193305 | M23: Veikia trumpiau | N23: Veikia trumpiau | P23: Veikia trumpiau | Q23: Veikia trumpiau | S23: 0.44 | T23: 0.56 | U23: -
A24: Tikslinės pensijų fondų dalyvių grupės pensijų fondai, 1975-1981 | G24: Svertinis vidurkis [4]: | I24: 8.4923243 | J24: 7.8048319 | K24: 14.682711 | L24: 10.347139 | M24: 8.9885569 | N24: 16.370227
A25: Luminor investicijų valdymas UAB | B25: LMN-75/81 | C25: Luminor 1975–1981 tikslinės grupės pensijų fondas | D25: 5 m. 3 mėn. | E25: 90 | F25: 132.63731 | G25: 19508 | I25: 9.4129159 | J25: 5.6781453 | K25: 13.469468 | L25: 9.3137391 | M25: 7.3169505 | N25: 14.888145 | P25: 10.905829 | Q25: 11.916672 | S25: 0.49 | T25: 0.72 | U25: -
A26: UAB „SB Asset Management“ | B26: INV-75/81 | C26: INVL pensija 1975–1981 Index Plus | D26: 5 m. 3 mėn. | E26: 97 | F26: 255.68835 | G26: 27850 | I26: 7.9167178 | J26: 7.6956918 | K26: 14.815519 | L26: 10.532328 | M26: 8.4953354 | N26: 16.782549 | P26: 10.126082 | Q26: 12.892925 | S26: 0.5 | T26: - | U26: 1.39
A27: UAB „SEB investicijų valdymas“ | B27: SBN-75/81 | C27: SEB 1975–1981 metų tikslinės grupės pensijų kaupimo fondas | D27: 5 m. 3 mėn. | E27: 98 | F27: 505.11624 | G27: 62799 | I27: 8.18099 | J27: 6.8090969 | K27: 14.373634 | L27: 10.76314 | M27: 9.9630213 | N27: 17.556671 | P27: 11.72438 | Q27: 13.47069 | S27: 0.5 | T27: - | U27: 0.87
A28: UAB „Swedbank investicijų valdymas“ | B28: SWD-75/81 | C28: Swedbank pensija 1975–1981 [7] | D28: 5 m. 3 mėn. | E28: 97 | F28: 658.27323 | G28: 98543 | I28: 8.2402321 | J28: 8.9758873 | K28: 15.17346 | L28: 10.189152 | M28: 8.8112656 | N28: 15.907326 | P28: 12.609515 | Q28: 13.255328 | S28: 0.5 | T28: - | U28: 0.8308
A29: Allianz Lietuva gyvybės draudimas UAB | B29: AVI-75/81 | C29: Allianz X3 1975–1981 tikslinės grupės pensijų fondas | D29: 5 m. 3 mėn. | E29: 90 | F29: 237.47194 | G29: 39988 | I29: 9.8617271 | J29: 7.981995 | K29: 14.514425 | L29: 10.278026 | M29: 8.8719815 | N29: 15.513608 | P29: 11.744353 | Q29: 13.043972 | S29: 0.5 | T29: 0.99 | U29: -
A30: Goindex, UAB | B30: GOX-75/81 | C30: Goindex pensija 1975–1981 tikslinės grupės pensijų fondas | D30: 1 m. 8 mėn. | E30: 100 | F30: 13.299993 | G30: 1168 | I30: 10.227814 | J30: Veikia trumpiau | K30: Veikia trumpiau | L30: 10.193305 | M30: Veikia trumpiau | N30: Veikia trumpiau | P30: Veikia trumpiau | Q30: Veikia trumpiau | S30: 0.45 | T30: 0.57 | U30: -
A31: Tikslinės pensijų fondų dalyvių grupės pensijų fondai, 1968-1974 | G31: Svertinis vidurkis [4]: | I31: 6.4744884 | J31: 6.1724513 | K31: 12.755032 | L31: 7.4124211 | M31: 6.5195628 | N31: 13.640129
A32: Luminor investicijų valdymas UAB | B32: LMN-68/74 | C32: Luminor 1968–1974 tikslinės grupės pensijų fondas | D32: 5 m. 3 mėn. | E32: 70 | F32: 127.33494 | G32: 18136 | I32: 7.4022624 | J32: 4.5258464 | K32: 12.441957 | L32: 7.1692941 | M32: 5.6637984 | N32: 13.55155 | P32: 10.135718 | Q32: 11.193315 | S32: 0.49 | T32: 0.72 | U32: -
A33: UAB „SB Asset Management“ | B33: INV-68/74 | C33: INVL pensija 1968–1974 Index Plus | D33: 5 m. 3 mėn. | E33: 67.58 | F33: 206.05183 | G33: 23225 | I33: 5.6007345 | J33: 5.5890966 | K33: 12.035906 | L33: 7.3755919 | M33: 5.1068913 | N33: 12.883911 | P33: 8.4786355 | Q33: 11.327649 | S33: 0.5 | T33: - | U33: 1.23
A34: UAB „SEB investicijų valdymas“ | B34: SBN-68/74 | C34: SEB 1968–1974 metų tikslinės grupės pensijų kaupimo fondas | D34: 5 m. 3 mėn. | E34: 68.1 | F34: 441.73316 | G34: 53381 | I34: 6.0819545 | J34: 5.3733379 | K34: 12.416589 | L34: 7.5901578 | M34: 7.4217018 | N34: 14.466623 | P34: 10.232744 | Q34: 11.659738 | S34: 0.5 | T34: - | U34: 0.79
A35: UAB „Swedbank investicijų valdymas“ | B35: SWD-68/74 | C35: Swedbank pensija 1968–1974 [7] | D35: 5 m. 3 mėn. | E35: 70 | F35: 653.53135 | G35: 95871 | I35: 6.3253973 | J35: 7.2765453 | K35: 13.607163 | L35: 7.1908912 | M35: 6.3853493 | N35: 13.720486 | P35: 10.922329 | Q35: 11.900739 | S35: 0.5 | T35: - | U35: 0.7872
A36: Allianz Lietuva gyvybės draudimas UAB | B36: AVI-68/74 | C36: Allianz X2 1968–1974 tikslinės grupės pensijų fondas | D36: 5 m. 3 mėn. | E36: 70 | F36: 247.72351 | G36: 39466 | I36: 7.710198 | J36: 6.0162551 | K36: 11.869565 | L36: 7.8355212 | M36: 6.8798853 | N36: 12.628894 | P36: 10.389297 | Q36: 11.325991 | S36: 0.5 | T36: 0.87 | U36: -
A37: Goindex, UAB | B37: GOX-68/74 | C37: Goindex pensija 1968–1974 tikslinės grupės pensijų fondas | D37: 1 m. 8 mėn. | E37: 100 | F37: 7.2070003 | G37: 758 | I37: 10.167715 | J37: Veikia trumpiau | K37: Veikia trumpiau | L37: 10.193305 | M37: Veikia trumpiau | N37: Veikia trumpiau | P37: Veikia trumpiau | Q37: Veikia trumpiau | S37: 0.45 | T37: 0.57 | U37: -
A38: Tikslinės pensijų fondų dalyvių grupės pensijų fondai, 1961-1967 | G38: Svertinis vidurkis [4]: | I38: 3.7874461 | J38: 2.5910163 | K38: 7.2708112 | L38: 3.6306909 | M38: 2.0674013 | N38: 7.0667675
A39: Luminor investicijų valdymas UAB | B39: LMN-61/67 | C39: Luminor 1961–1967 tikslinės grupės pensijų fondas | D39: 5 m. 3 mėn. | E39: 35 | F39: 99.669389 | G39: 16476 | I39: 3.9173183 | J39: 1.2812437 | K39: 7.1555792 | L39: 3.7745682 | M39: 2.2013064 | N39: 7.6847714 | P39: 8.2441943 | Q39: 8.7639625 | S39: 0.49 | T39: 0.71 | U39: -
A40: UAB „SB Asset Management“ | B40: INV-61/67 | C40: INVL pensija 1961–1967 Index Plus | D40: 5 m. 3 mėn. | E40: 31.75 | F40: 127.96628 | G40: 17483 | I40: 3.407155 | J40: 2.515204 | K40: 7.2288752 | L40: 3.7729764 | M40: 0.27148396 | N40: 6.0313682 | P40: 6.5432902 | Q40: 9.1948908 | S40: 0.5 | T40: - | U40: 0.86
...

Sheet 1996-2002
A1: =+GCF_2024!A1 -> 45382 | C1: Grįžti į pagrindinį puslapį | D1: Veiklos laikotarpis, metais | E1: Strategija | F1: Grynųjų aktyvų vertė, mln. Eur [6] | G1: Dalyvių skaičius | I1: Grąža | J1: 0 | L1: 0 | M1: 0 | P1: Rizika [3] | Q1: 0 | S1: Išlaidų rodikliai (2023 m.) | T1: 0 | U1: 0
A2: =+GCF_2024!A2 -> Pensijų kaupimo bendrovės pavadinimas | B2: =+GCF_2024!B2 -> Fondo kodas | C2: =+GCF_2024!C2 -> Pensijų fondo pavadinimas | D2: 0 | E2: rizikingų aktyvų dalis fonde, proc. [5] | F2: 0 | G2: 0 | I2: vieneto vertės pokytis nuo metų pradžios, proc. [1] | J2: vidutinis metinis vieneto vertės pokytis [10] per praėjusius 3 metus, proc. | K2: vidutinis metinis vieneto vertės pokytis [10] per praėjusius 4 metus, proc. | L2: lyginamojo indekso vertės pokytis nuo metų pradžios, proc. [2] | M2: vidutinis lyginamojo indekso vertės pokytis [10] per praėjusius 3 metus, proc. | N2: vidutinis lyginamojo indekso vertės pokytis [10] per praėjusius 4 metus, proc. | P2: vieneto vertės standartinis nuokrypis, per praėjusius 3 metus, proc. | Q2: lyginamojo indekso standartinis nuokrypis, per praėjusius 3 metus, proc. | S2: BAR, proc. [8] | T2: Sąlyginis BIK, proc. [9] | U2: Tikėtinas sąlyginis BIK, proc. [9]
A3: =+GCF_2024!A3 -> Tikslinės pensijų fondų dalyvių grupės pensijų fondai, 1996-2002 | G3: Svertinis vidurkis [4]: | I3: 9.0110159 | J3: 7.9482267 | K3: 14.56622 | L3: 10.301576 | M3: 8.8862377 | N3: 16.217609
A4: =+GCF_2024!A4 -> Luminor investicijų valdymas UAB | B4: =+GCF_2024!B4 -> LMN-96/02 | C4: =+GCF_2024!C4 -> Luminor 1996–2002 tikslinės grupės pensijų fondas | D4: 5 m. 3 mėn. | E4: 90 | F4: 17.964447 | G4: 14666 | I4: 9.3551729 | J4: 5.3357527 | K4: 13.503407 | L4: 9.3137391 | M4: 7.3169505 | N4: 14.888145 | P4: 11.018596 | Q4: 11.916672 | S4: 0.49 | T4: 0.7 | U4: -
A5: =+GCF_2024!A5 -> UAB „SB Asset Management“ | B5: =+GCF_2024!B5 -> INV-96/02 | C5: =+GCF_2024!C5 -> INVL pensija 1996–2002 Index Plus | D5: 5 m. 3 mėn. | E5: 97 | F5: 39.140957 | G5: 19859 | I5: 8.4422422 | J5: 7.5337095 | K5: 14.692618 | L5: 10.532328 | M5: 8.4953354 | N5: 16.782549 | P5: 10.539487 | Q5: 12.892925 | S5: 0.5 | T5: 1.2 | U5: 1.2
A6: =+GCF_2024!A6 -> UAB „SEB investicijų valdymas“ | B6: =+GCF_2024!B6 -> SBN-96/02 | C6: =+GCF_2024!C6 -> SEB 1996–2002 metų tikslinės grupės pensijų kaupimo fondas | D6: 5 m. 3 mėn. | E6: 98 | F6: 48.911384 | G6: 21723 | I6: 8.4727969 | J6: 7.0704201 | K6: 14.459195 | L6: 10.762943 | M6: 9.963111 | N6: 17.556549 | P6: 11.84815 | Q6: 13.470594 | S6: 0.5 | T6: - | U6: 0.89
A7: =+GCF_2024!A7 -> UAB „Swedbank investicijų valdymas“ | B7: =+GCF_2024!B7 -> SWD-96/02 | C7: =+GCF_2024!C7 -> Swedbank pensija 1996–2002 [7] | D7: 5 m. 3 mėn. | E7: 97 | F7: 114.85712 | G7: 49488 | I7: 8.6797912 | J7: 8.7683209 | K7: 14.711747 | L7: 10.189152 | M7: 8.8112656 | N7: 15.907326 | P7: 13.122368 | Q7: 13.255328 | S7: 0.5 | T7: - | U7: 0.8413
A8: =+GCF_2024!A8 -> Allianz Lietuva gyvybės draudimas UAB | B8: =+GCF_2024!B8 -> AVI-96/02 | C8: =GCF_2024!C8 -> Allianz Y3 1996–2002 tikslinės grupės pensijų fondas | D8: 5 m. 3 mėn. | E8: 90 | F8: 39.886673 | G8: 20316 | I8: 10.714975 | J8: 8.2465053 | K8: 14.633044 | L8: 10.278026 | M8: 8.8719815 | N8: 15.513608 | P8: 11.869462 | Q8: 13.043972 | S8: 0.5 | T8: 1.11 | U8: -
A9: =+GCF_2024!A9 -> Goindex, UAB [11] | B9: =+GCF_2024!B9 -> GOX-96/02 | C9: =GCF_2024!C9 -> Goindex pensija 1996–2002 tikslinės grupės pensijų fondas | D9: 1 m. 8 mėn. | E9: 100 | F9: 10.36854 | G9: 5820 | I9: 10.214951 | J9: Veikia trumpiau | K9: Veikia trumpiau | L9: 10.193305 | M9: Veikia trumpiau | N9: Veikia trumpiau | P9: Veikia trumpiau | Q9: Veikia trumpiau | S9: 0.44 | T9: 0.57 | U9: -
A11: =+GCF_2024!A62 -> Pastaba: praeities rezultatai negarantuoja, kad tokie patys ar panašūs rezultatai bus ir ateityje. Įtakos 2019 m. pirmojo pusmečio pensijų fondų rezultatams galėjo turėti skirtingu laiku vykdytas turto perkėlimas į tikslinės grupės ir turto išsaugojimo pensijų fondus bei skirtingas fondų dydis nagrinėjamu laikotarpiu.
A12: =+GCF_2024!A63 -> [1] Apskaitos vieneto vertės pokytis. Juo atsižvelgiama į atskaitymus nuo turto.
A13: =+GCF_2024!A64 -> [2] Lyginamasis indeksas apibrėžiamas kaip pensijų kaupimo bendrovės pasirinktas orientacinis investicijų portfelis, atitinkantis fondo investavimo strategiją, su kurio vertės pokyčio reikšme lyginama fondo investicijų portfelio investicijų grąža.
A14: =+GCF_2024!A65 -> [3] Rodikliui apskaičiuoti naudoti mėnesiniai apskaitos vieneto (lyginamojo indekso) verčių pokyčiai, rezultatas perskaičiuotas į metinį. Standartinis nuokrypis parodo, kaip intensyviai per laikotarpį svyruoja fondo investicinio vieneto vertė (lyginamojo indekso vertė). Kuo šis rodiklis didesnis, tuo didesnė rizika.
A15: =+GCF_2024!A66 -> [4] Svertiniam vidurkiui apskaičiuoti naudotas 2024-03-29 dienos fondų grynųjų aktyvų dydis.
A16: =+GCF_2024!A67 -> [5] Investicijų į akcijas dalis, numatyta pensijų fondo strategijoje. Rizikingų turto klasių dalis gali būti padidinta arba sumažinta iki 10 procentinių punktų.
A17: =+GCF_2024!A68 -> [6] Grynieji aktyvai – pensijų fondą sudarančio turto ir įsipareigojimų verčių skirtumas.
A18: =+GCF_2024!A69 -> [7] Šie UAB „Swedbank investicijų valdymas“ valdomi pensijų fondai pradėjo veiklą 2018-03-01, tačiau dėl 2019 m. sausio mėnesį įsigaliojusios pensijų pertvarkos pagal galiojančius teisės aktus buvo įsteigti iš naujo, todėl jų rezultatai skaičiuojami nuo 2019 m. sausio 1 d. (kaip ir visų II pakopos pensijų fondų).
A19: =+GCF_2024!A70 -> [8] Bendrasis atskaitymų rodiklis (BAR) – procentinis dydis, apskaičiuojamas bendrąsias veiklos išlaidas (kurias sudaro atskaitymai nuo pensijų turto) dalijant iš vidutinės atitinkamo laikotarpio grynųjų aktyvų vertės. Kuo šis rodiklis didesnis, tuo daugiau mokesčių yra atskaitoma. Rodiklis skaičiuojamas kartą per metus. Daugiau informacijos apie šį rodiklį ir jo skaičiavimo tvarką galima rasti Lietuvos banko valdybos 2012 m. liepos 12 d. nutarimo Nr. 03-154 „Dėl Valdymo įmonių, kolektyvinio investavimo subjektų ir pensijų fondų informacijos rengimo ir teikimo taisyklių patvirtinimo“ VI skyriuje.
A20: =+GCF_2024!A71 -> [9] Bendrasis išlaidų koeficientas (BIK) – procentinis dydis, kuris parodo, kokia vidutinė pensijų fondo grynųjų aktyvų dalis skiriama jo valdymo išlaidoms padengti. Kai daugiau kaip 10 proc. pensijų fondo grynųjų aktyvų investuota į kitus kolektyvinio investavimo subjektus (skelbiančius savo BIK), turi būti apskaičiuojamas ir paskelbiamas sąlyginis šio pensijų fondo BIK. Jei ne visi šie kolektyvinio investavimo subjektai skaičiuoja savo BIK, skaičiuojamas tikėtinas sąlyginis tokio pensijų fondo BIK. Šios išlaidos tiesiogiai sumažina investuotojo investicijų grąžą (t. y. kuo šie rodikliai didesni, tuo daugiau mokesčių atskaitoma). Rodikliai skaičiuojami kartą per metus. Daugiau informacijos apie šiuos rodiklius ir jų skaičiavimo tvarką galima rasti Lietuvos banko valdybos 2012 m. liepos 12 d. nutarimo Nr. 03-154 „Dėl Valdymo įmonių, kolektyvinio investavimo subjektų ir pensijų fondų informacijos rengimo ir teikimo taisyklių patvirtinimo“ VI skyriuje.
A21: =+GCF_2024!A72 -> [10] Apskaičiuota taikant geometrinį vidurkį.
A22: =+GCF_2024!A73 -> [11] Goindex, UAB valdomi pensijų fondai įsteigti 2022-07-05.
A25: Rizikos ir grąžos palyginimas (per praėjusius 3 metus)
A26: Kuo pensijų fondas paveiksle vaizduojamas aukščiau, tuo jo uždirbama grąža yra didesnė. Kuo žemiau – tuo grąža mažesnė.
A27: Dešiniau pavaizduoti pensijų fondai prisiima didesnę riziką (jų vieneto vertės svyruoja daugiau). Kairiau – mažesnę (jų vieneto vertės svyruoja mažiau).
A35: Fondas | B35: Rizika | C35: Grąža
A36: =+B4 -> LMN-96/02 | B36: =+P4 -> 11.018596 | C36: =+J4 -> 5.3357527
A37: =+B5 -> INV-96/02 | B37: =+P5 -> 10.539487 | C37: =+J5 -> 7.5337095
A38: =+B6 -> SBN-96/02 | B38: =+P6 -> 11.84815 | C38: =+J6 -> 7.0704201
A39: =+B7 -> SWD-96/02 | B39: =+P7 -> 13.122368 | C39: =+J7 -> 8.7683209
A40: =+B8 -> AVI-96/02 | B40: =+P8 -> 11.869462 | C40: =+J8 -> 8.2465053
A57: Dalyvių skaičiaus, grąžos (per praėjusius 3 metus) ir fondo turto palyginimas
A58: Kuo pensijų fondas paveiksle pavaizduotas aukščiau, tuo jo uždirbama grąža yra didesnė. Kuo žemiau – tuo grąža mažesnė.
A59: Dešiniau pavaizduoti pensijų fondai turi daugiau dalyvių. Kairiau – mažiau.
A60: Kuo didesnis fondą vaizduojančio skritulio dydis – tuo fondas turi daugiau turto. Kuo mažesnis – mažiau.
A65: Fondas | B65: Dalyvių sk. (tūkst.) | C65: Grąža (proc.) | D65: Fondo turtas (mln. Eur)
A66: =+B4 -> LMN-96/02 | B66: =+G4/1000 -> 14.666 | C66: =+J4 -> 5.3357527 | D66: =+F4 -> 17.964447
A67: =+B5 -> INV-96/02 | B67: =+G5/1000 -> 19.859 | C67: =+J5 -> 7.5337095 | D67: =+F5 -> 39.140957
A68: =+B6 -> SBN-96/02 | B68: =+G6/1000 -> 21.723 | C68: =+J6 -> 7.0704201 | D68: =+F6 -> 48.911384
A69: =+B7 -> SWD-96/02 | B69: =+G7/1000 -> 49.488 | C69: =+J7 -> 8.7683209 | D69: =+F7 -> 114.85712
A70: =+B8 -> AVI-96/02 | B70: =+G8/1000 -> 20.316 | C70: =+J8 -> 8.2465053 | D70: =+F8 -> 39.886673

Sheet 1989-1995
A1: =+GCF_2024!A1 -> 45382 | C1: Grįžti į pagrindinį puslapį | D1: Veiklos laikotarpis, metais | E1: Strategija | F1: Grynųjų aktyvų vertė, mln. Eur [6] | G1: Dalyvių skaičius | I1: Grąža | J1: 0 | L1: 0 | M1: 0 | P1: Rizika [3] | Q1: 0 | S1: Išlaidų rodikliai (2023 m.) | T1: 0 | U1: 0
A2: =+GCF_2024!A2 -> Pensijų kaupimo bendrovės pavadinimas | B2: =+GCF_2024!B2 -> Fondo kodas | C2: =+GCF_2024!C2 -> Pensijų fondo pavadinimas | D2: 0 | E2: rizikingų aktyvų dalis fonde, proc. [5] | F2: 0 | G2: 0 | I2: vieneto vertės pokytis nuo metų pradžios, proc. [1] | J2: vidutinis metinis vieneto vertės pokytis [10] per praėjusius 3 metus, proc. | K2: vidutinis metinis vieneto vertės pokytis [10] per praėjusius 4 metus, proc. | L2: lyginamojo indekso vertės pokytis nuo metų pradžios, proc. [2] | M2: vidutinis lyginamojo indekso vertės pokytis [10] per praėjusius 3 metus, proc. | N2: vidutinis lyginamojo indekso vertės pokytis [10] per praėjusius 4 metus, proc. | P2: vieneto vertės standartinis nuokrypis, per praėjusius 3 metus, proc. | Q2: lyginamojo indekso standartinis nuokrypis, per praėjusius 3 metus, proc. | S2: BAR, proc. [8] | T2: Sąlyginis BIK, proc. [9] | U2: Tikėtinas sąlyginis BIK, proc. [9]
A3: =+GCF_2024!A10 -> Tikslinės pensijų fondų dalyvių grupės pensijų fondai, 1989-1995 | B3: =+GCF_2024!B10 -> 0 | C3: =+GCF_2024!C10 -> 0 | G3: Svertinis vidurkis [4]: | I3: 8.6104816 | J3: 7.9523501 | K3: 14.69681 | L3: 10.316087 | M3: 8.9039091 | N3: 16.272016
A4: =+GCF_2024!A11 -> Luminor investicijų valdymas UAB | B4: =+GCF_2024!B11 -> LMN-89/95 | C4: =+GCF_2024!C11 -> Luminor 1989–1995 tikslinės grupės pensijų fondas | D4: 5 m. 3 mėn. | E4: 90 | F4: 60.414197 | G4: 18922 | I4: 9.4199596 | J4: 5.3723646 | K4: 13.377642 | L4: 9.3137391 | M4: 7.3169505 | N4: 14.888145 | P4: 10.943007 | Q4: 11.916672 | S4: 0.49 | T4: 0.71 | U4: -
A5: =+GCF_2024!A12 -> UAB „SB Asset Management“ | B5: =+GCF_2024!B12 -> INV-89/95 | C5: =+GCF_2024!C12 -> INVL pensija 1989–1995 Index Plus | D5: 5 m. 3 mėn. | E5: 97 | F5: 146.24354 | G5: 36626 | I5: 8.1441264 | J5: 7.6409375 | K5: 14.83333 | L5: 10.532328 | M5: 8.4953354 | N5: 16.782549 | P5: 10.240636 | Q5: 12.892925 | S5: 0.5 | T5: 1.37 | U5: 1.37
A6: =+GCF_2024!A13 -> UAB „SEB investicijų valdymas“ | B6: =+GCF_2024!B13 -> SBN-89/95 | C6: =+GCF_2024!C13 -> SEB 1989–1995 metų tikslinės grupės pensijų kaupimo fondas | D6: 5 m. 3 mėn. | E6: 98 | F6: 184.13743 | G6: 46062 | I6: 8.286264 | J6: 6.8928547 | K6: 14.402024 | L6: 10.762943 | M6: 9.963111 | N6: 17.556549 | P6: 11.799116 | Q6: 13.470594 | S6: 0.5 | T6: - | U6: 0.88
A7: =+GCF_2024!A14 -> UAB „Swedbank investicijų valdymas“ | B7: =+GCF_2024!B14 -> SWD-89/95 | C7: =+GCF_2024!C14 -> Swedbank pensija 1989–1995 [7] | D7: 5 m. 3 mėn. | E7: 97 | F7: 385.96674 | G7: 95911 | I7: 8.3343684 | J7: 8.8546465 | K7: 14.952957 | L7: 10.189152 | M7: 8.8112656 | N7: 15.907326 | P7: 12.776216 | Q7: 13.255328 | S7: 0.5 | T7: - | U7: 0.8223
A8: =+GCF_2024!A15 -> Allianz Lietuva gyvybės draudimas UAB | B8: =+GCF_2024!B15 -> AVI-89/95 | C8: =+GCF_2024!C15 -> Allianz Y2 1989–1995 tikslinės grupės pensijų fondas | D8: 5 m. 3 mėn. | E8: 90 | F8: 114.4883 | G8: 33894 | I8: 10.03871 | J8: 8.3737571 | K8: 14.829122 | L8: 10.278026 | M8: 8.8719815 | N8: 15.513608 | P8: 11.732258 | Q8: 13.043972 | S8: 0.5 | T8: 0.94 | U8: -
A9: =+GCF_2024!A16 -> Goindex, UAB | B9: =+GCF_2024!B16 -> GOX-89/95 | C9: =+GCF_2024!C16 -> Goindex pensija 1989–1995 tikslinės grupės pensijų fondas | D9: 1 m. 8 mėn. | E9: 100 | F9: 13.813249 | G9: 4333 | I9: 10.207002 | J9: Veikia trumpiau | K9: Veikia trumpiau | L9: 10.193305 | M9: Veikia trumpiau | N9: Veikia trumpiau | P9: Veikia trumpiau | Q9: Veikia trumpiau | S9: 0.44 | T9: 0.56 | U9: -
A11: =+GCF_2024!A62 -> Pastaba: praeities rezultatai negarantuoja, kad tokie patys ar panašūs rezultatai bus ir ateityje. Įtakos 2019 m. pirmojo pusmečio pensijų fondų rezultatams galėjo turėti skirtingu laiku vykdytas turto perkėlimas į tikslinės grupės ir turto išsaugojimo pensijų fondus bei skirtingas fondų dydis nagrinėjamu laikotarpiu.
A12: =+GCF_2024!A63 -> [1] Apskaitos vieneto vertės pokytis. Juo atsižvelgiama į atskaitymus nuo turto.
A13: =+GCF_2024!A64 -> [2] Lyginamasis indeksas apibrėžiamas kaip pensijų kaupimo bendrovės pasirinktas orientacinis investicijų portfelis, atitinkantis fondo investavimo strategiją, su kurio vertės pokyčio reikšme lyginama fondo investicijų portfelio investicijų grąža.
A14: =+GCF_2024!A65 -> [3] Rodikliui apskaičiuoti naudoti mėnesiniai apskaitos vieneto (lyginamojo indekso) verčių pokyčiai, rezultatas perskaičiuotas į metinį. Standartinis nuokrypis parodo, kaip intensyviai per laikotarpį svyruoja fondo investicinio vieneto vertė (lyginamojo indekso vertė). Kuo šis rodiklis didesnis, tuo didesnė rizika.
A15: =+GCF_2024!A66 -> [4] Svertiniam vidurkiui apskaičiuoti naudotas 2024-03-29 dienos fondų grynųjų aktyvų dydis.
A16: =+GCF_2024!A67 -> [5] Investicijų į akcijas dalis, numatyta pensijų fondo strategijoje. Rizikingų turto klasių dalis gali būti padidinta arba sumažinta iki 10 procentinių punktų.
A17: =+GCF_2024!A68 -> [6] Grynieji aktyvai – pensijų fondą sudarančio turto ir įsipareigojimų verčių skirtumas.
A18: =+GCF_2024!A69 -> [7] Šie UAB „Swedbank investicijų valdymas“ valdomi pensijų fondai pradėjo veiklą 2018-03-01, tačiau dėl 2019 m. sausio mėnesį įsigaliojusios pensijų pertvarkos pagal galiojančius teisės aktus buvo įsteigti iš naujo, todėl jų rezultatai skaičiuojami nuo 2019 m. sausio 1 d. (kaip ir visų II pakopos pensijų fondų).
A19: =+GCF_2024!A70 -> [8] Bendrasis atskaitymų rodiklis (BAR) – procentinis dydis, apskaičiuojamas bendrąsias veiklos išlaidas (kurias sudaro atskaitymai nuo pensijų turto) dalijant iš vidutinės atitinkamo laikotarpio grynųjų aktyvų vertės. Kuo šis rodiklis didesnis, tuo daugiau mokesčių yra atskaitoma. Rodiklis skaičiuojamas kartą per metus. Daugiau informacijos apie šį rodiklį ir jo skaičiavimo tvarką galima rasti Lietuvos banko valdybos 2012 m. liepos 12 d. nutarimo Nr. 03-154 „Dėl Valdymo įmonių, kolektyvinio investavimo subjektų ir pensijų fondų informacijos rengimo ir teikimo taisyklių patvirtinimo“ VI skyriuje.
A20: =+GCF_2024!A71 -> [9] Bendrasis išlaidų koeficientas (BIK) – procentinis dydis, kuris parodo, kokia vidutinė pensijų fondo grynųjų aktyvų dalis skiriama jo valdymo išlaidoms padengti. Kai daugiau kaip 10 proc. pensijų fondo grynųjų aktyvų investuota į kitus kolektyvinio investavimo subjektus (skelbiančius savo BIK), turi būti apskaičiuojamas ir paskelbiamas sąlyginis šio pensijų fondo BIK. Jei ne visi šie kolektyvinio investavimo subjektai skaičiuoja savo BIK, skaičiuojamas tikėtinas sąlyginis tokio pensijų fondo BIK. Šios išlaidos tiesiogiai sumažina investuotojo investicijų grąžą (t. y. kuo šie rodikliai didesni, tuo daugiau mokesčių atskaitoma). Rodikliai skaičiuojami kartą per metus. Daugiau informacijos apie šiuos rodiklius ir jų skaičiavimo tvarką galima rasti Lietuvos banko valdybos 2012 m. liepos 12 d. nutarimo Nr. 03-154 „Dėl Valdymo įmonių, kolektyvinio investavimo subjektų ir pensijų fondų informacijos rengimo ir teikimo taisyklių patvirtinimo“ VI skyriuje.
A21: =+GCF_2024!A72 -> [10] Apskaičiuota taikant geometrinį vidurkį.
A22: =+GCF_2024!A73 -> [11] Goindex, UAB valdomi pensijų fondai įsteigti 2022-07-05.
A25: =+'1996-2002'!A25 -> Rizikos ir grąžos palyginimas (per praėjusius 3 metus)
A26: =+'1996-2002'!A26 -> Kuo pensijų fondas paveiksle vaizduojamas aukščiau, tuo jo uždirbama grąža yra didesnė. Kuo žemiau – tuo grąža mažesnė.
A27: =+'1996-2002'!A27 -> Dešiniau pavaizduoti pensijų fondai prisiima didesnę riziką (jų vieneto vertės svyruoja daugiau). Kairiau – mažesnę (jų vieneto vertės svyruoja mažiau).
A35: Fondas | B35: Rizika | C35: Grąža
A36: =+B4 -> LMN-89/95 | B36: =+P4 -> 10.943007 | C36: =+J4 -> 5.3723646
A37: =+B5 -> INV-89/95 | B37: =+P5 -> 10.240636 | C37: =+J5 -> 7.6409375
A38: =+B6 -> SBN-89/95 | B38: =+P6 -> 11.799116 | C38: =+J6 -> 6.8928547
A39: =+B7 -> SWD-89/95 | B39: =+P7 -> 12.776216 | C39: =+J7 -> 8.8546465
A40: =+B8 -> AVI-89/95 | B40: =+P8 -> 11.732258 | C40: =+J8 -> 8.3737571
A57: =+'1996-2002'!A57 -> Dalyvių skaičiaus, grąžos (per praėjusius 3 metus) ir fondo turto palyginimas
A58: =+'1996-2002'!A58 -> Kuo pensijų fondas paveiksle pavaizduotas aukščiau, tuo jo uždirbama grąža yra didesnė. Kuo žemiau – tuo grąža mažesnė.
A59: =+'1996-2002'!A59 -> Dešiniau pavaizduoti pensijų fondai turi daugiau dalyvių. Kairiau – mažiau.
A60: =+'1996-2002'!A60 -> Kuo didesnis fondą vaizduojančio skritulio dydis – tuo fondas turi daugiau turto. Kuo mažesnis – mažiau.
A65: Fondas | B65: Dalyvių sk. (tūkst.) | C65: Grąža (proc.) | D65: Fondo turtas (mln. Eur)
A66: =+B4 -> LMN-89/95 | B66: =+G4/1000 -> 18.922 | C66: =+J4 -> 5.3723646 | D66: =+F4 -> 60.414197
A67: =+B5 -> INV-89/95 | B67: =+G5/1000 -> 36.626 | C67: =+J5 -> 7.6409375 | D67: =+F5 -> 146.24354
A68: =+B6 -> SBN-89/95 | B68: =+G6/1000 -> 46.062 | C68: =+J6 -> 6.8928547 | D68: =+F6 -> 184.13743
A69: =+B7 -> SWD-89/95 | B69: =+G7/1000 -> 95.911 | C69: =+J7 -> 8.8546465 | D69: =+F7 -> 385.96674
A70: =+B8 -> AVI-89/95 | B70: =+G8/1000 -> 33.894 | C70: =+J8 -> 8.3737571 | D70: =+F8 -> 114.4883

Sheet 1982-1988
A1: =+GCF_2024!A1 -> 45382 | C1: Grįžti į pagrindinį puslapį | D1: Veiklos laikotarpis, metais | E1: Strategija | F1: Grynųjų aktyvų vertė, mln. Eur [6] | G1: Dalyvių skaičius | I1: Grąža | J1: 0 | L1: 0 | M1: 0 | P1: Rizika [3] | Q1: 0 | S1: Išlaidų rodikliai (2023 m.) | T1: 0 | U1: 0
A2: =+GCF_2024!A2 -> Pensijų kaupimo bendrovės pavadinimas | B2: =+GCF_2024!B2 -> Fondo kodas | C2: =+GCF_2024!C2 -> Pensijų fondo pavadinimas | D2: 0 | E2: rizikingų aktyvų dalis fonde, proc. [5] | F2: 0 | G2: 0 | I2: vieneto vertės pokytis nuo metų pradžios, proc. [1] | J2: vidutinis metinis vieneto vertės pokytis [10] per praėjusius 3 metus, proc. | K2: vidutinis metinis vieneto vertės pokytis [10] per praėjusius 4 metus, proc. | L2: lyginamojo indekso vertės pokytis nuo metų pradžios, proc. [2] | M2: vidutinis lyginamojo indekso vertės pokytis [10] per praėjusius 3 metus, proc. | N2: vidutinis lyginamojo indekso vertės pokytis [10] per praėjusius 4 metus, proc. | P2: vieneto vertės standartinis nuokrypis, per praėjusius 3 metus, proc. | Q2: lyginamojo indekso standartinis nuokrypis, per praėjusius 3 metus, proc. | S2: BAR, proc. [8] | T2: Sąlyginis BIK, proc. [9] | U2: Tikėtinas sąlyginis BIK, proc. [9]
A3: =+GCF_2024!A17 -> Tikslinės pensijų fondų dalyvių grupės pensijų fondai, 1982-1988 | G3: Svertinis vidurkis [4]: | I3: 8.5770439 | J3: 7.8543104 | K3: 14.725251 | L3: 10.343093 | M3: 8.9575176 | N3: 16.363271
A4: =+GCF_2024!A18 -> Luminor investicijų valdymas UAB | B4: =+GCF_2024!B18 -> LMN-82/88 | C4: =+GCF_2024!C18 -> Luminor 1982–1988 tikslinės grupės pensijų fondas | D4: 5 m. 3 mėn. | E4: 90 | F4: 117.31882 | G4: 26132 | I4: 9.4285341 | J4: 5.5212436 | K4: 13.322932 | L4: 9.3137391 | M4: 7.3169505 | N4: 14.888145 | P4: 10.883094 | Q4: 11.916672 | S4: 0.49 | T4: 0.72 | U4: -
A5: =+GCF_2024!A19 -> UAB „SB Asset Management“ | B5: =+GCF_2024!B19 -> INV-82/88 | C5: =+GCF_2024!C19 -> INVL pensija 1982–1988 Index Plus | D5: 5 m. 3 mėn. | E5: 97 | F5: 253.84621 | G5: 44292 | I5: 8.0577493 | J5: 7.7350641 | K5: 14.867413 | L5: 10.532328 | M5: 8.4953354 | N5: 16.782549 | P5: 10.174667 | Q5: 12.892925 | S5: 0.5 | T5: 1.38 | U5: 1.38
A6: =+GCF_2024!A20 -> UAB „SEB investicijų valdymas“ | B6: =+GCF_2024!B20 -> SBN-82/88 | C6: =+GCF_2024!C20 -> SEB 1982–1988 metų tikslinės grupės pensijų kaupimo fondas | D6: 5 m. 3 mėn. | E6: 98 | F6: 404.37064 | G6: 73986 | I6: 8.2377735 | J6: 6.8457942 | K6: 14.40298 | L6: 10.762943 | M6: 9.963111 | N6: 17.556549 | P6: 11.741186 | Q6: 13.470594 | S6: 0.5 | T6: - | U6: 0.88
A7: =+GCF_2024!A21 -> UAB „Swedbank investicijų valdymas“ | B7: =+GCF_2024!B21 -> SWD-82/88 | C7: =+GCF_2024!C21 -> Swedbank pensija 1982–1988 [7] | D7: 5 m. 3 mėn. | E7: 97 | F7: 547.78486 | G7: 113847 | I7: 8.2984487 | J7: 9.0033483 | K7: 15.18448 | L7: 10.189152 | M7: 8.8112656 | N7: 15.907326 | P7: 12.734842 | Q7: 13.255328 | S7: 0.5 | T7: - | U7: 0.8251
A8: =+GCF_2024!A22 -> Allianz Lietuva gyvybės draudimas UAB | B8: =+GCF_2024!B22 -> AVI-82/88 | C8: =+GCF_2024!C22 -> Allianz Y1 1982–1988 tikslinės grupės pensijų fondas | D8: 5 m. 3 mėn. | E8: 90 | F8: 195.5342 | G8: 47768 | I8: 10.105182 | J8: 8.2755753 | K8: 14.762019 | L8: 10.278026 | M8: 8.8719815 | N8: 15.513608 | P8: 11.691745 | Q8: 13.043972 | S8: 0.5 | T8: 0.98 | U8: -
A9: =+GCF_2024!A23 -> Goindex, UAB | B9: =+GCF_2024!B23 -> GOX-82/88 | C9: =+GCF_2024!C23 -> Goindex pensija 1982–1988 tikslinės grupės pensijų fondas | D9: 1 m. 8 mėn. | E9: 100 | F9: 14.132639 | G9: 3162 | I9: 10.199052 | J9: Veikia trumpiau | K9: Veikia trumpiau | L9: 10.193305 | M9: Veikia trumpiau | N9: Veikia trumpiau | P9: Veikia trumpiau | Q9: Veikia trumpiau | S9: 0.44 | T9: 0.56 | U9: -
A11: =+GCF_2024!A62 -> Pastaba: praeities rezultatai negarantuoja, kad tokie patys ar panašūs rezultatai bus ir ateityje. Įtakos 2019 m. pirmojo pusmečio pensijų fondų rezultatams galėjo turėti skirtingu laiku vykdytas turto perkėlimas į tikslinės grupės ir turto išsaugojimo pensijų fondus bei skirtingas fondų dydis nagrinėjamu laikotarpiu.
A12: =+GCF_2024!A63 -> [1] Apskaitos vieneto vertės pokytis. Juo atsižvelgiama į atskaitymus nuo turto.
A13: =+GCF_2024!A64 -> [2] Lyginamasis indeksas apibrėžiamas kaip pensijų kaupimo bendrovės pasirinktas orientacinis investicijų portfelis, atitinkantis fondo investavimo strategiją, su kurio vertės pokyčio reikšme lyginama fondo investicijų portfelio investicijų grąža.
A14: =+GCF_2024!A65 -> [3] Rodikliui apskaičiuoti naudoti mėnesiniai apskaitos vieneto (lyginamojo indekso) verčių pokyčiai, rezultatas perskaičiuotas į metinį. Standartinis nuokrypis parodo, kaip intensyviai per laikotarpį svyruoja fondo investicinio vieneto vertė (lyginamojo indekso vertė). Kuo šis rodiklis didesnis, tuo didesnė rizika.
A15: =+GCF_2024!A66 -> [4] Svertiniam vidurkiui apskaičiuoti naudotas 2024-03-29 dienos fondų grynųjų aktyvų dydis.
A16: =+GCF_2024!A67 -> [5] Investicijų į akcijas dalis, numatyta pensijų fondo strategijoje. Rizikingų turto klasių dalis gali būti padidinta arba sumažinta iki 10 procentinių punktų.
A17: =+GCF_2024!A68 -> [6] Grynieji aktyvai – pensijų fondą sudarančio turto ir įsipareigojimų verčių skirtumas.
A18: =+GCF_2024!A69 -> [7] Šie UAB „Swedbank investicijų valdymas“ valdomi pensijų fondai pradėjo veiklą 2018-03-01, tačiau dėl 2019 m. sausio mėnesį įsigaliojusios pensijų pertvarkos pagal galiojančius teisės aktus buvo įsteigti iš naujo, todėl jų rezultatai skaičiuojami nuo 2019 m. sausio 1 d. (kaip ir visų II pakopos pensijų fondų).
A19: =+GCF_2024!A70 -> [8] Bendrasis atskaitymų rodiklis (BAR) – procentinis dydis, apskaičiuojamas bendrąsias veiklos išlaidas (kurias sudaro atskaitymai nuo pensijų turto) dalijant iš vidutinės atitinkamo laikotarpio grynųjų aktyvų vertės. Kuo šis rodiklis didesnis, tuo daugiau mokesčių yra atskaitoma. Rodiklis skaičiuojamas kartą per metus. Daugiau informacijos apie šį rodiklį ir jo skaičiavimo tvarką galima rasti Lietuvos banko valdybos 2012 m. liepos 12 d. nutarimo Nr. 03-154 „Dėl Valdymo įmonių, kolektyvinio investavimo subjektų ir pensijų fondų informacijos rengimo ir teikimo taisyklių patvirtinimo“ VI skyriuje.
A20: =+GCF_2024!A71 -> [9] Bendrasis išlaidų koeficientas (BIK) – procentinis dydis, kuris parodo, kokia vidutinė pensijų fondo grynųjų aktyvų dalis skiriama jo valdymo išlaidoms padengti. Kai daugiau kaip 10 proc. pensijų fondo grynųjų aktyvų investuota į kitus kolektyvinio investavimo subjektus (skelbiančius savo BIK), turi būti apskaičiuojamas ir paskelbiamas sąlyginis šio pensijų fondo BIK. Jei ne visi šie kolektyvinio investavimo subjektai skaičiuoja savo BIK, skaičiuojamas tikėtinas sąlyginis tokio pensijų fondo BIK. Šios išlaidos tiesiogiai sumažina investuotojo investicijų grąžą (t. y. kuo šie rodikliai didesni, tuo daugiau mokesčių atskaitoma). Rodikliai skaičiuojami kartą per metus. Daugiau informacijos apie šiuos rodiklius ir jų skaičiavimo tvarką galima rasti Lietuvos banko valdybos 2012 m. liepos 12 d. nutarimo Nr. 03-154 „Dėl Valdymo įmonių, kolektyvinio investavimo subjektų ir pensijų fondų informacijos rengimo ir teikimo taisyklių patvirtinimo“ VI skyriuje.
A21: =+GCF_2024!A72 -> [10] Apskaičiuota taikant geometrinį vidurkį.
A22: =+GCF_2024!A73 -> [11] Goindex, UAB valdomi pensijų fondai įsteigti 2022-07-05.
A25: =+'1996-2002'!A25 -> Rizikos ir grąžos palyginimas (per praėjusius 3 metus)
A26: =+'1996-2002'!A26 -> Kuo pensijų fondas paveiksle vaizduojamas aukščiau, tuo jo uždirbama grąža yra didesnė. Kuo žemiau – tuo grąža mažesnė.
A27: =+'1996-2002'!A27 -> Dešiniau pavaizduoti pensijų fondai prisiima didesnę riziką (jų vieneto vertės svyruoja daugiau). Kairiau – mažesnę (jų vieneto vertės svyruoja mažiau).
A35: Fondas | B35: Rizika | C35: Grąža
A36: =+B4 -> LMN-82/88 | B36: =+P4 -> 10.883094 | C36: =+J4 -> 5.5212436
A37: =+B5 -> INV-82/88 | B37: =+P5 -> 10.174667 | C37: =+J5 -> 7.7350641
A38: =+B6 -> SBN-82/88 | B38: =+P6 -> 11.741186 | C38: =+J6 -> 6.8457942
A39: =+B7 -> SWD-82/88 | B39: =+P7 -> 12.734842 | C39: =+J7 -> 9.0033483
A40: =+B8 -> AVI-82/88 | B40: =+P8 -> 11.691745 | C40: =+J8 -> 8.2755753
A57: =+'1996-2002'!A57 -> Dalyvių skaičiaus, grąžos (per praėjusius 3 metus) ir fondo turto palyginimas
A58: =+'1996-2002'!A58 -> Kuo pensijų fondas paveiksle pavaizduotas aukščiau, tuo jo uždirbama grąža yra didesnė. Kuo žemiau – tuo grąža mažesnė.
A59: =+'1996-2002'!A59 -> Dešiniau pavaizduoti pensijų fondai turi daugiau dalyvių. Kairiau – mažiau.
A60: =+'1996-2002'!A60 -> Kuo didesnis fondą vaizduojančio skritulio dydis – tuo fondas turi daugiau turto. Kuo mažesnis – mažiau.
A65: Fondas | B65: Dalyvių sk. (tūkst.) | C65: Grąža (proc.) | D65: Fondo turtas (mln. Eur)
A66: =+B4 -> LMN-82/88 | B66: =+G4/1000 -> 26.132 | C66: =+J4 -> 5.5212436 | D66: =+F4 -> 117.31882
A67: =+B5 -> INV-82/88 | B67: =+G5/1000 -> 44.292 | C67: =+J5 -> 7.7350641 | D67: =+F5 -> 253.84621
A68: =+B6 -> SBN-82/88 | B68: =+G6/1000 -> 73.986 | C68: =+J6 -> 6.8457942 | D68: =+F6 -> 404.37064
A69: =+B7 -> SWD-82/88 | B69: =+G7/1000 -> 113.847 | C69: =+J7 -> 9.0033483 | D69: =+F7 -> 547.78486
A70: =+B8 -> AVI-82/88 | B70: =+G8/1000 -> 47.768 | C70: =+J8 -> 8.2755753 | D70: =+F8 -> 195.5342

Sheet 1975-1981
A1: =+GCF_2024!A1 -> 45382 | C1: Grįžti į pagrindinį puslapį | D1: Veiklos laikotarpis, metais | E1: Strategija | F1: Grynųjų aktyvų vertė, mln. Eur [6] | G1: Dalyvių skaičius | I1: Grąža | J1: 0 | L1: 0 | M1: 0 | P1: Rizika [3] | Q1: 0 | S1: Išlaidų rodikliai (2023 m.) | T1: 0 | U1: 0
A2: =+GCF_2024!A2 -> Pensijų kaupimo bendrovės pavadinimas | B2: =+GCF_2024!B2 -> Fondo kodas | C2: =+GCF_2024!C2 -> Pensijų fondo pavadinimas | D2: 0 | E2: rizikingų aktyvų dalis fonde, proc. [5] | F2: 0 | G2: 0 | I2: vieneto vertės pokytis nuo metų pradžios, proc. [1] | J2: vidutinis metinis vieneto vertės pokytis [10] per praėjusius 3 metus, proc. | K2: vidutinis metinis vieneto vertės pokytis [10] per praėjusius 4 metus, proc. | L2: lyginamojo indekso vertės pokytis nuo metų pradžios, proc. [2] | M2: vidutinis lyginamojo indekso vertės pokytis [10] per praėjusius 3 metus, proc. | N2: vidutinis lyginamojo indekso vertės pokytis [10] per praėjusius 4 metus, proc. | P2: vieneto vertės standartinis nuokrypis, per praėjusius 3 metus, proc. | Q2: lyginamojo indekso standartinis nuokrypis, per praėjusius 3 metus, proc. | S2: BAR, proc. [8] | T2: Sąlyginis BIK, proc. [9] | U2: Tikėtinas sąlyginis BIK, proc. [9]
A3: =+GCF_2024!A24 -> Tikslinės pensijų fondų dalyvių grupės pensijų fondai, 1975-1981 | G3: Svertinis vidurkis [4]: | I3: 8.4923243 | J3: 7.8048319 | K3: 14.682711 | L3: 10.347139 | M3: 8.9885569 | N3: 16.370227
A4: =+GCF_2024!A25 -> Luminor investicijų valdymas UAB | B4: =+GCF_2024!B25 -> LMN-75/81 | C4: =+GCF_2024!C25 -> Luminor 1975–1981 tikslinės grupės pensijų fondas | D4: 5 m. 3 mėn. | E4: 90 | F4: 132.63731 | G4: 19508 | I4: 9.4129159 | J4: 5.6781453 | K4: 13.469468 | L4: 9.3137391 | M4: 7.3169505 | N4: 14.888145 | P4: 10.905829 | Q4: 11.916672 | S4: 0.49 | T4: 0.72 | U4: -
A5: =+GCF_2024!A26 -> UAB „SB Asset Management“ | B5: =+GCF_2024!B26 -> INV-75/81 | C5: =+GCF_2024!C26 -> INVL pensija 1975–1981 Index Plus | D5: 5 m. 3 mėn. | E5: 97 | F5: 255.68835 | G5: 27850 | I5: 7.9167178 | J5: 7.6956918 | K5: 14.815519 | L5: 10.532328 | M5: 8.4953354 | N5: 16.782549 | P5: 10.126082 | Q5: 12.892925 | S5: 0.5 | T5: 1.39 | U5: 1.39
A6: =+GCF_2024!A27 -> UAB „SEB investicijų valdymas“ | B6: =+GCF_2024!B27 -> SBN-75/81 | C6: =+GCF_2024!C27 -> SEB 1975–1981 metų tikslinės grupės pensijų kaupimo fondas | D6: 5 m. 3 mėn. | E6: 98 | F6: 505.11624 | G6: 62799 | I6: 8.18099 | J6: 6.8090969 | K6: 14.373634 | L6: 10.76314 | M6: 9.9630213 | N6: 17.556671 | P6: 11.72438 | Q6: 13.47069 | S6: 0.5 | T6: - | U6: 0.87
A7: =+GCF_2024!A28 -> UAB „Swedbank investicijų valdymas“ | B7: =+GCF_2024!B28 -> SWD-75/81 | C7: =+GCF_2024!C28 -> Swedbank pensija 1975–1981 [7] | D7: 5 m. 3 mėn. | E7: 97 | F7: 658.27323 | G7: 98543 | I7: 8.2402321 | J7: 8.9758873 | K7: 15.17346 | L7: 10.189152 | M7: 8.8112656 | N7: 15.907326 | P7: 12.609515 | Q7: 13.255328 | S7: 0.5 | T7: - | U7: 0.8308
A8: =+GCF_2024!A29 -> Allianz Lietuva gyvybės draudimas UAB | B8: =+GCF_2024!B29 -> AVI-75/81 | C8: =+GCF_2024!C29 -> Allianz X3 1975–1981 tikslinės grupės pensijų fondas | D8: 5 m. 3 mėn. | E8: 90 | F8: 237.47194 | G8: 39988 | I8: 9.8617271 | J8: 7.981995 | K8: 14.514425 | L8: 10.278026 | M8: 8.8719815 | N8: 15.513608 | P8: 11.744353 | Q8: 13.043972 | S8: 0.5 | T8: 0.99 | U8: -
A9: =+GCF_2024!A30 -> Goindex, UAB | B9: =+GCF_2024!B30 -> GOX-75/81 | C9: =+GCF_2024!C30 -> Goindex pensija 1975–1981 tikslinės grupės pensijų fondas | D9: 1 m. 8 mėn. | E9: 100 | F9: 13.299993 | G9: 1168 | I9: 10.227814 | J9: Veikia trumpiau | K9: Veikia trumpiau | L9: 10.193305 | M9: Veikia trumpiau | N9: Veikia trumpiau | P9: Veikia trumpiau | Q9: Veikia trumpiau | S9: 0.45 | T9: 0.57 | U9: -
A11: =+GCF_2024!A62 -> Pastaba: praeities rezultatai negarantuoja, kad tokie patys ar panašūs rezultatai bus ir ateityje. Įtakos 2019 m. pirmojo pusmečio pensijų fondų rezultatams galėjo turėti skirtingu laiku vykdytas turto perkėlimas į tikslinės grupės ir turto išsaugojimo pensijų fondus bei skirtingas fondų dydis nagrinėjamu laikotarpiu.
A12: =+GCF_2024!A63 -> [1] Apskaitos vieneto vertės pokytis. Juo atsižvelgiama į atskaitymus nuo turto.
A13: =+GCF_2024!A64 -> [2] Lyginamasis indeksas apibrėžiamas kaip pensijų kaupimo bendrovės pasirinktas orientacinis investicijų portfelis, atitinkantis fondo investavimo strategiją, su kurio vertės pokyčio reikšme lyginama fondo investicijų portfelio investicijų grąža.
A14: =+GCF_2024!A65 -> [3] Rodikliui apskaičiuoti naudoti mėnesiniai apskaitos vieneto (lyginamojo indekso) verčių pokyčiai, rezultatas perskaičiuotas į metinį. Standartinis nuokrypis parodo, kaip intensyviai per laikotarpį svyruoja fondo investicinio vieneto vertė (lyginamojo indekso vertė). Kuo šis rodiklis didesnis, tuo didesnė rizika.
A15: =+GCF_2024!A66 -> [4] Svertiniam vidurkiui apskaičiuoti naudotas 2024-03-29 dienos fondų grynųjų aktyvų dydis.
A16: =+GCF_2024!A67 -> [5] Investicijų į akcijas dalis, numatyta pensijų fondo strategijoje. Rizikingų turto klasių dalis gali būti padidinta arba sumažinta iki 10 procentinių punktų.
A17: =+GCF_2024!A68 -> [6] Grynieji aktyvai – pensijų fondą sudarančio turto ir įsipareigojimų verčių skirtumas.
A18: =+GCF_2024!A69 -> [7] Šie UAB „Swedbank investicijų valdymas“ valdomi pensijų fondai pradėjo veiklą 2018-03-01, tačiau dėl 2019 m. sausio mėnesį įsigaliojusios pensijų pertvarkos pagal galiojančius teisės aktus buvo įsteigti iš naujo, todėl jų rezultatai skaičiuojami nuo 2019 m. sausio 1 d. (kaip ir visų II pakopos pensijų fondų).
A19: =+GCF_2024!A70 -> [8] Bendrasis atskaitymų rodiklis (BAR) – procentinis dydis, apskaičiuojamas bendrąsias veiklos išlaidas (kurias sudaro atskaitymai nuo pensijų turto) dalijant iš vidutinės atitinkamo laikotarpio grynųjų aktyvų vertės. Kuo šis rodiklis didesnis, tuo daugiau mokesčių yra atskaitoma. Rodiklis skaičiuojamas kartą per metus. Daugiau informacijos apie šį rodiklį ir jo skaičiavimo tvarką galima rasti Lietuvos banko valdybos 2012 m. liepos 12 d. nutarimo Nr. 03-154 „Dėl Valdymo įmonių, kolektyvinio investavimo subjektų ir pensijų fondų informacijos rengimo ir teikimo taisyklių patvirtinimo“ VI skyriuje.
A20: =+GCF_2024!A71 -> [9] Bendrasis išlaidų koeficientas (BIK) – procentinis dydis, kuris parodo, kokia vidutinė pensijų fondo grynųjų aktyvų dalis skiriama jo valdymo išlaidoms padengti. Kai daugiau kaip 10 proc. pensijų fondo grynųjų aktyvų investuota į kitus kolektyvinio investavimo subjektus (skelbiančius savo BIK), turi būti apskaičiuojamas ir paskelbiamas sąlyginis šio pensijų fondo BIK. Jei ne visi šie kolektyvinio investavimo subjektai skaičiuoja savo BIK, skaičiuojamas tikėtinas sąlyginis tokio pensijų fondo BIK. Šios išlaidos tiesiogiai sumažina investuotojo investicijų grąžą (t. y. kuo šie rodikliai didesni, tuo daugiau mokesčių atskaitoma). Rodikliai skaičiuojami kartą per metus. Daugiau informacijos apie šiuos rodiklius ir jų skaičiavimo tvarką galima rasti Lietuvos banko valdybos 2012 m. liepos 12 d. nutarimo Nr. 03-154 „Dėl Valdymo įmonių, kolektyvinio investavimo subjektų ir pensijų fondų informacijos rengimo ir teikimo taisyklių patvirtinimo“ VI skyriuje.
A21: =+GCF_2024!A72 -> [10] Apskaičiuota taikant geometrinį vidurkį.
A22: =+GCF_2024!A73 -> [11] Goindex, UAB valdomi pensijų fondai įsteigti 2022-07-05.
A25: =+'1996-2002'!A25 -> Rizikos ir grąžos palyginimas (per praėjusius 3 metus)
A26: =+'1996-2002'!A26 -> Kuo pensijų fondas paveiksle vaizduojamas aukščiau, tuo jo uždirbama grąža yra didesnė. Kuo žemiau – tuo grąža mažesnė.
A27: =+'1996-2002'!A27 -> Dešiniau pavaizduoti pensijų fondai prisiima didesnę riziką (jų vieneto vertės svyruoja daugiau). Kairiau – mažesnę (jų vieneto vertės svyruoja mažiau).
A35: Fondas | B35: Rizika | C35: Grąža
A36: =+B4 -> LMN-75/81 | B36: =+P4 -> 10.905829 | C36: =+J4 -> 5.6781453
A37: =+B5 -> INV-75/81 | B37: =+P5 -> 10.126082 | C37: =+J5 -> 7.6956918
A38: =+B6 -> SBN-75/81 | B38: =+P6 -> 11.72438 | C38: =+J6 -> 6.8090969
A39: =+B7 -> SWD-75/81 | B39: =+P7 -> 12.609515 | C39: =+J7 -> 8.9758873
A40: =+B8 -> AVI-75/81 | B40: =+P8 -> 11.744353 | C40: =+J8 -> 7.981995
A57: =+'1996-2002'!A57 -> Dalyvių skaičiaus, grąžos (per praėjusius 3 metus) ir fondo turto palyginimas
A58: =+'1996-2002'!A58 -> Kuo pensijų fondas paveiksle pavaizduotas aukščiau, tuo jo uždirbama grąža yra didesnė. Kuo žemiau – tuo grąža mažesnė.
A59: =+'1996-2002'!A59 -> Dešiniau pavaizduoti pensijų fondai turi daugiau dalyvių. Kairiau – mažiau.
A60: =+'1996-2002'!A60 -> Kuo didesnis fondą vaizduojančio skritulio dydis – tuo fondas turi daugiau turto. Kuo mažesnis – mažiau.
A65: Fondas | B65: Dalyvių sk. (tūkst.) | C65: Grąža (proc.) | D65: Fondo turtas (mln. Eur)
A66: =+B5 -> INV-75/81 | B66: =+G5/1000 -> 27.85 | C66: =+J5 -> 7.6956918 | D66: =+F5 -> 255.68835
A67: =+B4 -> LMN-75/81 | B67: =+G4/1000 -> 19.508 | C67: =+J4 -> 5.6781453 | D67: =+F4 -> 132.63731
A68: =+B6 -> SBN-75/81 | B68: =+G6/1000 -> 62.799 | C68: =+J6 -> 6.8090969 | D68: =+F6 -> 505.11624
A69: =+B7 -> SWD-75/81 | B69: =+G7/1000 -> 98.543 | C69: =+J7 -> 8.9758873 | D69: =+F7 -> 658.27323
A70: =+B8 -> AVI-75/81 | B70: =+G8/1000 -> 39.988 | C70: =+J8 -> 7.981995 | D70: =+F8 -> 237.47194

Sheet 1968-1974
A1: =+GCF_2024!A1 -> 45382 | C1: Grįžti į pagrindinį puslapį | D1: Veiklos laikotarpis, metais | E1: Strategija | F1: Grynųjų aktyvų vertė, mln. Eur [6] | G1: Dalyvių skaičius | I1: Grąža | J1: 0 | L1: 0 | M1: 0 | P1: Rizika [3] | Q1: 0 | S1: Išlaidų rodikliai (2023 m.) | T1: 0 | U1: 0
A2: =+GCF_2024!A2 -> Pensijų kaupimo bendrovės pavadinimas | B2: =+GCF_2024!B2 -> Fondo kodas | C2: =+GCF_2024!C2 -> Pensijų fondo pavadinimas | D2: 0 | E2: rizikingų aktyvų dalis fonde, proc. [5] | F2: 0 | G2: 0 | I2: vieneto vertės pokytis nuo metų pradžios, proc. [1] | J2: vidutinis metinis vieneto vertės pokytis [10] per praėjusius 3 metus, proc. | K2: vidutinis metinis vieneto vertės pokytis [10] per praėjusius 4 metus, proc. | L2: lyginamojo indekso vertės pokytis nuo metų pradžios, proc. [2] | M2: vidutinis lyginamojo indekso vertės pokytis [10] per praėjusius 3 metus, proc. | N2: vidutinis lyginamojo indekso vertės pokytis [10] per praėjusius 4 metus, proc. | P2: vieneto vertės standartinis nuokrypis, per praėjusius 3 metus, proc. | Q2: lyginamojo indekso standartinis nuokrypis, per praėjusius 3 metus, proc. | S2: BAR, proc. [8] | T2: Sąlyginis BIK, proc. [9] | U2: Tikėtinas sąlyginis BIK, proc. [9]
A3: =+GCF_2024!A31 -> Tikslinės pensijų fondų dalyvių grupės pensijų fondai, 1968-1974 | G3: Svertinis vidurkis [4]: | I3: 6.4744884 | J3: 6.1724513 | K3: 12.755032 | L3: 7.4124211 | M3: 6.5195628 | N3: 13.640129
A4: =+GCF_2024!A32 -> Luminor investicijų valdymas UAB | B4: =+GCF_2024!B32 -> LMN-68/74 | C4: =+GCF_2024!C32 -> Luminor 1968–1974 tikslinės grupės pensijų fondas | D4: 5 m. 3 mėn. | E4: 70 | F4: 127.33494 | G4: 18136 | I4: 7.4022624 | J4: 4.5258464 | K4: 12.441957 | L4: 7.1692941 | M4: 5.6637984 | N4: 13.55155 | P4: 10.135718 | Q4: 11.193315 | S4: 0.49 | T4: 0.72 | U4: -
A5: =+GCF_2024!A33 -> UAB „SB Asset Management“ | B5: =+GCF_2024!B33 -> INV-68/74 | C5: =+GCF_2024!C33 -> INVL pensija 1968–1974 Index Plus | D5: 5 m. 3 mėn. | E5: 67.58 | F5: 206.05183 | G5: 23225 | I5: 5.6007345 | J5: 5.5890966 | K5: 12.035906 | L5: 7.3755919 | M5: 5.1068913 | N5: 12.883911 | P5: 8.4786355 | Q5: 11.327649 | S5: 0.5 | T5: 1.23 | U5: 1.23
A6: =+GCF_2024!A34 -> UAB „SEB investicijų valdymas“ | B6: =+GCF_2024!B34 -> SBN-68/74 | C6: =+GCF_2024!C34 -> SEB 1968–1974 metų tikslinės grupės pensijų kaupimo fondas | D6: 5 m. 3 mėn. | E6: 68.1 | F6: 441.73316 | G6: 53381 | I6: 6.0819545 | J6: 5.3733379 | K6: 12.416589 | L6: 7.5901578 | M6: 7.4217018 | N6: 14.466623 | P6: 10.232744 | Q6: 11.659738 | S6: 0.5 | T6: - | U6: 0.79
A7: =+GCF_2024!A35 -> UAB „Swedbank investicijų valdymas“ | B7: =+GCF_2024!B35 -> SWD-68/74 | C7: =+GCF_2024!C35 -> Swedbank pensija 1968–1974 [7] | D7: 5 m. 3 mėn. | E7: 70 | F7: 653.53135 | G7: 95871 | I7: 6.3253973 | J7: 7.2765453 | K7: 13.607163 | L7: 7.1908912 | M7: 6.3853493 | N7: 13.720486 | P7: 10.922329 | Q7: 11.900739 | S7: 0.5 | T7: - | U7: 0.7872
A8: =+GCF_2024!A36 -> Allianz Lietuva gyvybės draudimas UAB | B8: =+GCF_2024!B36 -> AVI-68/74 | C8: =+GCF_2024!C36 -> Allianz X2 1968–1974 tikslinės grupės pensijų fondas | D8: 5 m. 3 mėn. | E8: 70 | F8: 247.72351 | G8: 39466 | I8: 7.710198 | J8: 6.0162551 | K8: 11.869565 | L8: 7.8355212 | M8: 6.8798853 | N8: 12.628894 | P8: 10.389297 | Q8: 11.325991 | S8: 0.5 | T8: 0.87 | U8: -
A9: =+GCF_2024!A37 -> Goindex, UAB | B9: =+GCF_2024!B37 -> GOX-68/74 | C9: =+GCF_2024!C37 -> Goindex pensija 1968–1974 tikslinės grupės pensijų fondas | D9: 1 m. 8 mėn. | E9: 100 | F9: 7.2070003 | G9: 758 | I9: 10.167715 | J9: Veikia trumpiau | K9: Veikia trumpiau | L9: 10.193305 | M9: Veikia trumpiau | N9: Veikia trumpiau | P9: Veikia trumpiau | Q9: Veikia trumpiau | S9: 0.45 | T9: 0.57 | U9: -
A11: =+GCF_2024!A62 -> Pastaba: praeities rezultatai negarantuoja, kad tokie patys ar panašūs rezultatai bus ir ateityje. Įtakos 2019 m. pirmojo pusmečio pensijų fondų rezultatams galėjo turėti skirtingu laiku vykdytas turto perkėlimas į tikslinės grupės ir turto išsaugojimo pensijų fondus bei skirtingas fondų dydis nagrinėjamu laikotarpiu.
A12: =+GCF_2024!A63 -> [1] Apskaitos vieneto vertės pokytis. Juo atsižvelgiama į atskaitymus nuo turto.
A13: =+GCF_2024!A64 -> [2] Lyginamasis indeksas apibrėžiamas kaip pensijų kaupimo bendrovės pasirinktas orientacinis investicijų portfelis, atitinkantis fondo investavimo strategiją, su kurio vertės pokyčio reikšme lyginama fondo investicijų portfelio investicijų grąža.
A14: =+GCF_2024!A65 -> [3] Rodikliui apskaičiuoti naudoti mėnesiniai apskaitos vieneto (lyginamojo indekso) verčių pokyčiai, rezultatas perskaičiuotas į metinį. Standartinis nuokrypis parodo, kaip intensyviai per laikotarpį svyruoja fondo investicinio vieneto vertė (lyginamojo indekso vertė). Kuo šis rodiklis didesnis, tuo didesnė rizika.
A15: =+GCF_2024!A66 -> [4] Svertiniam vidurkiui apskaičiuoti naudotas 2024-03-29 dienos fondų grynųjų aktyvų dydis.
A16: =+GCF_2024!A67 -> [5] Investicijų į akcijas dalis, numatyta pensijų fondo strategijoje. Rizikingų turto klasių dalis gali būti padidinta arba sumažinta iki 10 procentinių punktų.
A17: =+GCF_2024!A68 -> [6] Grynieji aktyvai – pensijų fondą sudarančio turto ir įsipareigojimų verčių skirtumas.
A18: =+GCF_2024!A69 -> [7] Šie UAB „Swedbank investicijų valdymas“ valdomi pensijų fondai pradėjo veiklą 2018-03-01, tačiau dėl 2019 m. sausio mėnesį įsigaliojusios pensijų pertvarkos pagal galiojančius teisės aktus buvo įsteigti iš naujo, todėl jų rezultatai skaičiuojami nuo 2019 m. sausio 1 d. (kaip ir visų II pakopos pensijų fondų).
A19: =+GCF_2024!A70 -> [8] Bendrasis atskaitymų rodiklis (BAR) – procentinis dydis, apskaičiuojamas bendrąsias veiklos išlaidas (kurias sudaro atskaitymai nuo pensijų turto) dalijant iš vidutinės atitinkamo laikotarpio grynųjų aktyvų vertės. Kuo šis rodiklis didesnis, tuo daugiau mokesčių yra atskaitoma. Rodiklis skaičiuojamas kartą per metus. Daugiau informacijos apie šį rodiklį ir jo skaičiavimo tvarką galima rasti Lietuvos banko valdybos 2012 m. liepos 12 d. nutarimo Nr. 03-154 „Dėl Valdymo įmonių, kolektyvinio investavimo subjektų ir pensijų fondų informacijos rengimo ir teikimo taisyklių patvirtinimo“ VI skyriuje.
A20: =+GCF_2024!A71 -> [9] Bendrasis išlaidų koeficientas (BIK) – procentinis dydis, kuris parodo, kokia vidutinė pensijų fondo grynųjų aktyvų dalis skiriama jo valdymo išlaidoms padengti. Kai daugiau kaip 10 proc. pensijų fondo grynųjų aktyvų investuota į kitus kolektyvinio investavimo subjektus (skelbiančius savo BIK), turi būti apskaičiuojamas ir paskelbiamas sąlyginis šio pensijų fondo BIK. Jei ne visi šie kolektyvinio investavimo subjektai skaičiuoja savo BIK, skaičiuojamas tikėtinas sąlyginis tokio pensijų fondo BIK. Šios išlaidos tiesiogiai sumažina investuotojo investicijų grąžą (t. y. kuo šie rodikliai didesni, tuo daugiau mokesčių atskaitoma). Rodikliai skaičiuojami kartą per metus. Daugiau informacijos apie šiuos rodiklius ir jų skaičiavimo tvarką galima rasti Lietuvos banko valdybos 2012 m. liepos 12 d. nutarimo Nr. 03-154 „Dėl Valdymo įmonių, kolektyvinio investavimo subjektų ir pensijų fondų informacijos rengimo ir teikimo taisyklių patvirtinimo“ VI skyriuje.
A21: =+GCF_2024!A72 -> [10] Apskaičiuota taikant geometrinį vidurkį.
A22: =+GCF_2024!A73 -> [11] Goindex, UAB valdomi pensijų fondai įsteigti 2022-07-05.
A25: =+'1996-2002'!A25 -> Rizikos ir grąžos palyginimas (per praėjusius 3 metus)
A26: =+'1996-2002'!A26 -> Kuo pensijų fondas paveiksle vaizduojamas aukščiau, tuo jo uždirbama grąža yra didesnė. Kuo žemiau – tuo grąža mažesnė.
A27: =+'1996-2002'!A27 -> Dešiniau pavaizduoti pensijų fondai prisiima didesnę riziką (jų vieneto vertės svyruoja daugiau). Kairiau – mažesnę (jų vieneto vertės svyruoja mažiau).
A35: Fondas | B35: Rizika | C35: Grąža
A36: =+B4 -> LMN-68/74 | B36: =+P4 -> 10.135718 | C36: =+J4 -> 4.5258464
A37: =+B5 -> INV-68/74 | B37: =+P5 -> 8.4786355 | C37: =+J5 -> 5.5890966
A38: =+B6 -> SBN-68/74 | B38: =+P6 -> 10.232744 | C38: =+J6 -> 5.3733379
A39: =+B7 -> SWD-68/74 | B39: =+P7 -> 10.922329 | C39: =+J7 -> 7.2765453
A40: =+B8 -> AVI-68/74 | B40: =+P8 -> 10.389297 | C40: =+J8 -> 6.0162551
A57: =+'1996-2002'!A57 -> Dalyvių skaičiaus, grąžos (per praėjusius 3 metus) ir fondo turto palyginimas
A58: =+'1996-2002'!A58 -> Kuo pensijų fondas paveiksle pavaizduotas aukščiau, tuo jo uždirbama grąža yra didesnė. Kuo žemiau – tuo grąža mažesnė.
A59: =+'1996-2002'!A59 -> Dešiniau pavaizduoti pensijų fondai turi daugiau dalyvių. Kairiau – mažiau.
A60: =+'1996-2002'!A60 -> Kuo didesnis fondą vaizduojančio skritulio dydis – tuo fondas turi daugiau turto. Kuo mažesnis – mažiau.
A65: Fondas | B65: Dalyvių sk. (tūkst.) | C65: Grąža (proc.) | D65: Fondo turtas (mln. Eur)
A66: =+B5 -> INV-68/74 | B66: =+G5/1000 -> 23.225 | C66: =+J5 -> 5.5890966 | D66: =+F5 -> 206.05183
A67: =+B4 -> LMN-68/74 | B67: =+G4/1000 -> 18.136 | C67: =+J4 -> 4.5258464 | D67: =+F4 -> 127.33494
A68: =+B6 -> SBN-68/74 | B68: =+G6/1000 -> 53.381 | C68: =+J6 -> 5.3733379 | D68: =+F6 -> 441.73316
A69: =+B7 -> SWD-68/74 | B69: =+G7/1000 -> 95.871 | C69: =+J7 -> 7.2765453 | D69: =+F7 -> 653.53135
A70: =+B8 -> AVI-68/74 | B70: =+G8/1000 -> 39.466 | C70: =+J8 -> 6.0162551 | D70: =+F8 -> 247.72351

Sheet 1961-1967
A1: =+GCF_2024!A1 -> 45382 | C1: Grįžti į pagrindinį puslapį | D1: Veiklos laikotarpis, metais | E1: Strategija | F1: Grynųjų aktyvų vertė, mln. Eur [6] | G1: Dalyvių skaičius | I1: Grąža | J1: 0 | L1: 0 | M1: 0 | P1: Rizika [3] | Q1: 0 | S1: Išlaidų rodikliai (2023 m.) | T1: 0 | U1: 0
A2: =+GCF_2024!A2 -> Pensijų kaupimo bendrovės pavadinimas | B2: =+GCF_2024!B2 -> Fondo kodas | C2: =+GCF_2024!C2 -> Pensijų fondo pavadinimas | D2: 0 | E2: rizikingų aktyvų dalis fonde, proc. [5] | F2: 0 | G2: 0 | I2: vieneto vertės pokytis nuo metų pradžios, proc. [1] | J2: vidutinis metinis vieneto vertės pokytis [10] per praėjusius 3 metus, proc. | K2: vidutinis metinis vieneto vertės pokytis [10] per praėjusius 4 metus, proc. | L2: lyginamojo indekso vertės pokytis nuo metų pradžios, proc. [2] | M2: vidutinis lyginamojo indekso vertės pokytis [10] per praėjusius 3 metus, proc. | N2: vidutinis lyginamojo indekso vertės pokytis [10] per praėjusius 4 metus, proc. | P2: vieneto vertės standartinis nuokrypis, per praėjusius 3 metus, proc. | Q2: lyginamojo indekso standartinis nuokrypis, per praėjusius 3 metus, proc. | S2: BAR, proc. [8] | T2: Sąlyginis BIK, proc. [9] | U2: Tikėtinas sąlyginis BIK, proc. [9]
