Workbook

Sheet GCF_2025
A1: 46022 | D1: Veiklos laikotarpis, metais | E1: Strategija | F1: Grynųjų aktyvų vertė, mln. Eur [6] | G1: Dalyvių skaičius | I1: Grąža | T1: Rizika [3] | W1: Išlaidų rodikliai (2024 m.)
A2: Pensijų kaupimo bendrovės pavadinimas | B2: Fondo kodas | C2: Pensijų fondo pavadinimas | E2: rizikingų aktyvų dalis fonde, proc. [5] | I2: vieneto vertės pokytis nuo metų pradžios, proc. [1] | J2: vieneto vertės pokytis [1] per praėjusius 1 metus, proc. | K2: vidutinis metinis vieneto vertės pokytis [10] per praėjusius 3 metus, proc. | L2: vidutinis metinis vieneto vertės pokytis [10] per praėjusius 5 metus, proc. | M2: vidutinis metinis vieneto vertės pokytis [1] nuo faktinės GCF [12] pradžios | N2: lyginamojo indekso vertės pokytis nuo metų pradžios, proc. [2] | O2: lyginamojo indekso vertės pokytis [2] per praėjusius 1 metus, proc. | P2: vidutinis lyginamojo indekso vertės pokytis [10] per praėjusius 3 metus, proc. | Q2: vidutinis lyginamojo indekso vertės pokytis [10] per praėjusius 5 metus, proc. | R2: vidutinis metinis lyginamojo indekso vertės pokytis [2] nuo faktinės GCF [12] pradžios | T2: vieneto vertės standartinis nuokrypis, per praėjusius 3 metus, proc. | U2: lyginamojo indekso standartinis nuokrypis, per praėjusius 3 metus, proc. | W2: BAR, proc. [8] | X2: Sąlyginis BIK, proc. [9] | Y2: Tikėtinas sąlyginis BIK, proc. [9]
A3: Tikslinės pensijų fondų dalyvių grupės pensijų fondai, 2003-2009 | G3: Svertinis vidurkis [4]: | I3: 6.0766499 | J3: 6.0766499 | K3: Veikia trumpiau | L3: Veikia trumpiau | M3: 6.0766499 | N3: 7.3524061 | O3: 7.3524061 | P3: Veikia trumpiau | Q3: Veikia trumpiau | R3: 7.3524061 | T3: Veikia trumpiau | U3: Veikia trumpiau
A4: Luminor investicijų valdymas UAB | B4: LMN-03/09 | C4: Luminor 2003-2009 tikslinės grupės pensijų fondas | D4: 1 m. | E4: 90 | F4: 4.1563697 | G4: 5919 | I4: 5.61 | J4: 5.61 | K4: Veikia trumpiau | L4: Veikia trumpiau | M4: 5.61 | N4: 8.4596 | O4: 8.4596 | P4: Veikia trumpiau | Q4: Veikia trumpiau | R4: 8.4596 | T4: Veikia trumpiau | U4: Veikia trumpiau | W4: - | X4: - | Y4: -
A5: UAB Artea Asset Management | B5: INV-03/09 | C5: Artea pensija 2003-2009 Index Plus | D5: 1 m. | E5: 97 | F5: 2.4900215 | G5: 4241 | I5: 6.64 | J5: 6.64 | K5: Veikia trumpiau | L5: Veikia trumpiau | M5: 6.64 | N5: 7.7931 | O5: 7.7931 | P5: Veikia trumpiau | Q5: Veikia trumpiau | R5: 7.7931 | T5: Veikia trumpiau | U5: Veikia trumpiau | W5: - | X5: - | Y5: -
A6: UAB „SEB investicijų valdymas“ | B6: SBN-03/09 | C6: SEB 2003-2009 metų tikslinės grupės pensijų kaupimo fondas | D6: 1 m. | E6: 98 | F6: 2.9165787 | G6: 3053 | I6: 5.12 | J6: 5.12 | K6: Veikia trumpiau | L6: Veikia trumpiau | M6: 5.12 | N6: 8.0323 | O6: 8.0323 | P6: Veikia trumpiau | Q6: Veikia trumpiau | R6: 8.0323 | T6: Veikia trumpiau | U6: Veikia trumpiau | W6: - | X6: - | Y6: -
A7: UAB „Swedbank investicijų valdymas“ | B7: SWD-03/09 | C7: Swedbank pensija 2003-2009 | D7: 1 m. | E7: 97 | F7: 4.3606964 | G7: 3767 | I7: 3.93 | J7: 3.93 | K7: Veikia trumpiau | L7: Veikia trumpiau | M7: 3.93 | N7: 6.9256 | O7: 6.9256 | P7: Veikia trumpiau | Q7: Veikia trumpiau | R7: 6.9256 | T7: Veikia trumpiau | U7: Veikia trumpiau | W7: - | X7: - | Y7: -
A8: Allianz Lietuva gyvybės draudimas UAB | B8: AVI-03/09 | C8: Allianz D1 2003-2009 tikslinės grupės pensijų fondas | D8: 1 m. | E8: 90 | F8: 2.1753071 | G8: 2449 | I8: 9.98 | J8: 9.98 | K8: Veikia trumpiau | L8: Veikia trumpiau | M8: 9.98 | N8: 5.5455 | O8: 5.5455 | P8: Veikia trumpiau | Q8: Veikia trumpiau | R8: 5.5455 | T8: Veikia trumpiau | U8: Veikia trumpiau | W8: - | X8: - | Y8: -
A9: Goindex, UAB [11] | B9: GOX-03/09 | C9: Goindex pensija 2003-2009 tikslinės grupės pensijų fondas | D9: 1 m. | E9: 100 | F9: 4.6978947 | G9: 4755 | I9: 6.97 | J9: 6.97 | K9: Veikia trumpiau | L9: Veikia trumpiau | M9: 6.97 | N9: 6.95 | O9: 6.95 | P9: Veikia trumpiau | Q9: Veikia trumpiau | R9: 6.95 | T9: Veikia trumpiau | U9: Veikia trumpiau | W9: - | X9: - | Y9: -
A10: Tikslinės pensijų fondų dalyvių grupės pensijų fondai, 1996-2002 | G10: Svertinis vidurkis [4]: | I10: 6.5912777 | J10: 6.5912777 | K10: 14.327236 | L10: 9.6553655 | M10: 10.758475 | N10: 7.6988505 | O10: 7.6988505 | P10: 16.131279 | Q10: 11.168683 | R10: 12.163586
A11: Luminor investicijų valdymas UAB | B11: LMN-96/02 | C11: Luminor 1996–2002 tikslinės grupės pensijų fondas | D11: 7m. | E11: 90 | F11: 37.472794 | G11: 14957 | I11: 7.5594067 | J11: 7.5594067 | K11: 14.63502 | L11: 8.3632218 | M11: 10.583084 | N11: 8.8673133 | O11: 8.8673133 | P11: 15.678993 | Q11: 10.173084 | R11: 11.673338 | T11: 10.06397 | U11: 10.378472 | W11: 0.49 | X11: 0.7 | Y11: -
A12: UAB Artea Asset Management | B12: INV-96/02 | C12: Artea pensija 1996–2002 Index Plus | D12: 7m. | E12: 97 | F12: 59.517167 | G12: 19326 | I12: 8.1376665 | J12: 8.1376665 | K12: 13.709859 | L12: 10.17796 | M12: 11.068157 | N12: 8.4179276 | O12: 8.4179276 | P12: 15.601022 | Q12: 10.945158 | R12: 12.266888 | T12: 9.5172305 | U12: 11.210352 | W12: 0.5 | X12: - | Y12: 1.06
A13: UAB „SEB investicijų valdymas“ | B13: SBN-96/02 | C13: SEB 1996–2002 metų tikslinės grupės pensijų kaupimo fondas | D13: 7m. | E13: 98 | F13: 85.870047 | G13: 22171 | I13: 6.8009563 | J13: 6.8009563 | K13: 14.576113 | L13: 9.7201038 | M13: 11.168953 | N13: 8.7022104 | O13: 8.7022104 | P13: 17.879221 | Q13: 12.280018 | R13: 13.372685 | T13: 10.601815 | U13: 11.581169 | W13: 0.5 | X13: - | Y13: 0.78
A14: UAB „Swedbank investicijų valdymas“ | B14: SWD-96/02 | C14: Swedbank pensija 1996–2002 [7] | D14: 7m. | E14: 97 | F14: 188.41916 | G14: 50784 | I14: 4.0944379 | J14: 4.0944379 | K14: 13.111689 | L14: 9.3897645 | M14: 10.414898 | N14: 7.4805838 | O14: 7.4805838 | P14: 16.213889 | Q14: 11.209001 | R14: 12.314826 | T14: 10.956221 | U14: 11.179359 | W14: 0.41 | X14: - | Y14: 0.6699
A15: Allianz Lietuva gyvybės draudimas UAB | B15: AVI-96/02 | C15: Allianz Y3 1996–2002 tikslinės grupės pensijų fondas | D15: 7m. | E15: 90 | F15: 69.952308 | G15: 19939 | I15: 10.03453 | J15: 10.03453 | K15: 16.222712 | L15: 10.538855 | M15: 11.196142 | N15: 5.9134873 | O15: 5.9134873 | P15: 14.346589 | Q15: 10.419378 | R15: 11.472872 | T15: 10.838279 | U15: 10.520281 | W15: 0.5 | X15: 1.11 | Y15: -
A16: Goindex, UAB | B16: GOX-96/02 | C16: Goindex pensija 1996–2002 tikslinės grupės pensijų fondas | D16: 3 m. 5 mėn. | E16: 100 | F16: 47.484372 | G16: 12840 | I16: 8.3448807 | J16: 8.3448807 | K16: 16.439071 | L16: Veikia trumpiau | M16: 10.48499 | N16: 7.5572113 | O16: 7.5572113 | P16: 16.29322 | Q16: Veikia trumpiau | R16: 10.651887 | T16: 11.247602 | U16: 11.471015 | W16: 0.4469 | X16: 0.5734 | Y16: -
A17: Tikslinės pensijų fondų dalyvių grupės pensijų fondai, 1989-1995 | G17: Svertinis vidurkis [4]: | I17: 6.6840296 | J17: 6.6840296 | K17: 14.079313 | L17: 9.7086262 | M17: 10.850926 | N17: 7.7652444 | O17: 7.7652444 | P17: 16.187721 | Q17: 11.209027 | R17: 12.271585
A18: Luminor investicijų valdymas UAB | B18: LMN-89/95 | C18: Luminor 1989–1995 tikslinės grupės pensijų fondas | D18: 7m. | E18: 90 | F18: 103.47337 | G18: 22623 | I18: 7.5067881 | J18: 7.5067881 | K18: 14.687656 | L18: 8.4278535 | M18: 10.551851 | N18: 8.8673133 | O18: 8.8673133 | P18: 15.678993 | Q18: 10.173084 | R18: 11.673338 | T18: 10.060781 | U18: 10.378472 | W18: 0.49 | X18: 0.71 | Y18: -
A19: UAB Artea Asset Management | B19: INV-89/95 | C19: Artea pensija 1989–1995 Index Plus | D19: 7m. | E19: 97 | F19: 192.49501 | G19: 36524 | I19: 8.0419218 | J19: 8.0419218 | K19: 13.360042 | L19: 10.160751 | M19: 11.038496 | N19: 8.4179276 | O19: 8.4179276 | P19: 15.601022 | Q19: 10.945158 | R19: 12.266888 | T19: 9.070072 | U19: 11.210352 | W19: 0.5 | X19: - | Y19: 1.27
A20: UAB „SEB investicijų valdymas“ | B20: SBN-89/95 | C20: SEB 1989–1995 metų tikslinės grupės pensijų kaupimo fondas | D20: 7m. | E20: 98 | F20: 279.46909 | G20: 46452 | I20: 6.6755401 | J20: 6.6755401 | K20: 14.353559 | L20: 9.6259649 | M20: 11.049149 | N20: 8.7022104 | O20: 8.7022104 | P20: 17.879221 | Q20: 12.280018 | R20: 13.372685 | T20: 10.476499 | U20: 11.581169 | W20: 0.5 | X20: - | Y20: 0.81
A21: UAB „Swedbank investicijų valdymas“ | B21: SWD-89/95 | C21: Swedbank pensija 1989–1995 [7] | D21: 7m. | E21: 97 | F21: 541.1594 | G21: 96020 | I21: 4.7038235 | J21: 4.7038235 | K21: 12.858817 | L21: 9.461512 | M21: 10.682627 | N21: 7.4805838 | O21: 7.4805838 | P21: 16.213889 | Q21: 11.209001 | R21: 12.314826 | T21: 10.607805 | U21: 11.179359 | W21: 0.41 | X21: - | Y21: 0.683
A22: Allianz Lietuva gyvybės draudimas UAB | B22: AVI-89/95 | C22: Allianz Y2 1989–1995 tikslinės grupės pensijų fondas | D22: 7m. | E22: 90 | F22: 178.95154 | G22: 34360 | I22: 9.9994776 | J22: 9.9994776 | K22: 16.734572 | L22: 10.839231 | M22: 11.213491 | N22: 5.9134873 | O22: 5.9134873 | P22: 14.346589 | Q22: 10.419378 | R22: 11.472872 | T22: 10.162212 | U22: 10.520281 | W22: 0.5 | X22: 0.93 | Y22: -
A23: Goindex, UAB | B23: GOX-89/95 | C23: Goindex pensija 1989–1995 tikslinės grupės pensijų fondas | D23: 3 m. 5 mėn. | E23: 100 | F23: 77.413357 | G23: 13448 | I23: 8.4169884 | J23: 8.4169884 | K23: 16.458556 | L23: Veikia trumpiau | M23: 10.407048 | N23: 7.5572113 | O23: 7.5572113 | P23: 16.29322 | Q23: Veikia trumpiau | R23: 10.651887 | T23: 11.234738 | U23: 11.471015 | W23: 0.4466 | X23: 0.5766 | Y23: -
A24: Tikslinės pensijų fondų dalyvių grupės pensijų fondai, 1982-1988 | G24: Svertinis vidurkis [4]: | I24: 6.8018139 | J24: 6.8018139 | K24: 14.120698 | L24: 9.7681313 | M24: 10.94075 | N24: 7.8496558 | O24: 7.8496558 | P24: 16.272348 | Q24: 11.263214 | R24: 12.359967
A25: Luminor investicijų valdymas UAB | B25: LMN-82/88 | C25: Luminor 1982–1988 tikslinės grupės pensijų fondas | D25: 7m. | E25: 90 | F25: 182.51375 | G25: 28878 | I25: 7.4398249 | J25: 7.4398249 | K25: 14.73898 | L25: 8.5308702 | M25: 10.503334 | N25: 8.8673133 | O25: 8.8673133 | P25: 15.678993 | Q25: 10.173084 | R25: 11.673338 | T25: 10.004816 | U25: 10.378472 | W25: 0.49 | X25: 0.72 | Y25: -
A26: UAB Artea Asset Management | B26: INV-82/88 | C26: Artea pensija 1982–1988 Index Plus | D26: 7m. | E26: 97 | F26: 321.58775 | G26: 42682 | I26: 8.1311373 | J26: 8.1311373 | K26: 13.356769 | L26: 10.220276 | M26: 11.02936 | N26: 8.4179276 | O26: 8.4179276 | P26: 15.601022 | Q26: 10.945158 | R26: 12.266888 | T26: 9.0340028 | U26: 11.210352 | W26: 0.5 | X26: - | Y26: 1.26
A27: UAB „SEB investicijų valdymas“ | B27: SBN-82/88 | C27: SEB 1982–1988 metų tikslinės grupės pensijų kaupimo fondas | D27: 7m. | E27: 98 | F27: 578.57099 | G27: 74338 | I27: 6.6104294 | J27: 6.6104294 | K27: 14.244515 | L27: 9.6034614 | M27: 11.060556 | N27: 8.7022104 | O27: 8.7022104 | P27: 17.879221 | Q27: 12.280018 | R27: 13.372685 | T27: 10.423404 | U27: 11.581169 | W27: 0.5 | X27: - | Y27: 0.82
A28: UAB „Swedbank investicijų valdymas“ | B28: SWD-82/88 | C28: Swedbank pensija 1982–1988 [7] | D28: 7m. | E28: 97 | F28: 733.87588 | G28: 114002 | I28: 4.68405 | J28: 4.68405 | K28: 12.898401 | L28: 9.609903 | M28: 10.836959 | N28: 7.4805838 | O28: 7.4805838 | P28: 16.213889 | Q28: 11.209001 | R28: 12.314826 | T28: 10.600653 | U28: 11.179359 | W28: 0.41 | X28: - | Y28: 0.6896
A29: Allianz Lietuva gyvybės draudimas UAB | B29: AVI-82/88 | C29: Allianz Y1 1982–1988 tikslinės grupės pensijų fondas | D29: 7m. | E29: 90 | F29: 293.01943 | G29: 48030 | I29: 10.186589 | J29: 10.186589 | K29: 16.752115 | L29: 10.763991 | M29: 11.233838 | N29: 5.9134873 | O29: 5.9134873 | P29: 14.346589 | Q29: 10.419378 | R29: 11.472872 | T29: 10.177916 | U29: 10.520281 | W29: 0.5 | X29: 0.97 | Y29: -
A30: Goindex, UAB | B30: GOX-82/88 | C30: Goindex pensija 1982–1988 tikslinės grupės pensijų fondas | D30: 3 m. 5 mėn. | E30: 100 | F30: 80.566328 | G30: 10505 | I30: 8.4049739 | J30: 8.4049739 | K30: 16.443577 | L30: Veikia trumpiau | M30: 10.597084 | N30: 7.5572113 | O30: 7.5572113 | P30: 16.29322 | Q30: Veikia trumpiau | R30: 10.651887 | T30: 11.256195 | U30: 11.471015 | W30: 0.4466 | X30: 0.577 | Y30: -
A31: Tikslinės pensijų fondų dalyvių grupės pensijų fondai, 1975-1981 | G31: Svertinis vidurkis [4]: | I31: 6.7685894 | J31: 6.7685894 | K31: 14.053189 | L31: 9.7338052 | M31: 11.009541 | N31: 7.7981503 | O31: 7.7981503 | P31: 16.289257 | Q31: 11.280439 | R31: 12.514961
A32: Luminor investicijų valdymas UAB | B32: LMN-75/81 | C32: Luminor 1975–1981 tikslinės grupės pensijų fondas | D32: 7m. | E32: 90 | F32: 187.64337 | G32: 19611 | I32: 7.2530864 | J32: 7.2530864 | K32: 14.707147 | L32: 8.6136655 | M32: 10.52213 | N32: 8.8673133 | O32: 8.8673133 | P32: 15.678993 | Q32: 10.173084 | R32: 11.673338 | T32: 9.9957415 | U32: 10.378472 | W32: 0.49 | X32: 0.72 | Y32: -
A33: UAB Artea Asset Management | B33: INV-75/81 | C33: Artea pensija 1975–1981 Index Plus | D33: 7m. | E33: 97 | F33: 311.22315 | G33: 25872 | I33: 7.8482194 | J33: 7.8482194 | K33: 13.133303 | L33: 10.113204 | M33: 11.024028 | N33: 8.1573001 | O33: 8.1573001 | P33: 15.508316 | Q33: 10.891766 | R33: 12.228324 | T33: 8.9049332 | U33: 11.15897 | W33: 0.5 | X33: - | Y33: 1.28
A34: UAB „SEB investicijų valdymas“ | B34: SBN-75/81 | C34: SEB 1975–1981 metų tikslinės grupės pensijų kaupimo fondas | D34: 7m. | E34: 98 | F34: 686.27158 | G34: 62239 | I34: 6.605523 | J34: 6.605523 | K34: 14.18939 | L34: 9.5762188 | M34: 11.375641 | N34: 8.7021838 | O34: 8.7021838 | P34: 17.879174 | Q34: 12.279917 | R34: 13.822147 | T34: 10.38007 | U34: 11.581183 | W34: 0.5 | X34: - | Y34: 0.82
A35: UAB „Swedbank investicijų valdymas“ | B35: SWD-75/81 | C35: Swedbank pensija 1975–1981 [7] | D35: 7m. | E35: 97 | F35: 838.96081 | G35: 96814 | I35: 4.8716191 | J35: 4.8716191 | K35: 12.889449 | L35: 9.6414824 | M35: 10.860365 | N35: 7.4805838 | O35: 7.4805838 | P35: 16.213889 | Q35: 11.209001 | R35: 12.314826 | T35: 10.523927 | U35: 11.179359 | W35: 0.41 | X35: - | Y35: 0.6963
A36: Allianz Lietuva gyvybės draudimas UAB | B36: AVI-75/81 | C36: Allianz X3 1975–1981 tikslinės grupės pensijų fondas | D36: 7m. | E36: 90 | F36: 345.18833 | G36: 40106 | I36: 10.151612 | J36: 10.151612 | K36: 16.620097 | L36: 10.538326 | M36: 11.004212 | N36: 5.9134873 | O36: 5.9134873 | P36: 14.346589 | Q36: 10.419378 | R36: 11.472872 | T36: 10.172996 | U36: 10.520281 | W36: 0.5 | X36: 0.98 | Y36: -
A37: Goindex, UAB | B37: GOX-75/81 | C37: Goindex pensija 1975–1981 tikslinės grupės pensijų fondas | D37: 3 m. 5 mėn. | E37: 100 | F37: 65.660426 | G37: 5044 | I37: 8.4239759 | J37: 8.4239759 | K37: 16.495647 | L37: Veikia trumpiau | M37: 10.441451 | N37: 7.5572113 | O37: 7.5572113 | P37: 16.29322 | Q37: Veikia trumpiau | R37: 10.651887 | T37: 11.235966 | U37: 11.471015 | W37: 0.4469 | X37: 0.5782 | Y37: -
A38: Tikslinės pensijų fondų dalyvių grupės pensijų fondai, 1968-1974 | G38: Svertinis vidurkis [4]: | I38: 5.9008404 | J38: 5.9008404 | K38: 11.904877 | L38: 8.0109179 | M38: 9.5594241 | N38: 6.230927 | O38: 6.230927 | P38: 13.198716 | Q38: 8.702144 | R38: 10.463459
A39: Luminor investicijų valdymas UAB | B39: LMN-68/74 | C39: Luminor 1968–1974 tikslinės grupės pensijų fondas | D39: 7m. | E39: 65 | F39: 170.57983 | G39: 17990 | I39: 6.5132387 | J39: 6.5132387 | K39: 12.618039 | L39: 7.3420304 | M39: 9.6509178 | N39: 6.8624145 | O39: 6.8624145 | P39: 13.08079 | Q39: 8.381148 | R39: 10.37393 | T39: 8.0763417 | U39: 8.6678001 | W39: 0.49 | X39: 0.73 | Y39: -
A40: UAB Artea Asset Management | B40: INV-68/74 | C40: Artea pensija 1968–1974 Index Plus | D40: 7m. | E40: 61.18 | F40: 248.29906 | G40: 22088 | I40: 7.6017008 | J40: 7.6017008 | K40: 11.181691 | L40: 8.0564922 | M40: 9.3688347 | N40: 7.2509023 | O40: 7.2509023 | P40: 12.735413 | Q40: 7.7849618 | R40: 9.8149586 | T40: 6.2715084 | U40: 8.2435801 | W40: 0.5 | X40: - | Y40: 1.1
...

Sheet 2003-2009
A1: 46022 | C1: Grįžti į pagrindinį puslapį | D1: Veiklos laikotarpis, metais | E1: Strategija | F1: Grynųjų aktyvų vertė, mln. Eur [6] | G1: Dalyvių skaičius | I1: Grąža | T1: Rizika [3] | U1: 0 | W1: Išlaidų rodikliai (2024 m.) | X1: 0 | Y1: 0
A2: Pensijų kaupimo bendrovės pavadinimas | B2: Fondo kodas | C2: Pensijų fondo pavadinimas | D2: 0 | E2: rizikingų aktyvų dalis fonde, proc. [5] | F2: 0 | G2: 0 | I2: vieneto vertės pokytis nuo metų pradžios, proc. [1] | J2: vieneto vertės pokytis [1] per praėjusius 1 metus, proc. | K2: vidutinis metinis vieneto vertės pokytis [10] per praėjusius 3 metus, proc. | L2: vidutinis metinis vieneto vertės pokytis [10] per praėjusius 5 metus, proc. | M2: vidutinis metinis vieneto vertės pokytis [1] nuo faktinės GCF [12] pradžios | N2: lyginamojo indekso vertės pokytis nuo metų pradžios, proc. [2] | O2: lyginamojo indekso vertės pokytis [2] per praėjusius 1 metus, proc. | P2: vidutinis lyginamojo indekso vertės pokytis [10] per praėjusius 3 metus, proc. | Q2: vidutinis lyginamojo indekso vertės pokytis [10] per praėjusius 5 metus, proc. | R2: vidutinis metinis lyginamojo indekso vertės pokytis [2] nuo faktinės GCF [12] pradžios | T2: vieneto vertės standartinis nuokrypis, per praėjusius 3 metus, proc. | U2: lyginamojo indekso standartinis nuokrypis, per praėjusius 3 metus, proc. | W2: BAR, proc. [8] | X2: Sąlyginis BIK, proc. [9] | Y2: Tikėtinas sąlyginis BIK, proc. [9]
A3: Tikslinės pensijų fondų dalyvių grupės pensijų fondai, 2003-2009 | G3: Svertinis vidurkis [4]: | I3: 6.0766499 | J3: 6.0766499 | K3: Veikia trumpiau | L3: Veikia trumpiau | M3: 6.0766499 | N3: 7.3524061 | O3: 7.3524061 | P3: Veikia trumpiau | Q3: Veikia trumpiau | R3: 7.3524061
A4: Luminor investicijų valdymas UAB | B4: LMN-03/09 | C4: Luminor 2003-2009 tikslinės grupės pensijų fondas | D4: 1 m. | E4: 90 | F4: 4.1563697 | G4: 5919 | I4: 5.61 | J4: 5.61 | K4: Veikia trumpiau | L4: Veikia trumpiau | M4: 5.61 | N4: 8.4596 | O4: 8.4596 | P4: Veikia trumpiau | Q4: Veikia trumpiau | R4: 8.4596 | T4: Veikia trumpiau | U4: Veikia trumpiau | W4: - | X4: - | Y4: -
A5: UAB Artea Asset Management | B5: INV-03/09 | C5: Artea pensija 2003-2009 Index Plus | D5: 1 m. | E5: 97 | F5: 2.4900215 | G5: 4241 | I5: 6.64 | J5: 6.64 | K5: Veikia trumpiau | L5: Veikia trumpiau | M5: 6.64 | N5: 7.7931 | O5: 7.7931 | P5: Veikia trumpiau | Q5: Veikia trumpiau | R5: 7.7931 | T5: Veikia trumpiau | U5: Veikia trumpiau | W5: - | X5: - | Y5: -
A6: UAB „SEB investicijų valdymas“ | B6: SBN-03/09 | C6: SEB 2003-2009 metų tikslinės grupės pensijų kaupimo fondas | D6: 1 m. | E6: 98 | F6: 2.9165787 | G6: 3053 | I6: 5.12 | J6: 5.12 | K6: Veikia trumpiau | L6: Veikia trumpiau | M6: 5.12 | N6: 8.0323 | O6: 8.0323 | P6: Veikia trumpiau | Q6: Veikia trumpiau | R6: 8.0323 | T6: Veikia trumpiau | U6: Veikia trumpiau | W6: - | X6: - | Y6: -
A7: UAB „Swedbank investicijų valdymas“ | B7: SWD-03/09 | C7: Swedbank pensija 2003-2009 | D7: 1 m. | E7: 97 | F7: 4.3606964 | G7: 3767 | I7: 3.93 | J7: 3.93 | K7: Veikia trumpiau | L7: Veikia trumpiau | M7: 3.93 | N7: 6.9256 | O7: 6.9256 | P7: Veikia trumpiau | Q7: Veikia trumpiau | R7: 6.9256 | T7: Veikia trumpiau | U7: Veikia trumpiau | W7: - | X7: - | Y7: -
A8: Allianz Lietuva gyvybės draudimas UAB | B8: AVI-03/09 | C8: Allianz D1 2003-2009 tikslinės grupės pensijų fondas | D8: 1 m. | E8: 90 | F8: 2.1753071 | G8: 2449 | I8: 9.98 | J8: 9.98 | K8: Veikia trumpiau | L8: Veikia trumpiau | M8: 9.98 | N8: 5.5455 | O8: 5.5455 | P8: Veikia trumpiau | Q8: Veikia trumpiau | R8: 5.5455 | T8: Veikia trumpiau | U8: Veikia trumpiau | W8: - | X8: - | Y8: -
A9: Goindex, UAB [11] | B9: GOX-03/09 | C9: Goindex pensija 2003-2009 tikslinės grupės pensijų fondas | D9: 1 m. | E9: 100 | F9: 4.6978947 | G9: 4755 | I9: 6.97 | J9: 6.97 | K9: Veikia trumpiau | L9: Veikia trumpiau | M9: 6.97 | N9: 6.95 | O9: 6.95 | P9: Veikia trumpiau | Q9: Veikia trumpiau | R9: 6.95 | T9: Veikia trumpiau | U9: Veikia trumpiau | W9: - | X9: - | Y9: -
A11: Pastaba: praeities rezultatai negarantuoja, kad tokie patys ar panašūs rezultatai bus ir ateityje. Įtakos 2019 m. pirmojo pusmečio pensijų fondų rezultatams galėjo turėti skirtingu laiku vykdytas turto perkėlimas į tikslinės grupės ir turto išsaugojimo pensijų fondus bei skirtingas fondų dydis nagrinėjamu laikotarpiu.
A12: [1] Apskaitos vieneto vertės pokytis. Juo atsižvelgiama į atskaitymus nuo turto.
A13: [2] Lyginamasis indeksas apibrėžiamas kaip pensijų kaupimo bendrovės pasirinktas orientacinis investicijų portfelis, atitinkantis fondo investavimo strategiją, su kurio vertės pokyčio reikšme lyginama fondo investicijų portfelio investicijų grąža.
A14: [3] Rodikliui apskaičiuoti naudoti mėnesiniai apskaitos vieneto (lyginamojo indekso) verčių pokyčiai, rezultatas perskaičiuotas į metinį. Standartinis nuokrypis parodo, kaip intensyviai per laikotarpį svyruoja fondo investicinio vieneto vertė (lyginamojo indekso vertė). Kuo šis rodiklis didesnis, tuo didesnė rizika.
A15: [4] Svertiniam vidurkiui apskaičiuoti naudotas 2025-12-31 dienos fondų grynųjų aktyvų dydis.
A16: [5] Investicijų į akcijas dalis, numatyta pensijų fondo strategijoje. Rizikingų turto klasių dalis gali būti padidinta arba sumažinta iki 10 procentinių punktų.
A17: [6] Grynieji aktyvai – pensijų fondą sudarančio turto ir įsipareigojimų verčių skirtumas.
A18: [7] Šie UAB „Swedbank investicijų valdymas“ valdomi pensijų fondai pradėjo veiklą 2018-03-01, tačiau dėl 2019 m. sausio mėnesį įsigaliojusios pensijų pertvarkos pagal galiojančius teisės aktus buvo įsteigti iš naujo, todėl jų rezultatai skaičiuojami nuo 2019 m. sausio 1 d. (kaip ir visų II pakopos pensijų fondų).
A19: [8] Bendrasis atskaitymų rodiklis (BAR) – procentinis dydis, apskaičiuojamas bendrąsias veiklos išlaidas (kurias sudaro atskaitymai nuo pensijų turto) dalijant iš vidutinės atitinkamo laikotarpio grynųjų aktyvų vertės. Kuo šis rodiklis didesnis, tuo daugiau mokesčių yra atskaitoma. Rodiklis skaičiuojamas kartą per metus. Daugiau informacijos apie šį rodiklį ir jo skaičiavimo tvarką galima rasti Lietuvos banko valdybos 2012 m. liepos 12 d. nutarimo Nr. 03-154 „Dėl Valdymo įmonių, kolektyvinio investavimo subjektų ir pensijų fondų informacijos rengimo ir teikimo taisyklių patvirtinimo“ VI skyriuje.
A20: [9] Bendrasis išlaidų koeficientas (BIK) – procentinis dydis, kuris parodo, kokia vidutinė pensijų fondo grynųjų aktyvų dalis skiriama jo valdymo išlaidoms padengti. Kai daugiau kaip 10 proc. pensijų fondo grynųjų aktyvų investuota į kitus kolektyvinio investavimo subjektus (skelbiančius savo BIK), turi būti apskaičiuojamas ir paskelbiamas sąlyginis šio pensijų fondo BIK. Jei ne visi šie kolektyvinio investavimo subjektai skaičiuoja savo BIK, skaičiuojamas tikėtinas sąlyginis tokio pensijų fondo BIK. Šios išlaidos tiesiogiai sumažina investuotojo investicijų grąžą (t. y. kuo šie rodikliai didesni, tuo daugiau mokesčių atskaitoma). Rodikliai skaičiuojami kartą per metus. Daugiau informacijos apie šiuos rodiklius ir jų skaičiavimo tvarką galima rasti Lietuvos banko valdybos 2012 m. liepos 12 d. nutarimo Nr. 03-154 „Dėl Valdymo įmonių, kolektyvinio investavimo subjektų ir pensijų fondų informacijos rengimo ir teikimo taisyklių patvirtinimo“ VI skyriuje.
A21: [10] Apskaičiuota taikant geometrinį vidurkį.
A22: [11] Goindex, UAB valdomi pensijų fondai įsteigti 2022-07-05
... A27: Dešiniau pavaizduoti pensijų fondai prisiima didesnę riziką (jų vieneto vertės svyruoja daugiau). Kairiau – mažesnę (jų vieneto vertės svyruoja mažiau).
A35: Fondas | B35: Rizika | C35: Grąža
A36: LMN-03/09 | B36: Veikia trumpiau | C36: Veikia trumpiau
A37: INV-03/09 | B37: Veikia trumpiau | C37: Veikia trumpiau
A38: SBN-03/09 | B38: Veikia trumpiau | C38: Veikia trumpiau
A39: SWD-03/09 | B39: Veikia trumpiau | C39: Veikia trumpiau
A40: AVI-03/09 | B40: Veikia trumpiau | C40: Veikia trumpiau
A41: GOX-03/09 | B41: Veikia trumpiau | C41: Veikia trumpiau
A57: Dalyvių skaičiaus, grąžos (per praėjusius 3 metus) ir fondo turto palyginimas
A58: Kuo pensijų fondas paveiksle pavaizduotas aukščiau, tuo jo uždirbama grąža yra didesnė. Kuo žemiau – tuo grąža mažesnė.
A59: Dešiniau pavaizduoti pensijų fondai turi daugiau dalyvių. Kairiau – mažiau.
A60: Kuo didesnis fondą vaizduojančio skritulio dydis – tuo fondas turi daugiau turto. Kuo mažesnis – mažiau.
A65: Fondas | B65: Dalyvių sk. (tūkst.) | C65: Grąža (proc.) | D65: Fondo turtas (mln. Eur)
A66: LMN-03/09 | B66: 5.919 | C66: Veikia trumpiau | D66: 4.1563697
A67: INV-03/09 | B67: 4.241 | C67: Veikia trumpiau | D67: 2.4900215
A68: SBN-03/09 | B68: 3.053 | C68: Veikia trumpiau | D68: 2.9165787
A69: SWD-03/09 | B69: 3.767 | C69: Veikia trumpiau | D69: 4.3606964
A70: AVI-03/09 | B70: 2.449 | C70: Veikia trumpiau | D70: 2.1753071
A71: GOX-03/09 | B71: 4.755 | C71: Veikia trumpiau | D71: 4.6978947

Sheet 1996-2002
A1: 46022 | C1: Grįžti į pagrindinį puslapį | D1: Veiklos laikotarpis, metais | E1: Strategija | F1: Grynųjų aktyvų vertė, mln. Eur [6] | G1: Dalyvių skaičius | I1: Grąža | K1: 0 | N1: 0 | P1: 0 | T1: Rizika [3] | U1: 0 | W1: Išlaidų rodikliai (2024 m.) | X1: 0 | Y1: 0
A2: Pensijų kaupimo bendrovės pavadinimas | B2: Fondo kodas | C2: Pensijų fondo pavadinimas | D2: 0 | E2: rizikingų aktyvų dalis fonde, proc. [5] | F2: 0 | G2: 0 | I2: vieneto vertės pokytis nuo metų pradžios, proc. [1] | J2: vieneto vertės pokytis [1] per praėjusius 1 metus, proc. | K2: vidutinis metinis vieneto vertės pokytis [10] per praėjusius 3 metus, proc. | L2: vidutinis metinis vieneto vertės pokytis [10] per praėjusius 5 metus, proc. | M2: vidutinis metinis vieneto vertės pokytis [1] nuo faktinės GCF [12] pradžios | N2: lyginamojo indekso vertės pokytis nuo metų pradžios, proc. [2] | O2: lyginamojo indekso vertės pokytis [2] per praėjusius 1 metus, proc. | P2: vidutinis lyginamojo indekso vertės pokytis [10] per praėjusius 3 metus, proc. | Q2: vidutinis lyginamojo indekso vertės pokytis [10] per praėjusius 5 metus, proc. | R2: vidutinis metinis lyginamojo indekso vertės pokytis [2] nuo faktinės GCF [12] pradžios | T2: vieneto vertės standartinis nuokrypis, per praėjusius 3 metus, proc. | U2: lyginamojo indekso standartinis nuokrypis, per praėjusius 3 metus, proc. | W2: BAR, proc. [8] | X2: Sąlyginis BIK, proc. [9] | Y2: Tikėtinas sąlyginis BIK, proc. [9]
A3: Tikslinės pensijų fondų dalyvių grupės pensijų fondai, 1996-2002 | G3: Svertinis vidurkis [4]: | I3: 6.5912777 | J3: 6.5912777 | K3: 14.327236 | L3: 9.6553655 | M3: 10.758475 | N3: 7.6988505 | O3: 7.6988505 | P3: 16.131279 | Q3: 11.168683 | R3: 12.163586
A4: Luminor investicijų valdymas UAB | B4: LMN-96/02 | C4: Luminor 1996–2002 tikslinės grupės pensijų fondas | D4: 7m. | E4: 90 | F4: 37.472794 | G4: 14957 | I4: 7.5594067 | J4: 7.5594067 | K4: 14.63502 | L4: 8.3632218 | M4: 10.583084 | N4: 8.8673133 | O4: 8.8673133 | P4: 15.678993 | Q4: 10.173084 | R4: 11.673338 | T4: 10.06397 | U4: 10.378472 | W4: 0.49 | X4: 0.7 | Y4: -
A5: UAB Artea Asset Management | B5: INV-96/02 | C5: Artea pensija 1996–2002 Index Plus | D5: 7m. | E5: 97 | F5: 59.517167 | G5: 19326 | I5: 8.1376665 | J5: 8.1376665 | K5: 13.709859 | L5: 10.17796 | M5: 11.068157 | N5: 8.4179276 | O5: 8.4179276 | P5: 15.601022 | Q5: 10.945158 | R5: 12.266888 | T5: 9.5172305 | U5: 11.210352 | W5: 0.5 | X5: 1.06 | Y5: 1.06
A6: UAB „SEB investicijų valdymas“ | B6: SBN-96/02 | C6: SEB 1996–2002 metų tikslinės grupės pensijų kaupimo fondas | D6: 7m. | E6: 98 | F6: 85.870047 | G6: 22171 | I6: 6.8009563 | J6: 6.8009563 | K6: 14.576113 | L6: 9.7201038 | M6: 11.168953 | N6: 8.7022104 | O6: 8.7022104 | P6: 17.879221 | Q6: 12.280018 | R6: 13.372685 | T6: 10.601815 | U6: 11.581169 | W6: 0.5 | X6: - | Y6: 0.78
A7: UAB „Swedbank investicijų valdymas“ | B7: SWD-96/02 | C7: Swedbank pensija 1996–2002 [7] | D7: 7m. | E7: 97 | F7: 188.41916 | G7: 50784 | I7: 4.0944379 | J7: 4.0944379 | K7: 13.111689 | L7: 9.3897645 | M7: 10.414898 | N7: 7.4805838 | O7: 7.4805838 | P7: 16.213889 | Q7: 11.209001 | R7: 12.314826 | T7: 10.956221 | U7: 11.179359 | W7: 0.41 | X7: - | Y7: 0.6699
A8: Allianz Lietuva gyvybės draudimas UAB | B8: AVI-96/02 | C8: Allianz Y3 1996–2002 tikslinės grupės pensijų fondas | D8: 7m. | E8: 90 | F8: 69.952308 | G8: 19939 | I8: 10.03453 | J8: 10.03453 | K8: 16.222712 | L8: 10.538855 | M8: 11.196142 | N8: 5.9134873 | O8: 5.9134873 | P8: 14.346589 | Q8: 10.419378 | R8: 11.472872 | T8: 10.838279 | U8: 10.520281 | W8: 0.5 | X8: 1.11 | Y8: -
A9: Goindex, UAB | B9: GOX-96/02 | C9: Goindex pensija 1996–2002 tikslinės grupės pensijų fondas | D9: 3 m. 5 mėn. | E9: 100 | F9: 47.484372 | G9: 12840 | I9: 8.3448807 | J9: 8.3448807 | K9: 16.439071 | L9: Veikia trumpiau | M9: 10.48499 | N9: 7.5572113 | O9: 7.5572113 | P9: 16.29322 | Q9: Veikia trumpiau | R9: 10.651887 | T9: 11.247602 | U9: 11.471015 | W9: 0.4469 | X9: 0.5734 | Y9: -
A11: Pastaba: praeities rezultatai negarantuoja, kad tokie patys ar panašūs rezultatai bus ir ateityje. Įtakos 2019 m. pirmojo pusmečio pensijų fondų rezultatams galėjo turėti skirtingu laiku vykdytas turto perkėlimas į tikslinės grupės ir turto išsaugojimo pensijų fondus bei skirtingas fondų dydis nagrinėjamu laikotarpiu.
A12: [1] Apskaitos vieneto vertės pokytis. Juo atsižvelgiama į atskaitymus nuo turto.
A13: [2] Lyginamasis indeksas apibrėžiamas kaip pensijų kaupimo bendrovės pasirinktas orientacinis investicijų portfelis, atitinkantis fondo investavimo strategiją, su kurio vertės pokyčio reikšme lyginama fondo investicijų portfelio investicijų grąža.
A14: [3] Rodikliui apskaičiuoti naudoti mėnesiniai apskaitos vieneto (lyginamojo indekso) verčių pokyčiai, rezultatas perskaičiuotas į metinį. Standartinis nuokrypis parodo, kaip intensyviai per laikotarpį svyruoja fondo investicinio vieneto vertė (lyginamojo indekso vertė). Kuo šis rodiklis didesnis, tuo didesnė rizika.
A15: [4] Svertiniam vidurkiui apskaičiuoti naudotas 2025-12-31 dienos fondų grynųjų aktyvų dydis.
A16: [5] Investicijų į akcijas dalis, numatyta pensijų fondo strategijoje. Rizikingų turto klasių dalis gali būti padidinta arba sumažinta iki 10 procentinių punktų.
A17: [6] Grynieji aktyvai – pensijų fondą sudarančio turto ir įsipareigojimų verčių skirtumas.
A18: [7] Šie UAB „Swedbank investicijų valdymas“ valdomi pensijų fondai pradėjo veiklą 2018-03-01, tačiau dėl 2019 m. sausio mėnesį įsigaliojusios pensijų pertvarkos pagal galiojančius teisės aktus buvo įsteigti iš naujo, todėl jų rezultatai skaičiuojami nuo 2019 m. sausio 1 d. (kaip ir visų II pakopos pensijų fondų).
A19: [8] Bendrasis atskaitymų rodiklis (BAR) – procentinis dydis, apskaičiuojamas bendrąsias veiklos išlaidas (kurias sudaro atskaitymai nuo pensijų turto) dalijant iš vidutinės atitinkamo laikotarpio grynųjų aktyvų vertės. Kuo šis rodiklis didesnis, tuo daugiau mokesčių yra atskaitoma. Rodiklis skaičiuojamas kartą per metus. Daugiau informacijos apie šį rodiklį ir jo skaičiavimo tvarką galima rasti Lietuvos banko valdybos 2012 m. liepos 12 d. nutarimo Nr. 03-154 „Dėl Valdymo įmonių, kolektyvinio investavimo subjektų ir pensijų fondų informacijos rengimo ir teikimo taisyklių patvirtinimo“ VI skyriuje.
A20: [9] Bendrasis išlaidų koeficientas (BIK) – procentinis dydis, kuris parodo, kokia vidutinė pensijų fondo grynųjų aktyvų dalis skiriama jo valdymo išlaidoms padengti. Kai daugiau kaip 10 proc. pensijų fondo grynųjų aktyvų investuota į kitus kolektyvinio investavimo subjektus (skelbiančius savo BIK), turi būti apskaičiuojamas ir paskelbiamas sąlyginis šio pensijų fondo BIK. Jei ne visi šie kolektyvinio investavimo subjektai skaičiuoja savo BIK, skaičiuojamas tikėtinas sąlyginis tokio pensijų fondo BIK. Šios išlaidos tiesiogiai sumažina investuotojo investicijų grąžą (t. y. kuo šie rodikliai didesni, tuo daugiau mokesčių atskaitoma). Rodikliai skaičiuojami kartą per metus. Daugiau informacijos apie šiuos rodiklius ir jų skaičiavimo tvarką galima rasti Lietuvos banko valdybos 2012 m. liepos 12 d. nutarimo Nr. 03-154 „Dėl Valdymo įmonių, kolektyvinio investavimo subjektų ir pensijų fondų informacijos rengimo ir teikimo taisyklių patvirtinimo“ VI skyriuje.
A21: [10] Apskaičiuota taikant geometrinį vidurkį.
A22: [11] Goindex, UAB valdomi pensijų fondai įsteigti 2022-07-05
... A27: Dešiniau pavaizduoti pensijų fondai prisiima didesnę riziką (jų vieneto vertės svyruoja daugiau). Kairiau – mažesnę (jų vieneto vertės svyruoja mažiau).
A35: Fondas | B35: Rizika | C35: Grąža
A36: LMN-96/02 | B36: 10.06397 | C36: 14.63502
A37: INV-96/02 | B37: 9.5172305 | C37: 13.709859
A38: SBN-96/02 | B38: 10.601815 | C38: 14.576113
A39: SWD-96/02 | B39: 10.956221 | C39: 13.111689
A40: AVI-96/02 | B40: 10.838279 | C40: 16.222712
A41: GOX-96/02 | B41: 11.247602 | C41: 16.439071
A57: Dalyvių skaičiaus, grąžos (per praėjusius 3 metus) ir fondo turto palyginimas
A58: Kuo pensijų fondas paveiksle pavaizduotas aukščiau, tuo jo uždirbama grąža yra didesnė. Kuo žemiau – tuo grąža mažesnė.
A59: Dešiniau pavaizduoti pensijų fondai turi daugiau dalyvių. Kairiau – mažiau.
A60: Kuo didesnis fondą vaizduojančio skritulio dydis – tuo fondas turi daugiau turto. Kuo mažesnis – mažiau.
A65: Fondas | B65: Dalyvių sk. (tūkst.) | C65: Grąža (proc.) | D65: Fondo turtas (mln. Eur)
A66: LMN-96/02 | B66: 14.957 | C66: 14.63502 | D66: 37.472794
A67: INV-96/02 | B67: 19.326 | C67: 13.709859 | D67: 59.517167
A68: SBN-96/02 | B68: 22.171 | C68: 14.576113 | D68: 85.870047
A69: SWD-96/02 | B69: 50.784 | C69: 13.111689 | D69: 188.41916
A70: AVI-96/02 | B70: 19.939 | C70: 16.222712 | D70: 69.952308
A71: GOX-96/02 | B71: 12.84 | C71: 16.439071 | D71: 47.484372

Sheet 1989-1995
A1: 46022 | C1: Grįžti į pagrindinį puslapį | D1: Veiklos laikotarpis, metais | E1: Strategija | F1: Grynųjų aktyvų vertė, mln. Eur [6] | G1: Dalyvių skaičius | I1: Grąža | K1: 0 | N1: 0 | P1: 0 | T1: Rizika [3] | U1: 0 | W1: Išlaidų rodikliai (2024 m.) | X1: 0 | Y1: 0
A2: Pensijų kaupimo bendrovės pavadinimas | B2: Fondo kodas | C2: Pensijų fondo pavadinimas | D2: 0 | E2: rizikingų aktyvų dalis fonde, proc. [5] | F2: 0 | G2: 0 | I2: vieneto vertės pokytis nuo metų pradžios, proc. [1] | J2: vieneto vertės pokytis [1] per praėjusius 1 metus, proc. | K2: vidutinis metinis vieneto vertės pokytis [10] per praėjusius 3 metus, proc. | L2: vidutinis metinis vieneto vertės pokytis [10] per praėjusius 5 metus, proc. | M2: vidutinis metinis vieneto vertės pokytis [1] nuo faktinės GCF [12] pradžios | N2: lyginamojo indekso vertės pokytis nuo metų pradžios, proc. [2] | O2: lyginamojo indekso vertės pokytis [2] per praėjusius 1 metus, proc. | P2: vidutinis lyginamojo indekso vertės pokytis [10] per praėjusius 3 metus, proc. | Q2: vidutinis lyginamojo indekso vertės pokytis [10] per praėjusius 5 metus, proc. | R2: vidutinis metinis lyginamojo indekso vertės pokytis [2] nuo faktinės GCF [12] pradžios | T2: vieneto vertės standartinis nuokrypis, per praėjusius 3 metus, proc. | U2: lyginamojo indekso standartinis nuokrypis, per praėjusius 3 metus, proc. | W2: BAR, proc. [8] | X2: Sąlyginis BIK, proc. [9] | Y2: Tikėtinas sąlyginis BIK, proc. [9]
A3: Tikslinės pensijų fondų dalyvių grupės pensijų fondai, 1989-1995 | B3: 0 | C3: 0 | G3: Svertinis vidurkis [4]: | I3: 6.6840296 | J3: 6.6840296 | K3: 14.079313 | L3: 9.7086262 | M3: 10.850926 | N3: 7.7652444 | O3: 7.7652444 | P3: 16.187721 | Q3: 11.209027 | R3: 12.271585
A4: Luminor investicijų valdymas UAB | B4: LMN-89/95 | C4: Luminor 1989–1995 tikslinės grupės pensijų fondas | D4: 7m. | E4: 90 | F4: 103.47337 | G4: 22623 | I4: 7.5067881 | J4: 7.5067881 | K4: 14.687656 | L4: 8.4278535 | M4: 10.551851 | N4: 8.8673133 | O4: 8.8673133 | P4: 15.678993 | Q4: 10.173084 | R4: 11.673338 | T4: 10.060781 | U4: 10.378472 | W4: 0.49 | X4: 0.71 | Y4: -
A5: UAB Artea Asset Management | B5: INV-89/95 | C5: Artea pensija 1989–1995 Index Plus | D5: 7m. | E5: 97 | F5: 192.49501 | G5: 36524 | I5: 8.0419218 | J5: 8.0419218 | K5: 13.360042 | L5: 10.160751 | M5: 11.038496 | N5: 8.4179276 | O5: 8.4179276 | P5: 15.601022 | Q5: 10.945158 | R5: 12.266888 | T5: 9.070072 | U5: 11.210352 | W5: 0.5 | X5: 1.27 | Y5: 1.27
A6: UAB „SEB investicijų valdymas“ | B6: SBN-89/95 | C6: SEB 1989–1995 metų tikslinės grupės pensijų kaupimo fondas | D6: 7m. | E6: 98 | F6: 279.46909 | G6: 46452 | I6: 6.6755401 | J6: 6.6755401 | K6: 14.353559 | L6: 9.6259649 | M6: 11.049149 | N6: 8.7022104 | O6: 8.7022104 | P6: 17.879221 | Q6: 12.280018 | R6: 13.372685 | T6: 10.476499 | U6: 11.581169 | W6: 0.5 | X6: - | Y6: 0.81
A7: UAB „Swedbank investicijų valdymas“ | B7: SWD-89/95 | C7: Swedbank pensija 1989–1995 [7] | D7: 7m. | E7: 97 | F7: 541.1594 | G7: 96020 | I7: 4.7038235 | J7: 4.7038235 | K7: 12.858817 | L7: 9.461512 | M7: 10.682627 | N7: 7.4805838 | O7: 7.4805838 | P7: 16.213889 | Q7: 11.209001 | R7: 12.314826 | T7: 10.607805 | U7: 11.179359 | W7: 0.41 | X7: - | Y7: 0.683
A8: Allianz Lietuva gyvybės draudimas UAB | B8: AVI-89/95 | C8: Allianz Y2 1989–1995 tikslinės grupės pensijų fondas | D8: 7m. | E8: 90 | F8: 178.95154 | G8: 34360 | I8: 9.9994776 | J8: 9.9994776 | K8: 16.734572 | L8: 10.839231 | M8: 11.213491 | N8: 5.9134873 | O8: 5.9134873 | P8: 14.346589 | Q8: 10.419378 | R8: 11.472872 | T8: 10.162212 | U8: 10.520281 | W8: 0.5 | X8: 0.93 | Y8: -
A9: Goindex, UAB | B9: GOX-89/95 | C9: Goindex pensija 1989–1995 tikslinės grupės pensijų fondas | D9: 3 m. 5 mėn. | E9: 100 | F9: 77.413357 | G9: 13448 | I9: 8.4169884 | J9: 8.4169884 | K9: 16.458556 | L9: Veikia trumpiau | M9: 10.407048 | N9: 7.5572113 | O9: 7.5572113 | P9: 16.29322 | Q9: Veikia trumpiau | R9: 10.651887 | T9: 11.234738 | U9: 11.471015 | W9: 0.4466 | X9: 0.5766 | Y9: -
A11: Pastaba: praeities rezultatai negarantuoja, kad tokie patys ar panašūs rezultatai bus ir ateityje. Įtakos 2019 m. pirmojo pusmečio pensijų fondų rezultatams galėjo turėti skirtingu laiku vykdytas turto perkėlimas į tikslinės grupės ir turto išsaugojimo pensijų fondus bei skirtingas fondų dydis nagrinėjamu laikotarpiu.
A12: [1] Apskaitos vieneto vertės pokytis. Juo atsižvelgiama į atskaitymus nuo turto.
A13: [2] Lyginamasis indeksas apibrėžiamas kaip pensijų kaupimo bendrovės pasirinktas orientacinis investicijų portfelis, atitinkantis fondo investavimo strategiją, su kurio vertės pokyčio reikšme lyginama fondo investicijų portfelio investicijų grąža.
A14: [3] Rodikliui apskaičiuoti naudoti mėnesiniai apskaitos vieneto (lyginamojo indekso) verčių pokyčiai, rezultatas perskaičiuotas į metinį. Standartinis nuokrypis parodo, kaip intensyviai per laikotarpį svyruoja fondo investicinio vieneto vertė (lyginamojo indekso vertė). Kuo šis rodiklis didesnis, tuo didesnė rizika.
A15: [4] Svertiniam vidurkiui apskaičiuoti naudotas 2025-12-31 dienos fondų grynųjų aktyvų dydis.
A16: [5] Investicijų į akcijas dalis, numatyta pensijų fondo strategijoje. Rizikingų turto klasių dalis gali būti padidinta arba sumažinta iki 10 procentinių punktų.
A17: [6] Grynieji aktyvai – pensijų fondą sudarančio turto ir įsipareigojimų verčių skirtumas.
A18: [7] Šie UAB „Swedbank investicijų valdymas“ valdomi pensijų fondai pradėjo veiklą 2018-03-01, tačiau dėl 2019 m. sausio mėnesį įsigaliojusios pensijų pertvarkos pagal galiojančius teisės aktus buvo įsteigti iš naujo, todėl jų rezultatai skaičiuojami nuo 2019 m. sausio 1 d. (kaip ir visų II pakopos pensijų fondų).
A19: [8] Bendrasis atskaitymų rodiklis (BAR) – procentinis dydis, apskaičiuojamas bendrąsias veiklos išlaidas (kurias sudaro atskaitymai nuo pensijų turto) dalijant iš vidutinės atitinkamo laikotarpio grynųjų aktyvų vertės. Kuo šis rodiklis didesnis, tuo daugiau mokesčių yra atskaitoma. Rodiklis skaičiuojamas kartą per metus. Daugiau informacijos apie šį rodiklį ir jo skaičiavimo tvarką galima rasti Lietuvos banko valdybos 2012 m. liepos 12 d. nutarimo Nr. 03-154 „Dėl Valdymo įmonių, kolektyvinio investavimo subjektų ir pensijų fondų informacijos rengimo ir teikimo taisyklių patvirtinimo“ VI skyriuje.
A20: [9] Bendrasis išlaidų koeficientas (BIK) – procentinis dydis, kuris parodo, kokia vidutinė pensijų fondo grynųjų aktyvų dalis skiriama jo valdymo išlaidoms padengti. Kai daugiau kaip 10 proc. pensijų fondo grynųjų aktyvų investuota į kitus kolektyvinio investavimo subjektus (skelbiančius savo BIK), turi būti apskaičiuojamas ir paskelbiamas sąlyginis šio pensijų fondo BIK. Jei ne visi šie kolektyvinio investavimo subjektai skaičiuoja savo BIK, skaičiuojamas tikėtinas sąlyginis tokio pensijų fondo BIK. Šios išlaidos tiesiogiai sumažina investuotojo investicijų grąžą (t. y. kuo šie rodikliai didesni, tuo daugiau mokesčių atskaitoma). Rodikliai skaičiuojami kartą per metus. Daugiau informacijos apie šiuos rodiklius ir jų skaičiavimo tvarką galima rasti Lietuvos banko valdybos 2012 m. liepos 12 d. nutarimo Nr. 03-154 „Dėl Valdymo įmonių, kolektyvinio investavimo subjektų ir pensijų fondų informacijos rengimo ir teikimo taisyklių patvirtinimo“ VI skyriuje.
A21: [10] Apskaičiuota taikant geometrinį vidurkį.
A22: [11] Goindex, UAB valdomi pensijų fondai įsteigti 2022-07-05
... A27: Dešiniau pavaizduoti pensijų fondai prisiima didesnę riziką (jų vieneto vertės svyruoja daugiau). Kairiau – mažesnę (jų vieneto vertės svyruoja mažiau).
A35: Fondas | B35: Rizika | C35: Grąža
A36: LMN-89/95 | B36: 10.060781 | C36: 14.687656
A37: INV-89/95 | B37: 9.070072 | C37: 13.360042
A38: SBN-89/95 | B38: 10.476499 | C38: 14.353559
A39: SWD-89/95 | B39: 10.607805 | C39: 12.858817
A40: AVI-89/95 | B40: 10.162212 | C40: 16.734572
A41: GOX-89/95 | B41: 11.234738 | C41: 16.458556
A57: Dalyvių skaičiaus, grąžos (per praėjusius 3 metus) ir fondo turto palyginimas
A58: Kuo pensijų fondas paveiksle pavaizduotas aukščiau, tuo jo uždirbama grąža yra didesnė. Kuo žemiau – tuo grąža mažesnė.
A59: Dešiniau pavaizduoti pensijų fondai turi daugiau dalyvių. Kairiau – mažiau.
A60: Kuo didesnis fondą vaizduojančio skritulio dydis – tuo fondas turi daugiau turto. Kuo mažesnis – mažiau.
A65: Fondas | B65: Dalyvių sk. (tūkst.) | C65: Grąža (proc.) | D65: Fondo turtas (mln. Eur)
A66: LMN-89/95 | B66: 22.623 | C66: 14.687656 | D66: 103.47337
A67: INV-89/95 | B67: 36.524 | C67: 13.360042 | D67: 192.49501
A68: SBN-89/95 | B68: 46.452 | C68: 14.353559 | D68: 279.46909
A69: SWD-89/95 | B69: 96.02 | C69: 12.858817 | D69: 541.1594
A70: AVI-89/95 | B70: 34.36 | C70: 16.734572 | D70: 178.95154
A71: GOX-89/95 | B71: 13.448 | C71: 16.458556 | D71: 77.413357

Sheet 1982-1988
A1: 46022 | C1: Grįžti į pagrindinį puslapį | D1: Veiklos laikotarpis, metais | E1: Strategija | F1: Grynųjų aktyvų vertė, mln. Eur [6] | G1: Dalyvių skaičius | I1: Grąža | K1: 0 | N1: 0 | P1: 0 | T1: Rizika [3] | U1: 0 | W1: Išlaidų rodikliai (2024 m.) | X1: 0 | Y1: 0
A2: Pensijų kaupimo bendrovės pavadinimas | B2: Fondo kodas | C2: Pensijų fondo pavadinimas | D2: 0 | E2: rizikingų aktyvų dalis fonde, proc. [5] | F2: 0 | G2: 0 | I2: vieneto vertės pokytis nuo metų pradžios, proc. [1] | J2: vieneto vertės pokytis [1] per praėjusius 1 metus, proc. | K2: vidutinis metinis vieneto vertės pokytis [10] per praėjusius 3 metus, proc. | L2: vidutinis metinis vieneto vertės pokytis [10] per praėjusius 5 metus, proc. | M2: vidutinis metinis vieneto vertės pokytis [1] nuo faktinės GCF [12] pradžios | N2: lyginamojo indekso vertės pokytis nuo metų pradžios, proc. [2] | O2: lyginamojo indekso vertės pokytis [2] per praėjusius 1 metus, proc. | P2: vidutinis lyginamojo indekso vertės pokytis [10] per praėjusius 3 metus, proc. | Q2: vidutinis lyginamojo indekso vertės pokytis [10] per praėjusius 5 metus, proc. | R2: vidutinis metinis lyginamojo indekso vertės pokytis [2] nuo faktinės GCF [12] pradžios | T2: vieneto vertės standartinis nuokrypis, per praėjusius 3 metus, proc. | U2: lyginamojo indekso standartinis nuokrypis, per praėjusius 3 metus, proc. | W2: BAR, proc. [8] | X2: Sąlyginis BIK, proc. [9] | Y2: Tikėtinas sąlyginis BIK, proc. [9]
A3: Tikslinės pensijų fondų dalyvių grupės pensijų fondai, 1982-1988 | G3: Svertinis vidurkis [4]: | I3: 6.8018139 | J3: 6.8018139 | K3: 14.120698 | L3: 9.7681313 | M3: 10.94075 | N3: 7.8496558 | O3: 7.8496558 | P3: 16.272348 | Q3: 11.263214 | R3: 12.359967
A4: Luminor investicijų valdymas UAB | B4: LMN-82/88 | C4: Luminor 1982–1988 tikslinės grupės pensijų fondas | D4: 7m. | E4: 90 | F4: 182.51375 | G4: 28878 | I4: 7.4398249 | J4: 7.4398249 | K4: 14.73898 | L4: 8.5308702 | M4: 10.503334 | N4: 8.8673133 | O4: 8.8673133 | P4: 15.678993 | Q4: 10.173084 | R4: 11.673338 | T4: 10.004816 | U4: 10.378472 | W4: 0.49 | X4: 0.72 | Y4: -
A5: UAB Artea Asset Management | B5: INV-82/88 | C5: Artea pensija 1982–1988 Index Plus | D5: 7m. | E5: 97 | F5: 321.58775 | G5: 42682 | I5: 8.1311373 | J5: 8.1311373 | K5: 13.356769 | L5: 10.220276 | M5: 11.02936 | N5: 8.4179276 | O5: 8.4179276 | P5: 15.601022 | Q5: 10.945158 | R5: 12.266888 | T5: 9.0340028 | U5: 11.210352 | W5: 0.5 | X5: 1.26 | Y5: 1.26
A6: UAB „SEB investicijų valdymas“ | B6: SBN-82/88 | C6: SEB 1982–1988 metų tikslinės grupės pensijų kaupimo fondas | D6: 7m. | E6: 98 | F6: 578.57099 | G6: 74338 | I6: 6.6104294 | J6: 6.6104294 | K6: 14.244515 | L6: 9.6034614 | M6: 11.060556 | N6: 8.7022104 | O6: 8.7022104 | P6: 17.879221 | Q6: 12.280018 | R6: 13.372685 | T6: 10.423404 | U6: 11.581169 | W6: 0.5 | X6: - | Y6: 0.82
A7: UAB „Swedbank investicijų valdymas“ | B7: SWD-82/88 | C7: Swedbank pensija 1982–1988 [7] | D7: 7m. | E7: 97 | F7: 733.87588 | G7: 114002 | I7: 4.68405 | J7: 4.68405 | K7: 12.898401 | L7: 9.609903 | M7: 10.836959 | N7: 7.4805838 | O7: 7.4805838 | P7: 16.213889 | Q7: 11.209001 | R7: 12.314826 | T7: 10.600653 | U7: 11.179359 | W7: 0.41 | X7: - | Y7: 0.6896
A8: Allianz Lietuva gyvybės draudimas UAB | B8: AVI-82/88 | C8: Allianz Y1 1982–1988 tikslinės grupės pensijų fondas | D8: 7m. | E8: 90 | F8: 293.01943 | G8: 48030 | I8: 10.186589 | J8: 10.186589 | K8: 16.752115 | L8: 10.763991 | M8: 11.233838 | N8: 5.9134873 | O8: 5.9134873 | P8: 14.346589 | Q8: 10.419378 | R8: 11.472872 | T8: 10.177916 | U8: 10.520281 | W8: 0.5 | X8: 0.97 | Y8: -
A9: Goindex, UAB | B9: GOX-82/88 | C9: Goindex pensija 1982–1988 tikslinės grupės pensijų fondas | D9: 3 m. 5 mėn. | E9: 100 | F9: 80.566328 | G9: 10505 | I9: 8.4049739 | J9: 8.4049739 | K9: 16.443577 | L9: Veikia trumpiau | M9: 10.597084 | N9: 7.5572113 | O9: 7.5572113 | P9: 16.29322 | Q9: Veikia trumpiau | R9: 10.651887 | T9: 11.256195 | U9: 11.471015 | W9: 0.4466 | X9: 0.577 | Y9: -
A11: Pastaba: praeities rezultatai negarantuoja, kad tokie patys ar panašūs rezultatai bus ir ateityje. Įtakos 2019 m. pirmojo pusmečio pensijų fondų rezultatams galėjo turėti skirtingu laiku vykdytas turto perkėlimas į tikslinės grupės ir turto išsaugojimo pensijų fondus bei skirtingas fondų dydis nagrinėjamu laikotarpiu.
A12: [1] Apskaitos vieneto vertės pokytis. Juo atsižvelgiama į atskaitymus nuo turto.
A13: [2] Lyginamasis indeksas apibrėžiamas kaip pensijų kaupimo bendrovės pasirinktas orientacinis investicijų portfelis, atitinkantis fondo investavimo strategiją, su kurio vertės pokyčio reikšme lyginama fondo investicijų portfelio investicijų grąža.
A14: [3] Rodikliui apskaičiuoti naudoti mėnesiniai apskaitos vieneto (lyginamojo indekso) verčių pokyčiai, rezultatas perskaičiuotas į metinį. Standartinis nuokrypis parodo, kaip intensyviai per laikotarpį svyruoja fondo investicinio vieneto vertė (lyginamojo indekso vertė). Kuo šis rodiklis didesnis, tuo didesnė rizika.
A15: [4] Svertiniam vidurkiui apskaičiuoti naudotas 2025-12-31 dienos fondų grynųjų aktyvų dydis.
A16: [5] Investicijų į akcijas dalis, numatyta pensijų fondo strategijoje. Rizikingų turto klasių dalis gali būti padidinta arba sumažinta iki 10 procentinių punktų.
A17: [6] Grynieji aktyvai – pensijų fondą sudarančio turto ir įsipareigojimų verčių skirtumas.
A18: [7] Šie UAB „Swedbank investicijų valdymas“ valdomi pensijų fondai pradėjo veiklą 2018-03-01, tačiau dėl 2019 m. sausio mėnesį įsigaliojusios pensijų pertvarkos pagal galiojančius teisės aktus buvo įsteigti iš naujo, todėl jų rezultatai skaičiuojami nuo 2019 m. sausio 1 d. (kaip ir visų II pakopos pensijų fondų).
A19: [8] Bendrasis atskaitymų rodiklis (BAR) – procentinis dydis, apskaičiuojamas bendrąsias veiklos išlaidas (kurias sudaro atskaitymai nuo pensijų turto) dalijant iš vidutinės atitinkamo laikotarpio grynųjų aktyvų vertės. Kuo šis rodiklis didesnis, tuo daugiau mokesčių yra atskaitoma. Rodiklis skaičiuojamas kartą per metus. Daugiau informacijos apie šį rodiklį ir jo skaičiavimo tvarką galima rasti Lietuvos banko valdybos 2012 m. liepos 12 d. nutarimo Nr. 03-154 „Dėl Valdymo įmonių, kolektyvinio investavimo subjektų ir pensijų fondų informacijos rengimo ir teikimo taisyklių patvirtinimo“ VI skyriuje.
A20: [9] Bendrasis išlaidų koeficientas (BIK) – procentinis dydis, kuris parodo, kokia vidutinė pensijų fondo grynųjų aktyvų dalis skiriama jo valdymo išlaidoms padengti. Kai daugiau kaip 10 proc. pensijų fondo grynųjų aktyvų investuota į kitus kolektyvinio investavimo subjektus (skelbiančius savo BIK), turi būti apskaičiuojamas ir paskelbiamas sąlyginis šio pensijų fondo BIK. Jei ne visi šie kolektyvinio investavimo subjektai skaičiuoja savo BIK, skaičiuojamas tikėtinas sąlyginis tokio pensijų fondo BIK. Šios išlaidos tiesiogiai sumažina investuotojo investicijų grąžą (t. y. kuo šie rodikliai didesni, tuo daugiau mokesčių atskaitoma). Rodikliai skaičiuojami kartą per metus. Daugiau informacijos apie šiuos rodiklius ir jų skaičiavimo tvarką galima rasti Lietuvos banko valdybos 2012 m. liepos 12 d. nutarimo Nr. 03-154 „Dėl Valdymo įmonių, kolektyvinio investavimo subjektų ir pensijų fondų informacijos rengimo ir teikimo taisyklių patvirtinimo“ VI skyriuje.
A21: [10] Apskaičiuota taikant geometrinį vidurkį.
A22: [11] Goindex, UAB valdomi pensijų fondai įsteigti 2022-07-05
... A27: Dešiniau pavaizduoti pensijų fondai prisiima didesnę riziką (jų vieneto vertės svyruoja daugiau). Kairiau – mažesnę (jų vieneto vertės svyruoja mažiau).
A35: Fondas | B35: Rizika | C35: Grąža
A36: LMN-82/88 | B36: 10.004816 | C36: 14.73898
A37: INV-82/88 | B37: 9.0340028 | C37: 13.356769
A38: SBN-82/88 | B38: 10.423404 | C38: 14.244515
A39: SWD-82/88 | B39: 10.600653 | C39: 12.898401
A40: AVI-82/88 | B40: 10.177916 | C40: 16.752115
A41: GOX-82/88 | B41: 11.256195 | C41: 16.443577
A57: Dalyvių skaičiaus, grąžos (per praėjusius 3 metus) ir fondo turto palyginimas
A58: Kuo pensijų fondas paveiksle pavaizduotas aukščiau, tuo jo uždirbama grąža yra didesnė. Kuo žemiau – tuo grąža mažesnė.
A59: Dešiniau pavaizduoti pensijų fondai turi daugiau dalyvių. Kairiau – mažiau.
A60: Kuo didesnis fondą vaizduojančio skritulio dydis – tuo fondas turi daugiau turto. Kuo mažesnis – mažiau.
A65: Fondas | B65: Dalyvių sk. (tūkst.) | C65: Grąža (proc.) | D65: Fondo turtas (mln. Eur)
A66: LMN-82/88 | B66: 28.878 | C66: 14.73898 | D66: 182.51375
A67: INV-82/88 | B67: 42.682 | C67: 13.356769 | D67: 321.58775
A68: SBN-82/88 | B68: 74.338 | C68: 14.244515 | D68: 578.57099
A69: SWD-82/88 | B69: 114.002 | C69: 12.898401 | D69: 733.87588
A70: AVI-82/88 | B70: 48.03 | C70: 16.752115 | D70: 293.01943
A71: GOX-82/88 | B71: 10.505 | C71: 16.443577 | D71: 80.566328

Sheet 1975-1981
A1: 46022 | C1: Grįžti į pagrindinį puslapį | D1: Veiklos laikotarpis, metais | E1: Strategija | F1: Grynųjų aktyvų vertė, mln. Eur [6] | G1: Dalyvių skaičius | I1: Grąža | K1: 0 | N1: 0 | P1: 0 | T1: Rizika [3] | U1: 0 | W1: Išlaidų rodikliai (2024 m.) | X1: 0 | Y1: 0
A2: Pensijų kaupimo bendrovės pavadinimas | B2: Fondo kodas | C2: Pensijų fondo pavadinimas | D2: 0 | E2: rizikingų aktyvų dalis fonde, proc. [5] | F2: 0 | G2: 0 | I2: vieneto vertės pokytis nuo metų pradžios, proc. [1] | J2: vieneto vertės pokytis [1] per praėjusius 1 metus, proc. | K2: vidutinis metinis vieneto vertės pokytis [10] per praėjusius 3 metus, proc. | L2: vidutinis metinis vieneto vertės pokytis [10] per praėjusius 5 metus, proc. | M2: vidutinis metinis vieneto vertės pokytis [1] nuo faktinės GCF [12] pradžios | N2: lyginamojo indekso vertės pokytis nuo metų pradžios, proc. [2] | O2: lyginamojo indekso vertės pokytis [2] per praėjusius 1 metus, proc. | P2: vidutinis lyginamojo indekso vertės pokytis [10] per praėjusius 3 metus, proc. | Q2: vidutinis lyginamojo indekso vertės pokytis [10] per praėjusius 5 metus, proc. | R2: vidutinis metinis lyginamojo indekso vertės pokytis [2] nuo faktinės GCF [12] pradžios | T2: vieneto vertės standartinis nuokrypis, per praėjusius 3 metus, proc. | U2: lyginamojo indekso standartinis nuokrypis, per praėjusius 3 metus, proc. | W2: BAR, proc. [8] | X2: Sąlyginis BIK, proc. [9] | Y2: Tikėtinas sąlyginis BIK, proc. [9]
A3: Tikslinės pensijų fondų dalyvių grupės pensijų fondai, 1975-1981 | G3: Svertinis vidurkis [4]: | I3: 6.7685894 | J3: 6.7685894 | K3: 14.053189 | L3: 9.7338052 | M3: 11.009541 | N3: 7.7981503 | O3: 7.7981503 | P3: 16.289257 | Q3: 11.280439 | R3: 12.514961
A4: Luminor investicijų valdymas UAB | B4: LMN-75/81 | C4: Luminor 1975–1981 tikslinės grupės pensijų fondas | D4: 7m. | E4: 90 | F4: 187.64337 | G4: 19611 | I4: 7.2530864 | J4: 7.2530864 | K4: 14.707147 | L4: 8.6136655 | M4: 10.52213 | N4: 8.8673133 | O4: 8.8673133 | P4: 15.678993 | Q4: 10.173084 | R4: 11.673338 | T4: 9.9957415 | U4: 10.378472 | W4: 0.49 | X4: 0.72 | Y4: -
A5: UAB Artea Asset Management | B5: INV-75/81 | C5: Artea pensija 1975–1981 Index Plus | D5: 7m. | E5: 97 | F5: 311.22315 | G5: 25872 | I5: 7.8482194 | J5: 7.8482194 | K5: 13.133303 | L5: 10.113204 | M5: 11.024028 | N5: 8.1573001 | O5: 8.1573001 | P5: 15.508316 | Q5: 10.891766 | R5: 12.228324 | T5: 8.9049332 | U5: 11.15897 | W5: 0.5 | X5: 1.28 | Y5: 1.28
A6: UAB „SEB investicijų valdymas“ | B6: SBN-75/81 | C6: SEB 1975–1981 metų tikslinės grupės pensijų kaupimo fondas | D6: 7m. | E6: 98 | F6: 686.27158 | G6: 62239 | I6: 6.605523 | J6: 6.605523 | K6: 14.18939 | L6: 9.5762188 | M6: 11.375641 | N6: 8.7021838 | O6: 8.7021838 | P6: 17.879174 | Q6: 12.279917 | R6: 13.822147 | T6: 10.38007 | U6: 11.581183 | W6: 0.5 | X6: - | Y6: 0.82
A7: UAB „Swedbank investicijų valdymas“ | B7: SWD-75/81 | C7: Swedbank pensija 1975–1981 [7] | D7: 7m. | E7: 97 | F7: 838.96081 | G7: 96814 | I7: 4.8716191 | J7: 4.8716191 | K7: 12.889449 | L7: 9.6414824 | M7: 10.860365 | N7: 7.4805838 | O7: 7.4805838 | P7: 16.213889 | Q7: 11.209001 | R7: 12.314826 | T7: 10.523927 | U7: 11.179359 | W7: 0.41 | X7: - | Y7: 0.6963
A8: Allianz Lietuva gyvybės draudimas UAB | B8: AVI-75/81 | C8: Allianz X3 1975–1981 tikslinės grupės pensijų fondas | D8: 7m. | E8: 90 | F8: 345.18833 | G8: 40106 | I8: 10.151612 | J8: 10.151612 | K8: 16.620097 | L8: 10.538326 | M8: 11.004212 | N8: 5.9134873 | O8: 5.9134873 | P8: 14.346589 | Q8: 10.419378 | R8: 11.472872 | T8: 10.172996 | U8: 10.520281 | W8: 0.5 | X8: 0.98 | Y8: -
A9: Goindex, UAB | B9: GOX-75/81 | C9: Goindex pensija 1975–1981 tikslinės grupės pensijų fondas | D9: 3 m. 5 mėn. | E9: 100 | F9: 65.660426 | G9: 5044 | I9: 8.4239759 | J9: 8.4239759 | K9: 16.495647 | L9: Veikia trumpiau | M9: 10.441451 | N9: 7.5572113 | O9: 7.5572113 | P9: 16.29322 | Q9: Veikia trumpiau | R9: 10.651887 | T9: 11.235966 | U9: 11.471015 | W9: 0.4469 | X9: 0.5782 | Y9: -
A11: Pastaba: praeities rezultatai negarantuoja, kad tokie patys ar panašūs rezultatai bus ir ateityje. Įtakos 2019 m. pirmojo pusmečio pensijų fondų rezultatams galėjo turėti skirtingu laiku vykdytas turto perkėlimas į tikslinės grupės ir turto išsaugojimo pensijų fondus bei skirtingas fondų dydis nagrinėjamu laikotarpiu.
A12: [1] Apskaitos vieneto vertės pokytis. Juo atsižvelgiama į atskaitymus nuo turto.
A13: [2] Lyginamasis indeksas apibrėžiamas kaip pensijų kaupimo bendrovės pasirinktas orientacinis investicijų portfelis, atitinkantis fondo investavimo strategiją, su kurio vertės pokyčio reikšme lyginama fondo investicijų portfelio investicijų grąža.
A14: [3] Rodikliui apskaičiuoti naudoti mėnesiniai apskaitos vieneto (lyginamojo indekso) verčių pokyčiai, rezultatas perskaičiuotas į metinį. Standartinis nuokrypis parodo, kaip intensyviai per laikotarpį svyruoja fondo investicinio vieneto vertė (lyginamojo indekso vertė). Kuo šis rodiklis didesnis, tuo didesnė rizika.
A15: [4] Svertiniam vidurkiui apskaičiuoti naudotas 2025-12-31 dienos fondų grynųjų aktyvų dydis.
A16: [5] Investicijų į akcijas dalis, numatyta pensijų fondo strategijoje. Rizikingų turto klasių dalis gali būti padidinta arba sumažinta iki 10 procentinių punktų.
A17: [6] Grynieji aktyvai – pensijų fondą sudarančio turto ir įsipareigojimų verčių skirtumas.
A18: [7] Šie UAB „Swedbank investicijų valdymas“ valdomi pensijų fondai pradėjo veiklą 2018-03-01, tačiau dėl 2019 m. sausio mėnesį įsigaliojusios pensijų pertvarkos pagal galiojančius teisės aktus buvo įsteigti iš naujo, todėl jų rezultatai skaičiuojami nuo 2019 m. sausio 1 d. (kaip ir visų II pakopos pensijų fondų).
A19: [8] Bendrasis atskaitymų rodiklis (BAR) – procentinis dydis, apskaičiuojamas bendrąsias veiklos išlaidas (kurias sudaro atskaitymai nuo pensijų turto) dalijant iš vidutinės atitinkamo laikotarpio grynųjų aktyvų vertės. Kuo šis rodiklis didesnis, tuo daugiau mokesčių yra atskaitoma. Rodiklis skaičiuojamas kartą per metus. Daugiau informacijos apie šį rodiklį ir jo skaičiavimo tvarką galima rasti Lietuvos banko valdybos 2012 m. liepos 12 d. nutarimo Nr. 03-154 „Dėl Valdymo įmonių, kolektyvinio investavimo subjektų ir pensijų fondų informacijos rengimo ir teikimo taisyklių patvirtinimo“ VI skyriuje.
A20: [9] Bendrasis išlaidų koeficientas (BIK) – procentinis dydis, kuris parodo, kokia vidutinė pensijų fondo grynųjų aktyvų dalis skiriama jo valdymo išlaidoms padengti. Kai daugiau kaip 10 proc. pensijų fondo grynųjų aktyvų investuota į kitus kolektyvinio investavimo subjektus (skelbiančius savo BIK), turi būti apskaičiuojamas ir paskelbiamas sąlyginis šio pensijų fondo BIK. Jei ne visi šie kolektyvinio investavimo subjektai skaičiuoja savo BIK, skaičiuojamas tikėtinas sąlyginis tokio pensijų fondo BIK. Šios išlaidos tiesiogiai sumažina investuotojo investicijų grąžą (t. y. kuo šie rodikliai didesni, tuo daugiau mokesčių atskaitoma). Rodikliai skaičiuojami kartą per metus. Daugiau informacijos apie šiuos rodiklius ir jų skaičiavimo tvarką galima rasti Lietuvos banko valdybos 2012 m. liepos 12 d. nutarimo Nr. 03-154 „Dėl Valdymo įmonių, kolektyvinio investavimo subjektų ir pensijų fondų informacijos rengimo ir teikimo taisyklių patvirtinimo“ VI skyriuje.
A21: [10] Apskaičiuota taikant geometrinį vidurkį.
A22: [11] Goindex, UAB valdomi pensijų fondai įsteigti 2022-07-05
... A27: Dešiniau pavaizduoti pensijų fondai prisiima didesnę riziką (jų vieneto vertės svyruoja daugiau). Kairiau – mažesnę (jų vieneto vertės svyruoja mažiau).
A35: Fondas | B35: Rizika | C35: Grąža
A36: LMN-75/81 | B36: 9.9957415 | C36: 14.707147
A37: INV-75/81 | B37: 8.9049332 | C37: 13.133303
A38: SBN-75/81 | B38: 10.38007 | C38: 14.18939
A39: SWD-75/81 | B39: 10.523927 | C39: 12.889449
A40: AVI-75/81 | B40: 10.172996 | C40: 16.620097
A41: GOX-75/81 | B41: 11.235966 | C41: 16.495647
A57: Dalyvių skaičiaus, grąžos (per praėjusius 3 metus) ir fondo turto palyginimas
A58: Kuo pensijų fondas paveiksle pavaizduotas aukščiau, tuo jo uždirbama grąža yra didesnė. Kuo žemiau – tuo grąža mažesnė.
A59: Dešiniau pavaizduoti pensijų fondai turi daugiau dalyvių. Kairiau – mažiau.
A60: Kuo didesnis fondą vaizduojančio skritulio dydis – tuo fondas turi daugiau turto. Kuo mažesnis – mažiau.
A65: Fondas | B65: Dalyvių sk. (tūkst.) | C65: Grąža (proc.) | D65: Fondo turtas (mln. Eur)
A66: INV-75/81 | B66: 25.872 | C66: 13.133303 | D66: 311.22315
A67: LMN-75/81 | B67: 19.611 | C67: 14.707147 | D67: 187.64337
A68: SBN-75/81 | B68: 62.239 | C68: 14.18939 | D68: 686.27158
A69: SWD-75/81 | B69: 96.814 | C69: 12.889449 | D69: 838.96081
A70: AVI-75/81 | B70: 40.106 | C70: 16.620097 | D70: 345.18833
A71: GOX-75/81 | B71: 5.044 | C71: 16.495647 | D71: 65.660426

Sheet 1968-1974
A1: 46022 | C1: Grįžti į pagrindinį puslapį | D1: Veiklos laikotarpis, metais | E1: Strategija | F1: Grynųjų aktyvų vertė, mln. Eur [6] | G1: Dalyvių skaičius | I1: Grąža | K1: 0 | N1: 0 | P1: 0 | T1: Rizika [3] | U1: 0 | W1: Išlaidų rodikliai (2024 m.) | X1: 0 | Y1: 0
