Workbook

Sheet GCF_2019_I_pusm
A1: 43646 | D1: Veiklos laikotarpis, metais | E1: Strategija | F1: Grynųjų aktyvų****** vertė, mln. Eur | G1: Dalyvių skaičius | I1: Grąža | L1: Rizika ***
A2: Pensijų kaupimo bendrovės pavadinimas | B2: Fondo kodas | C2: Pensijų fondo pavadinimas | E2: rizikingų aktyvų dalis fonde, proc. ***** | I2: vieneto vertės pokytis nuo metų pradžios, proc.* | J2: lyginamojo indekso vertės pokytis nuo metų pradžios, proc.** | L2: vieneto vertės standartinis nuokrypis, nuo metų pradžios, proc. | M2: lyginamojo indekso standartinis nuokrypis, nuo metų pradžios, proc.
A3: Tikslinės pensijų fondų dalyvių grupės pensijų fondai, 1996-2002 | G3: Svertinis vidurkis****: | I3: 12.416708 | J3: 14.402367
A4: Luminor investicijų valdymas UAB | B4: LMN-96/02 | C4: Luminor 1996–2002 tikslinės grupės pensijų fondas | D4: 0.49589041 | E4: 90 | F4: 1.3573505 | G4: 2689 | I4: 12.79 | J4: 14.349 | L4: 8.6030399 | M4: 13.629772
A5: UAB „INVL Asset Management“ | B5: INV-96/02 | C5: INVL pensija 1996–2002 | D5: 0.49589041 | E5: 97 | F5: 3.5362719 | G5: 5316 | I5: 11.66 | J5: 14.0587 | L5: 11.588044 | M5: 13.913715
A6: UAB „SEB investicijų valdymas“ | B6: SBN-96/02 | C6: SEB 1996–2002 metų tikslinės grupės pensijų kaupimo fondas | D6: 0.49589041 | E6: 98 | F6: 4.7351963 | G6: 8548 | I6: 14.29 | J6: 14.5133 | L6: 12.889463 | M6: 13.536476
A7: UAB „Swedbank investicijų valdymas“ | B7: SWD-96/02 | C7: Swedbank pensija 1996–2002******* | D7: 0.49589041 | E7: 90 | F7: 10.602895 | G7: 23519 | I7: 12.802945 | J7: 14.274787 | L7: 12.576963 | M7: 13.202445
A8: UAGDPB „Aviva Lietuva“ | B8: AVI-96/02 | C8: Aviva Y3 1996–2002 tikslinės grupės pensijų fondas | D8: 0.49589041 | E8: 90 | F8: 3.6148197 | G8: 8656 | I8: 9.43 | J8: 14.9875 | L8: 12.262372 | M8: 14.461534
A9: Tikslinės pensijų fondų dalyvių grupės pensijų fondai, 1989-1995 | G9: Svertinis vidurkis****: | I9: 12.278497 | J9: 14.389355
A10: Luminor investicijų valdymas UAB | B10: LMN-89/95 | C10: Luminor 1989–1995 tikslinės grupės pensijų fondas | D10: 0.49589041 | E10: 90 | F10: 17.913149 | G10: 14053 | I10: 12.85 | J10: 14.349 | L10: 8.758106 | M10: 13.629772
A11: UAB „INVL Asset Management“ | B11: INV-89/95 | C11: INVL pensija 1989–1995 | D11: 0.49589041 | E11: 97 | F11: 36.57312 | G11: 25922 | I11: 11.85 | J11: 14.0587 | L11: 11.781969 | M11: 13.913715
A12: UAB „SEB investicijų valdymas“ | B12: SBN-89/95 | C12: SEB 1989–1995 metų tikslinės grupės pensijų kaupimo fondas | D12: 0.49589041 | E12: 98 | F12: 43.291193 | G12: 33709 | I12: 13.62 | J12: 14.5133 | L12: 12.543169 | M12: 13.536476
A13: UAB „Swedbank investicijų valdymas“ | B13: SWD-89/95 | C13: Swedbank pensija 1989–1995******* | D13: 0.49589041 | E13: 90 | F13: 98.302401 | G13: 80282 | I13: 13.158709 | J13: 14.274787 | L13: 12.546812 | M13: 13.202445
A14: UAGDPB „Aviva Lietuva“ | B14: AVI-89/95 | C14: Aviva Y2 1989–1995 tikslinės grupės pensijų fondas | D14: 0.49589041 | E14: 90 | F14: 31.284284 | G14: 27117 | I14: 7.83 | J14: 14.9875 | L14: 11.924714 | M14: 14.461534
A15: Tikslinės pensijų fondų dalyvių grupės pensijų fondai, 1982-1988 | G15: Svertinis vidurkis****: | I15: 12.301919 | J15: 14.400263
A16: Luminor investicijų valdymas UAB | B16: LMN-82/88 | C16: Luminor 1982–1988 tikslinės grupės pensijų fondas | D16: 0.49589041 | E16: 90 | F16: 49.946327 | G16: 24695 | I16: 12.56 | J16: 14.349 | L16: 8.7168219 | M16: 13.629772
A17: UAB „INVL Asset Management“ | B17: INV-82/88 | C17: INVL pensija 1982–1988 | D17: 0.49589041 | E17: 97 | F17: 91.930357 | G17: 37324 | I17: 11.52 | J17: 14.0587 | L17: 11.539279 | M17: 13.913715
A18: UAB „SEB investicijų valdymas“ | B18: SBN-82/88 | C18: SEB 1982–1988 metų tikslinės grupės pensijų kaupimo fondas | D18: 0.49589041 | E18: 98 | F18: 142.59913 | G18: 66332 | I18: 13.55 | J18: 14.5133 | L18: 12.469694 | M18: 13.536476
A19: UAB „Swedbank investicijų valdymas“ | B19: SWD-82/88 | C19: Swedbank pensija 1982–1988******* | D19: 0.49589041 | E19: 90 | F19: 186.41144 | G19: 100798 | I19: 13.257615 | J19: 14.274787 | L19: 12.562916 | M19: 13.202445
A20: UAGDPB „Aviva Lietuva“ | B20: AVI-82/88 | C20: Aviva Y1 1982–1988 tikslinės grupės pensijų fondas | D20: 0.49589041 | E20: 90 | F20: 70.213076 | G20: 41303 | I20: 8.07 | J20: 14.9875 | L20: 12.010846 | M20: 14.461534
A21: Tikslinės pensijų fondų dalyvių grupės pensijų fondai, 1975-1981 | G21: Svertinis vidurkis****: | I21: 13.035929 | J21: 15.298515
A22: Luminor investicijų valdymas UAB | B22: LMN-75/81 | C22: Luminor 1975–1981 tikslinės grupės pensijų fondas | D22: 0.49589041 | E22: 90 | F22: 70.33041 | G22: 22441 | I22: 12.18 | J22: 14.349 | L22: 8.1280418 | M22: 13.629772
A23: UAB „INVL Asset Management“ | B23: INV-75/81 | C23: INVL pensija 1975–1981 | D23: 0.49589041 | E23: 97 | F23: 109.96911 | G23: 24964 | I23: 12.08 | J23: 14.0587 | L23: 11.917257 | M23: 13.913715
A24: UAB „SEB investicijų valdymas“ | B24: SBN-75/81 | C24: SEB 1975–1981 metų tikslinės grupės pensijų kaupimo fondas | D24: 0.49589041 | E24: 98 | F24: 213.10218 | G24: 60091 | I24: 15.97 | J24: 17.7318 | L24: 14.233434 | M24: 15.810854
A25: UAB „Swedbank investicijų valdymas“ | B25: SWD-75/81 | C25: Swedbank pensija 1975–1981******* | D25: 0.49589041 | E25: 90 | F25: 277.35841 | G25: 95386 | I25: 13.291925 | J25: 14.274787 | L25: 12.607081 | M25: 13.202445
A26: UAGDPB „Aviva Lietuva“ | B26: AVI-75/81 | C26: Aviva X3 1975–1981 tikslinės grupės pensijų fondas | D26: 0.49589041 | E26: 90 | F26: 101.20975 | G26: 39048 | I26: 7.79 | J26: 14.9875 | L26: 12.008808 | M26: 14.461534
A27: Tikslinės pensijų fondų dalyvių grupės pensijų fondai, 1968-1974 | G27: Svertinis vidurkis****: | I27: 12.090327 | J27: 14.139456
A28: Luminor investicijų valdymas UAB | B28: LMN-68/74 | C28: Luminor 1968–1974 tikslinės grupės pensijų fondas | D28: 0.49589041 | E28: 90 | F28: 74.372099 | G28: 22406 | I28: 12.72 | J28: 14.349 | L28: 8.2566888 | M28: 13.629772
A29: UAB „INVL Asset Management“ | B29: INV-68/74 | C29: INVL pensija 1968–1974 | D29: 0.49589041 | E29: 89 | F29: 103.64374 | G29: 22602 | I29: 12.02 | J29: 14.1045 | L29: 11.38819 | M29: 13.416322
A30: UAB „SEB investicijų valdymas“ | B30: SBN-68/74 | C30: SEB 1968–1974 metų tikslinės grupės pensijų kaupimo fondas | D30: 0.49589041 | E30: 92.9 | F30: 205.25631 | G30: 52661 | I30: 13.32 | J30: 14.0519 | L30: 12.358478 | M30: 12.876623
A31: UAB „Swedbank investicijų valdymas“ | B31: SWD-68/74 | C31: Swedbank pensija 1968–1974******* | D31: 0.49589041 | E31: 90 | F31: 297.90277 | G31: 95031 | I31: 13.330582 | J31: 14.274787 | L31: 12.643298 | M31: 13.202445
A32: UAGDPB „Aviva Lietuva“ | B32: AVI-68/74 | C32: Aviva X2 1968–1974 tikslinės grupės pensijų fondas | D32: 0.49589041 | E32: 83 | F32: 121.80008 | G32: 41303 | I32: 6.66 | J32: 13.8578 | L32: 11.042237 | M32: 13.343421
A33: Tikslinės pensijų fondų dalyvių grupės pensijų fondai, 1961-1967 | G33: Svertinis vidurkis****: | I33: 8.6872972 | J33: 10.362563
A34: Luminor investicijų valdymas UAB | B34: LMN-61/67 | C34: Luminor 1961–1967 tikslinės grupės pensijų fondas | D34: 0.49589041 | E34: 60 | F34: 68.052967 | G34: 20585 | I34: 9.46 | J34: 11.7499 | L34: 5.9337929 | M34: 9.3467927
A35: UAB „INVL Asset Management“ | B35: INV-61/67 | C35: INVL pensija 1961–1967 | D35: 0.49589041 | E35: 54 | F35: 78.231147 | G35: 18230 | I35: 8.86 | J35: 10.167 | L35: 7.0045938 | M35: 8.5709418
A36: UAB „SEB investicijų valdymas“ | B36: SBN-61/67 | C36: SEB 1961–1967 metų tikslinės grupės pensijų kaupimo fondas | D36: 0.49589041 | E36: 58.5 | F36: 181.86018 | G36: 46666 | I36: 9.58 | J36: 10.9504 | L36: 8.065854 | M36: 8.5639744
A37: UAB „Swedbank investicijų valdymas“ | B37: SWD-61/67 | C37: Swedbank pensija 1961–1967******* | D37: 0.49589041 | E37: 60 | F37: 263.13295 | G37: 84692 | I37: 9.5918367 | J37: 10.988503 | L37: 8.7057335 | M37: 9.0485297
A38: UAGDPB „Aviva Lietuva“ | B38: AVI-61/67 | C38: Aviva X1 1961–1967 tikslinės grupės pensijų fondas | D38: 0.49589041 | E38: 43 | F38: 124.14688 | G38: 39616 | I38: 4.93 | J38: 7.5375 | L38: 5.8826533 | M38: 6.9774488
A39: Tikslinės pensijų fondų dalyvių grupės pensijų fondai, 1954-1960 | G39: Svertinis vidurkis****: | I39: 4.9965229 | J39: 6.8010459
A40: Luminor investicijų valdymas UAB | B40: LMN-54/60 | C40: Luminor 1954–1960 tikslinės grupės pensijų fondas | D40: 0.49589041 | E40: 25 | F40: 36.870945 | G40: 10892 | I40: 5.59 | J40: 8.7374 | L40: 3.429621 | M40: 4.5121435
...

Sheet Likviduoti_fondai_2019_I_pusm
A1: 43646
A2: Fondo pavadinimas | B2: Veiklos laikotarpis, metais | C2: Investicijų į akcijas dalis, proc. | D2: FONDŲ GRĄŽA | H2: LYGINAMOJO INDEKSO GRĄŽA*** | J2: RIZIKOS RODIKLIAI
D3: grąža* nuo metų pradžios, proc. | E3: vidutinė metinė grąža** per praėjusius 3 metus, proc. | F3: vidutinė metinė grąža** per praėjusius 5 metus, proc. | G3: vidutinė metinė grąža** per praėjusius 10 metų, proc. | H3: vidutinė metinė lyginamojo indekso grąža per praėjusius 3 metus, proc. | I3: vidutinė metinė lyginamojo indekso grąža per praėjusius 5 metus, proc. | J3: standartinis nuokrypis**** per praėjusius 5 metus, proc. | K3: standartinis nuokrypis**** per praėjusius 10 metų, proc.
A4: KONSERVATYVAUS INVESTAVIMO PENSIJŲ FONDAI
A5: Aviva Europensija******** | B5: 14.920548 | C5: 0 | D5: 0.9909166 | E5: 0.31309898 | F5: 1.7991431 | G5: 3.5829708 | H5: 0.17448989 | I5: 0.74387863 | J5: 1.7044814 | K5: 2.5468775
A6: Swedbank Pensija 1********* | B6: 14.923288 | C6: 0 | D6: 0.74775673 | E6: 0.50718788 | F6: 1.6771485 | G6: 2.3117714 | H6: 0.44923055 | I6: 1.2505887 | J6: 2.0858991 | K6: 1.967455
A7: Luminor pensija 1******* | B7: 14.830137 | C7: 0 | D7: 0.30494957 | E7: -0.29102514 | F7: 0.5123442 | G7: 2.4679566 | H7: 0.48454651 | I7: 1.2829354 | J7: 0.77467284 | K7: 1.6047562
A8: INVL STABILO II 58+***** | B8: 14.638356 | C8: 0 | D8: 0.1618123 | E8: -0.075030628 | F8: 1.093527 | G8: 3.6736104 | H8: 0.28585038 | I8: 0.98328252 | J8: 1.4942674 | K8: 2.1003436
A9: SEB pensija 1****** | B9: 14.827397 | C9: 0 | D9: 0.18315018 | E9: -0.54188333 | F9: 0.28683051 | G9: 1.8049946 | H9: 0.59748448 | I9: 1.4008953 | J9: 0.73408428 | K9: 1.7805054
A10: Swedbank Pensijų išmokų fondas********* | B10: 14.923288 | C10: 0 | D10: 0.67076579 | E10: 0.20745798 | F10: 0.40226923 | G10: 1.0720417 | H10: -0.24898307 | I10: -0.13808174 | J10: 0.34841396 | K10: 0.68809776
A11: MAŽOS AKCIJŲ DALIES PENSIJŲ FONDAI (IKI 30 PROC.)
A12: Aviva Europensija plius******** | B12: 14.920548 | C12: iki 30 | D12: 3.1149098 | E12: 1.3762789 | F12: 2.6309574 | G12: 4.224789 | H12: 1.4969873 | I12: 1.8654509 | J12: 3.5155622 | K12: 3.8430673
A13: Luminor pensija 2******* | B13: 14.830137 | C13: iki 25 | D13: 3.5102209 | E13: 1.5512044 | F13: 2.352713 | G13: 4.2485558 | H13: 2.5766454 | I13: 2.9271268 | J13: 2.8346044 | K13: 3.0902045
A14: INVL MEZZO II 53+***** | B14: 14.638356 | C14: iki 30 | D14: 2.6439646 | E14: 2.6615783 | F14: 3.6645683 | G14: 6.4078751 | H14: 3.6338964 | I14: 4.7999802 | J14: 3.8128481 | K14: 4.9487058
A15: Swedbank Pensija 2********* | B15: 14.923288 | C15: iki 30 | D15: 3.8209607 | E15: 2.3613122 | F15: 2.9479345 | G15: 4.4490029 | H15: 3.2184169 | I15: 4.0400907 | J15: 3.1394377 | K15: 3.2892779
A16: VIDUTINĖS AKCIJŲ DALIES PENSIJŲ FONDAI (IKI 70 PROC.)
A17: Aviva Europensija ekstra******** | B17: 13.273973 | C17: iki 65 | D17: 4.7282992 | E17: 2.0317582 | F17: 3.3437294 | G17: 5.0048568 | H17: 2.7884693 | I17: 2.9338936 | J17: 5.3316217 | K17: 5.7892174
A18: Luminor pensija 3******* | B18: 14.830137 | C18: iki 50 | D18: 6.4449455 | E18: 3.4195017 | F18: 3.9001314 | G18: 5.8315932 | H18: 4.6644661 | I18: 4.534044 | J18: 4.9561849 | K18: 5.1213282
A19: INVL MEDIO II 47+ ***** | B19: 11.219178 | C19: iki 70 | D19: 3.9721765 | E19: 4.5140235 | F19: 5.5956832 | G19: 6.3955348 | H19: 4.9044573 | I19: 6.1600761 | J19: 6.3315648 | K19: 6.2921203
A20: SEB pensija 2****** | B20: 14.827397 | C20: 20–60 | D20: 8.5611654 | E20: 4.0833692 | F20: 3.5629727 | G20: 5.6447425 | H20: 5.770257 | I20: 4.6000182 | J20: 6.418846 | K20: 6.2322936
A21: Swedbank Pensija 3********* | B21: 14.923288 | C21: iki 50 | D21: 5.8473736 | E21: 3.8481092 | F21: 4.1541527 | G21: 5.5529728 | H21: 4.8666832 | I21: 5.2407485 | J21: 5.0943387 | K21: 4.9955449
A22: Swedbank Pensija 4********* | B22: 13.410959 | C22: iki 70 | D22: 8.0773043 | E22: 5.189998 | F22: 5.0905078 | G22: 6.6497175 | H22: 6.4927252 | I22: 6.3421444 | J22: 6.9859558 | K22: 7.357476
A23: AKCIJŲ PENSIJŲ FONDAI (IKI 100 PROC.)
A24: Luminor pensija 4******* | B24: 1.8493151 | C24: iki 100 | D24: 15.266701 | E24: - | F24: - | G24: - | H24: - | I24: - | J24: - | K24: -
A25: INVL EXTREMO II 16+***** | B25: 11.263014 | C25: iki 100 | D25: 7.0710456 | E25: 8.0411605 | F25: 8.0885916 | G25: 7.6504056 | H25: 7.7136528 | I25: 8.0339954 | J25: 11.055117 | K25: 9.7187567
A26: SEB pensija 3****** | B26: 13.046575 | C26: 60–100 | D26: 14.698429 | E26: 8.0104024 | F26: 6.3707862 | G26: 8.028976 | H26: 9.7284721 | I26: 7.2709406 | J26: 10.270703 | K26: 10.210868
A27: Swedbank Pensija 5********* | B27: 8.0328767 | C27: iki 100 | D27: 11.405197 | E27: 7.3042506 | F27: 6.5133505 | G27: - | H27: 8.8879818 | I27: 7.8799431 | J27: 10.048604 | K27: -
A29: Pastaba: praeities rezultatai negarantuoja, kad tokie patys ar panašūs rezultatai bus ir ateityje.
A30: * Apskaitos vieneto vertės pokytis.
A31: ** Apskaičiuota remiantis apskaitos vieneto vertės pokyčiu per nurodytą laikotarpį. Vidutinė metinė grąža gauta taikant geometrinį vidurkį.
A32: *** Lyginamasis indeksas apibrėžiamas kaip pensijų kaupimo bendrovės pasirinktas orientacinis investicijų portfelis, atitinkantis fondo investavimo strategiją, su kurio vertės pokyčio reikšme lyginama fondo investicijų portfelio investicijų grąža.
A33: **** Rodikliui apskaičiuoti naudoti mėnesiniai apskaitos vieneto verčių pokyčiai, rezultatas perskaičiuotas į metinį. Standartinis nuokrypis parodo, kaip intensyviai per laikotarpį svyruoja fondo investicinio vieneto vertė. Kuo šis rodiklis didesnis, tuo didesnė rizika.
A34: ***** UAB „INVL Asset Management“ 2019-02-01 atliko šių fondų dalyvių ir turto perkėlimą į naujuosius tikslinės grupės pensijų fondus. Šie pensijų fondai veikė iki 2019 m. sausio 31 d. Visi rodikliai apskaičiuoti pagal sausio 31 d. pabaigos duomenis.
A35: ****** UAB „SEB investicijų valdymas“ 2019-04-11 atliko šių fondų dalyvių ir turto perkėlimą į naujuosius tikslinės grupės pensijų fondus. Šie pensijų fondai veikė iki 2019 m. balandžio 10 d. Visi rodikliai apskaičiuoti pagal balandžio 10 d. pabaigos duomenis.
A36: ******* Luminor investicijų valdymas UAB 2019-04-12 atliko šių fondų dalyvių ir turto perkėlimą į naujuosius tikslinės grupės pensijų fondus. Šie pensijų fondai veikė iki 2019 m. balandžio 11 d. Visi rodikliai apskaičiuoti pagal balandžio 11 d. pabaigos duomenis.
A37: ******** UAGDPB „Aviva Lietuva“ 2019-05-15 atliko šių fondų dalyvių ir turto perkėlimą į naujuosius tikslinės grupės pensijų fondus. Šie pensijų fondai veikė iki 2019 m. gegužės 14 d. Visi rodikliai apskaičiuoti pagal gegužės 14 d. pabaigos duomenis.
A38: ********* UAB „Swedbank investicijų valdymas“ 2019-05-16 atliko šių fondų dalyvių ir turto perkėlimą į naujuosius tikslinės grupės pensijų fondus. Šie pensijų fondai veikė iki 2019 m. gegužės 15 d. Visi rodikliai apskaičiuoti pagal gegužės 15 d. pabaigos duomenis.

Sheet 1996-2002
A1: =+GCF_2019_I_pusm!A1 -> 43646 | C1: Grįžti į pagrindinį puslapį | D1: =+GCF_2019_I_pusm!D1 -> Veiklos laikotarpis, metais | E1: =+GCF_2019_I_pusm!E1 -> Strategija | F1: =+GCF_2019_I_pusm!F1 -> Grynųjų aktyvų****** vertė, mln. Eur | G1: =+GCF_2019_I_pusm!G1 -> Dalyvių skaičius | I1: =+GCF_2019_I_pusm!I1 -> Grąža | J1: =+GCF_2019_I_pusm!J1 -> 0 | L1: =+GCF_2019_I_pusm!L1 -> Rizika *** | M1: =+GCF_2019_I_pusm!M1 -> 0
A2: =+GCF_2019_I_pusm!A2 -> Pensijų kaupimo bendrovės pavadinimas | B2: =+GCF_2019_I_pusm!B2 -> Fondo kodas | C2: =+GCF_2019_I_pusm!C2 -> Pensijų fondo pavadinimas | D2: =+GCF_2019_I_pusm!D2 -> 0 | E2: =+GCF_2019_I_pusm!E2 -> rizikingų aktyvų dalis fonde, proc. ***** | F2: =+GCF_2019_I_pusm!F2 -> 0 | G2: =+GCF_2019_I_pusm!G2 -> 0 | I2: =+GCF_2019_I_pusm!I2 -> vieneto vertės pokytis nuo metų pradžios, proc.* | J2: =+GCF_2019_I_pusm!J2 -> lyginamojo indekso vertės pokytis nuo metų pradžios, proc.** | L2: =+GCF_2019_I_pusm!L2 -> vieneto vertės standartinis nuokrypis, nuo metų pradžios, proc. | M2: =+GCF_2019_I_pusm!M2 -> lyginamojo indekso standartinis nuokrypis, nuo metų pradžios, proc.
A3: =+GCF_2019_I_pusm!A3 -> Tikslinės pensijų fondų dalyvių grupės pensijų fondai, 1996-2002 | G3: =+GCF_2019_I_pusm!G3 -> Svertinis vidurkis****: | I3: =+GCF_2019_I_pusm!I3 -> 12.416708 | J3: =+GCF_2019_I_pusm!J3 -> 14.402367
A4: =+GCF_2019_I_pusm!A4 -> Luminor investicijų valdymas UAB | B4: =+GCF_2019_I_pusm!B4 -> LMN-96/02 | C4: =+GCF_2019_I_pusm!C4 -> Luminor 1996–2002 tikslinės grupės pensijų fondas | D4: =+GCF_2019_I_pusm!D4 -> 0.49589041 | E4: =+GCF_2019_I_pusm!E4 -> 90 | F4: =+GCF_2019_I_pusm!F4 -> 1.3573505 | G4: =+GCF_2019_I_pusm!G4 -> 2689 | I4: =+GCF_2019_I_pusm!I4 -> 12.79 | J4: =+GCF_2019_I_pusm!J4 -> 14.349 | L4: =+GCF_2019_I_pusm!L4 -> 8.6030399 | M4: =+GCF_2019_I_pusm!M4 -> 13.629772
A5: =+GCF_2019_I_pusm!A5 -> UAB „INVL Asset Management“ | B5: =+GCF_2019_I_pusm!B5 -> INV-96/02 | C5: =+GCF_2019_I_pusm!C5 -> INVL pensija 1996–2002 | D5: =+GCF_2019_I_pusm!D5 -> 0.49589041 | E5: =+GCF_2019_I_pusm!E5 -> 97 | F5: =+GCF_2019_I_pusm!F5 -> 3.5362719 | G5: =+GCF_2019_I_pusm!G5 -> 5316 | I5: =+GCF_2019_I_pusm!I5 -> 11.66 | J5: =+GCF_2019_I_pusm!J5 -> 14.0587 | L5: =+GCF_2019_I_pusm!L5 -> 11.588044 | M5: =+GCF_2019_I_pusm!M5 -> 13.913715
A6: =+GCF_2019_I_pusm!A6 -> UAB „SEB investicijų valdymas“ | B6: =+GCF_2019_I_pusm!B6 -> SBN-96/02 | C6: =+GCF_2019_I_pusm!C6 -> SEB 1996–2002 metų tikslinės grupės pensijų kaupimo fondas | D6: =+GCF_2019_I_pusm!D6 -> 0.49589041 | E6: =+GCF_2019_I_pusm!E6 -> 98 | F6: =+GCF_2019_I_pusm!F6 -> 4.7351963 | G6: =+GCF_2019_I_pusm!G6 -> 8548 | I6: =+GCF_2019_I_pusm!I6 -> 14.29 | J6: =+GCF_2019_I_pusm!J6 -> 14.5133 | L6: =+GCF_2019_I_pusm!L6 -> 12.889463 | M6: =+GCF_2019_I_pusm!M6 -> 13.536476
A7: =+GCF_2019_I_pusm!A7 -> UAB „Swedbank investicijų valdymas“ | B7: =+GCF_2019_I_pusm!B7 -> SWD-96/02 | C7: =+GCF_2019_I_pusm!C7 -> Swedbank pensija 1996–2002******* | D7: =+GCF_2019_I_pusm!D7 -> 0.49589041 | E7: =+GCF_2019_I_pusm!E7 -> 90 | F7: =+GCF_2019_I_pusm!F7 -> 10.602895 | G7: =+GCF_2019_I_pusm!G7 -> 23519 | I7: =+GCF_2019_I_pusm!I7 -> 12.802945 | J7: =+GCF_2019_I_pusm!J7 -> 14.274787 | L7: =+GCF_2019_I_pusm!L7 -> 12.576963 | M7: =+GCF_2019_I_pusm!M7 -> 13.202445
A8: =+GCF_2019_I_pusm!A8 -> UAGDPB „Aviva Lietuva“ | B8: =+GCF_2019_I_pusm!B8 -> AVI-96/02 | C8: =+GCF_2019_I_pusm!C8 -> Aviva Y3 1996–2002 tikslinės grupės pensijų fondas | D8: =+GCF_2019_I_pusm!D8 -> 0.49589041 | E8: =+GCF_2019_I_pusm!E8 -> 90 | F8: =+GCF_2019_I_pusm!F8 -> 3.6148197 | G8: =+GCF_2019_I_pusm!G8 -> 8656 | I8: =+GCF_2019_I_pusm!I8 -> 9.43 | J8: =+GCF_2019_I_pusm!J8 -> 14.9875 | L8: =+GCF_2019_I_pusm!L8 -> 12.262372 | M8: =+GCF_2019_I_pusm!M8 -> 14.461534
A10: =+GCF_2019_I_pusm!A54 -> Pastaba: praeities rezultatai negarantuoja, kad tokie patys ar panašūs rezultatai bus ir ateityje. Įtakos 2019 m. pirmojo pusmečio pensijų fondų rezultatams galėjo turėti skirtingu laiku vykdytas turto perkėlimas į tikslinės grupės ir turto išsaugojimo pensijų fondus bei skirtingas fondų dydis nagrinėjamu laikotarpiu.
A11: =+GCF_2019_I_pusm!A55 -> * Apskaitos vieneto vertės pokytis. Juo atsižvelgiama į atskaitymus nuo turto.
A12: =+GCF_2019_I_pusm!A56 -> ** Lyginamasis indeksas apibrėžiamas kaip pensijų kaupimo bendrovės pasirinktas orientacinis investicijų portfelis, atitinkantis fondo investavimo strategiją, su kurio vertės pokyčio reikšme lyginama fondo investicijų portfelio investicijų grąža.
A13: =+GCF_2019_I_pusm!A57 -> *** Rodikliui apskaičiuoti naudoti mėnesiniai apskaitos vieneto (lyginamojo indekso) verčių pokyčiai, rezultatas perskaičiuotas į metinį. Standartinis nuokrypis parodo, kaip intensyviai per laikotarpį svyruoja fondo investicinio vieneto vertė (lyginamojo indekso vertė). Kuo šis rodiklis didesnis, tuo didesnė rizika.
A14: =+GCF_2019_I_pusm!A58 -> **** Svertiniam vidurkiui apskaičiuoti naudotas 2019-06-30 dienos fondų grynųjų aktyvų dydis.
A15: =+GCF_2019_I_pusm!A59 -> ***** Investicijų į akcijas dalis. Rizikingų turto klasių dalis gali būti padidinta arba sumažinta iki 10 procentinių punktų.
A16: =+GCF_2019_I_pusm!A60 -> ****** Grynieji aktyvai – pensijų fondą sudarančio turto ir įsipareigojimų verčių skirtumas.
A17: =+GCF_2019_I_pusm!A61 -> ******* Šie UAB „Swedbank investicijų valdymas“ valdomi pensijų fondai pradėjo veiklą 2018-03-01, tačiau dėl 2019 m. sausio mėnesį įsigaliojusios pensijų pertvarkos pagal galiojančius teisės aktus buvo įsteigti iš naujo, todėl jų rezultatai skaičiuojami nuo 2019 m. sausio 1 d. (kaip ir visų II pakopos pensijų fondų).
A19: Rizikos ir grąžos palyginimas
A20: Kuo pensijų fondas paveiksle vaizduojamas aukščiau, tuo jo uždirbama grąža yra didesnė. Kuo žemiau – tuo grąža mažesnė.
A21: Dešiniau pavaizduoti pensijų fondai prisiima didesnę riziką (jų vieneto vertės svyruoja daugiau). Kairiau – mažesnę (jų vieneto vertės svyruoja mažiau).
A29: Fondas | B29: Rizika | C29: Grąža
A30: =+B4 -> LMN-96/02 | B30: =+L4 -> 8.6030399 | C30: =+I4 -> 12.79
A31: =+B5 -> INV-96/02 | B31: =+L5 -> 11.588044 | C31: =+I5 -> 11.66
A32: =+B6 -> SBN-96/02 | B32: =+L6 -> 12.889463 | C32: =+I6 -> 14.29
A33: =+B7 -> SWD-96/02 | B33: =+L7 -> 12.576963 | C33: =+I7 -> 12.802945
A34: =+B8 -> AVI-96/02 | B34: =+L8 -> 12.262372 | C34: =+I8 -> 9.43
A51: Dalyvių skaičiaus, grąžos ir fondo turto palyginimas
A52: Kuo pensijų fondas paveiksle pavaizduotas aukščiau, tuo jo uždirbama grąža yra didesnė. Kuo žemiau – tuo grąža mažesnė.
A53: Dešiniau pavaizduoti pensijų fondai turi daugiau dalyvių. Kairiau – mažiau.
A54: Kuo didesnis fondą vaizduojančio skritulio dydis – tuo fondas turi daugiau turto. Kuo mažesnis – mažiau.
A59: Fondas | B59: Dalyvių sk. (tūkst.) | C59: Grąža (proc.) | D59: Fondo turtas (mln. Eur)
A60: =+B4 -> LMN-96/02 | B60: =+G4/1000 -> 2.689 | C60: =+I4 -> 12.79 | D60: =+F4 -> 1.3573505
A61: =+B5 -> INV-96/02 | B61: =+G5/1000 -> 5.316 | C61: =+I5 -> 11.66 | D61: =+F5 -> 3.5362719
A62: =+B6 -> SBN-96/02 | B62: =+G6/1000 -> 8.548 | C62: =+I6 -> 14.29 | D62: =+F6 -> 4.7351963
A63: =+B7 -> SWD-96/02 | B63: =+G7/1000 -> 23.519 | C63: =+I7 -> 12.802945 | D63: =+F7 -> 10.602895
A64: =+B8 -> AVI-96/02 | B64: =+G8/1000 -> 8.656 | C64: =+I8 -> 9.43 | D64: =+F8 -> 3.6148197

Sheet 1989-1995
A1: =+GCF_2019_I_pusm!A1 -> 43646 | C1: Grįžti į pagrindinį puslapį | D1: =+GCF_2019_I_pusm!D1 -> Veiklos laikotarpis, metais | E1: =+GCF_2019_I_pusm!E1 -> Strategija | F1: =+GCF_2019_I_pusm!F1 -> Grynųjų aktyvų****** vertė, mln. Eur | G1: =+GCF_2019_I_pusm!G1 -> Dalyvių skaičius | I1: =+GCF_2019_I_pusm!I1 -> Grąža | J1: =+GCF_2019_I_pusm!J1 -> 0 | L1: =+GCF_2019_I_pusm!L1 -> Rizika *** | M1: =+GCF_2019_I_pusm!M1 -> 0
A2: =+GCF_2019_I_pusm!A2 -> Pensijų kaupimo bendrovės pavadinimas | B2: =+GCF_2019_I_pusm!B2 -> Fondo kodas | C2: =+GCF_2019_I_pusm!C2 -> Pensijų fondo pavadinimas | D2: =+GCF_2019_I_pusm!D2 -> 0 | E2: =+GCF_2019_I_pusm!E2 -> rizikingų aktyvų dalis fonde, proc. ***** | F2: =+GCF_2019_I_pusm!F2 -> 0 | G2: =+GCF_2019_I_pusm!G2 -> 0 | I2: =+GCF_2019_I_pusm!I2 -> vieneto vertės pokytis nuo metų pradžios, proc.* | J2: =+GCF_2019_I_pusm!J2 -> lyginamojo indekso vertės pokytis nuo metų pradžios, proc.** | L2: =+GCF_2019_I_pusm!L2 -> vieneto vertės standartinis nuokrypis, nuo metų pradžios, proc. | M2: =+GCF_2019_I_pusm!M2 -> lyginamojo indekso standartinis nuokrypis, nuo metų pradžios, proc.
A3: =+GCF_2019_I_pusm!A9 -> Tikslinės pensijų fondų dalyvių grupės pensijų fondai, 1989-1995 | G3: =+GCF_2019_I_pusm!G9 -> Svertinis vidurkis****: | I3: =+GCF_2019_I_pusm!I9 -> 12.278497 | J3: =+GCF_2019_I_pusm!J9 -> 14.389355
A4: =+GCF_2019_I_pusm!A10 -> Luminor investicijų valdymas UAB | B4: =+GCF_2019_I_pusm!B10 -> LMN-89/95 | C4: =+GCF_2019_I_pusm!C10 -> Luminor 1989–1995 tikslinės grupės pensijų fondas | D4: =+GCF_2019_I_pusm!D10 -> 0.49589041 | E4: =+GCF_2019_I_pusm!E10 -> 90 | F4: =+GCF_2019_I_pusm!F10 -> 17.913149 | G4: =+GCF_2019_I_pusm!G10 -> 14053 | I4: =+GCF_2019_I_pusm!I10 -> 12.85 | J4: =+GCF_2019_I_pusm!J10 -> 14.349 | L4: =+GCF_2019_I_pusm!L10 -> 8.758106 | M4: =+GCF_2019_I_pusm!M10 -> 13.629772
A5: =+GCF_2019_I_pusm!A11 -> UAB „INVL Asset Management“ | B5: =+GCF_2019_I_pusm!B11 -> INV-89/95 | C5: =+GCF_2019_I_pusm!C11 -> INVL pensija 1989–1995 | D5: =+GCF_2019_I_pusm!D11 -> 0.49589041 | E5: =+GCF_2019_I_pusm!E11 -> 97 | F5: =+GCF_2019_I_pusm!F11 -> 36.57312 | G5: =+GCF_2019_I_pusm!G11 -> 25922 | I5: =+GCF_2019_I_pusm!I11 -> 11.85 | J5: =+GCF_2019_I_pusm!J11 -> 14.0587 | L5: =+GCF_2019_I_pusm!L11 -> 11.781969 | M5: =+GCF_2019_I_pusm!M11 -> 13.913715
A6: =+GCF_2019_I_pusm!A12 -> UAB „SEB investicijų valdymas“ | B6: =+GCF_2019_I_pusm!B12 -> SBN-89/95 | C6: =+GCF_2019_I_pusm!C12 -> SEB 1989–1995 metų tikslinės grupės pensijų kaupimo fondas | D6: =+GCF_2019_I_pusm!D12 -> 0.49589041 | E6: =+GCF_2019_I_pusm!E12 -> 98 | F6: =+GCF_2019_I_pusm!F12 -> 43.291193 | G6: =+GCF_2019_I_pusm!G12 -> 33709 | I6: =+GCF_2019_I_pusm!I12 -> 13.62 | J6: =+GCF_2019_I_pusm!J12 -> 14.5133 | L6: =+GCF_2019_I_pusm!L12 -> 12.543169 | M6: =+GCF_2019_I_pusm!M12 -> 13.536476
A7: =+GCF_2019_I_pusm!A13 -> UAB „Swedbank investicijų valdymas“ | B7: =+GCF_2019_I_pusm!B13 -> SWD-89/95 | C7: =+GCF_2019_I_pusm!C13 -> Swedbank pensija 1989–1995******* | D7: =+GCF_2019_I_pusm!D13 -> 0.49589041 | E7: =+GCF_2019_I_pusm!E13 -> 90 | F7: =+GCF_2019_I_pusm!F13 -> 98.302401 | G7: =+GCF_2019_I_pusm!G13 -> 80282 | I7: =+GCF_2019_I_pusm!I13 -> 13.158709 | J7: =+GCF_2019_I_pusm!J13 -> 14.274787 | L7: =+GCF_2019_I_pusm!L13 -> 12.546812 | M7: =+GCF_2019_I_pusm!M13 -> 13.202445
A8: =+GCF_2019_I_pusm!A14 -> UAGDPB „Aviva Lietuva“ | B8: =+GCF_2019_I_pusm!B14 -> AVI-89/95 | C8: =+GCF_2019_I_pusm!C14 -> Aviva Y2 1989–1995 tikslinės grupės pensijų fondas | D8: =+GCF_2019_I_pusm!D14 -> 0.49589041 | E8: =+GCF_2019_I_pusm!E14 -> 90 | F8: =+GCF_2019_I_pusm!F14 -> 31.284284 | G8: =+GCF_2019_I_pusm!G14 -> 27117 | I8: =+GCF_2019_I_pusm!I14 -> 7.83 | J8: =+GCF_2019_I_pusm!J14 -> 14.9875 | L8: =+GCF_2019_I_pusm!L14 -> 11.924714 | M8: =+GCF_2019_I_pusm!M14 -> 14.461534
A10: =+GCF_2019_I_pusm!A54 -> Pastaba: praeities rezultatai negarantuoja, kad tokie patys ar panašūs rezultatai bus ir ateityje. Įtakos 2019 m. pirmojo pusmečio pensijų fondų rezultatams galėjo turėti skirtingu laiku vykdytas turto perkėlimas į tikslinės grupės ir turto išsaugojimo pensijų fondus bei skirtingas fondų dydis nagrinėjamu laikotarpiu.
A11: =+GCF_2019_I_pusm!A55 -> * Apskaitos vieneto vertės pokytis. Juo atsižvelgiama į atskaitymus nuo turto.
A12: =+GCF_2019_I_pusm!A56 -> ** Lyginamasis indeksas apibrėžiamas kaip pensijų kaupimo bendrovės pasirinktas orientacinis investicijų portfelis, atitinkantis fondo investavimo strategiją, su kurio vertės pokyčio reikšme lyginama fondo investicijų portfelio investicijų grąža.
A13: =+GCF_2019_I_pusm!A57 -> *** Rodikliui apskaičiuoti naudoti mėnesiniai apskaitos vieneto (lyginamojo indekso) verčių pokyčiai, rezultatas perskaičiuotas į metinį. Standartinis nuokrypis parodo, kaip intensyviai per laikotarpį svyruoja fondo investicinio vieneto vertė (lyginamojo indekso vertė). Kuo šis rodiklis didesnis, tuo didesnė rizika.
A14: =+GCF_2019_I_pusm!A58 -> **** Svertiniam vidurkiui apskaičiuoti naudotas 2019-06-30 dienos fondų grynųjų aktyvų dydis.
A15: =+GCF_2019_I_pusm!A59 -> ***** Investicijų į akcijas dalis. Rizikingų turto klasių dalis gali būti padidinta arba sumažinta iki 10 procentinių punktų.
A16: =+GCF_2019_I_pusm!A60 -> ****** Grynieji aktyvai – pensijų fondą sudarančio turto ir įsipareigojimų verčių skirtumas.
A17: =+GCF_2019_I_pusm!A61 -> ******* Šie UAB „Swedbank investicijų valdymas“ valdomi pensijų fondai pradėjo veiklą 2018-03-01, tačiau dėl 2019 m. sausio mėnesį įsigaliojusios pensijų pertvarkos pagal galiojančius teisės aktus buvo įsteigti iš naujo, todėl jų rezultatai skaičiuojami nuo 2019 m. sausio 1 d. (kaip ir visų II pakopos pensijų fondų).
A19: =+'1996-2002'!A19 -> Rizikos ir grąžos palyginimas
A20: =+'1996-2002'!A20 -> Kuo pensijų fondas paveiksle vaizduojamas aukščiau, tuo jo uždirbama grąža yra didesnė. Kuo žemiau – tuo grąža mažesnė.
A21: =+'1996-2002'!A21 -> Dešiniau pavaizduoti pensijų fondai prisiima didesnę riziką (jų vieneto vertės svyruoja daugiau). Kairiau – mažesnę (jų vieneto vertės svyruoja mažiau).
A29: Fondas | B29: Rizika | C29: Grąža
A30: =+B4 -> LMN-89/95 | B30: =+L4 -> 8.758106 | C30: =+I4 -> 12.85
A31: =+B5 -> INV-89/95 | B31: =+L5 -> 11.781969 | C31: =+I5 -> 11.85
A32: =+B6 -> SBN-89/95 | B32: =+L6 -> 12.543169 | C32: =+I6 -> 13.62
A33: =+B7 -> SWD-89/95 | B33: =+L7 -> 12.546812 | C33: =+I7 -> 13.158709
A34: =+B8 -> AVI-89/95 | B34: =+L8 -> 11.924714 | C34: =+I8 -> 7.83
A51: =+'1996-2002'!A51 -> Dalyvių skaičiaus, grąžos ir fondo turto palyginimas
A52: =+'1996-2002'!A52 -> Kuo pensijų fondas paveiksle pavaizduotas aukščiau, tuo jo uždirbama grąža yra didesnė. Kuo žemiau – tuo grąža mažesnė.
A53: =+'1996-2002'!A53 -> Dešiniau pavaizduoti pensijų fondai turi daugiau dalyvių. Kairiau – mažiau.
A54: =+'1996-2002'!A54 -> Kuo didesnis fondą vaizduojančio skritulio dydis – tuo fondas turi daugiau turto. Kuo mažesnis – mažiau.
A59: Fondas | B59: Dalyvių sk. (tūkst.) | C59: Grąža (proc.) | D59: Fondo turtas (mln. Eur)
A60: =+B4 -> LMN-89/95 | B60: =+G4/1000 -> 14.053 | C60: =+I4 -> 12.85 | D60: =+F4 -> 17.913149
A61: =+B5 -> INV-89/95 | B61: =+G5/1000 -> 25.922 | C61: =+I5 -> 11.85 | D61: =+F5 -> 36.57312
A62: =+B6 -> SBN-89/95 | B62: =+G6/1000 -> 33.709 | C62: =+I6 -> 13.62 | D62: =+F6 -> 43.291193
A63: =+B7 -> SWD-89/95 | B63: =+G7/1000 -> 80.282 | C63: =+I7 -> 13.158709 | D63: =+F7 -> 98.302401
A64: =+B8 -> AVI-89/95 | B64: =+G8/1000 -> 27.117 | C64: =+I8 -> 7.83 | D64: =+F8 -> 31.284284

Sheet 1982-1988
A1: =+GCF_2019_I_pusm!A1 -> 43646 | C1: Grįžti į pagrindinį puslapį | D1: =+GCF_2019_I_pusm!D1 -> Veiklos laikotarpis, metais | E1: =+GCF_2019_I_pusm!E1 -> Strategija | F1: =+GCF_2019_I_pusm!F1 -> Grynųjų aktyvų****** vertė, mln. Eur | G1: =+GCF_2019_I_pusm!G1 -> Dalyvių skaičius | I1: =+GCF_2019_I_pusm!I1 -> Grąža | J1: =+GCF_2019_I_pusm!J1 -> 0 | L1: =+GCF_2019_I_pusm!L1 -> Rizika *** | M1: =+GCF_2019_I_pusm!M1 -> 0
A2: =+GCF_2019_I_pusm!A2 -> Pensijų kaupimo bendrovės pavadinimas | B2: =+GCF_2019_I_pusm!B2 -> Fondo kodas | C2: =+GCF_2019_I_pusm!C2 -> Pensijų fondo pavadinimas | D2: =+GCF_2019_I_pusm!D2 -> 0 | E2: =+GCF_2019_I_pusm!E2 -> rizikingų aktyvų dalis fonde, proc. ***** | F2: =+GCF_2019_I_pusm!F2 -> 0 | G2: =+GCF_2019_I_pusm!G2 -> 0 | I2: =+GCF_2019_I_pusm!I2 -> vieneto vertės pokytis nuo metų pradžios, proc.* | J2: =+GCF_2019_I_pusm!J2 -> lyginamojo indekso vertės pokytis nuo metų pradžios, proc.** | L2: =+GCF_2019_I_pusm!L2 -> vieneto vertės standartinis nuokrypis, nuo metų pradžios, proc. | M2: =+GCF_2019_I_pusm!M2 -> lyginamojo indekso standartinis nuokrypis, nuo metų pradžios, proc.
A3: =+GCF_2019_I_pusm!A15 -> Tikslinės pensijų fondų dalyvių grupės pensijų fondai, 1982-1988 | G3: =+GCF_2019_I_pusm!G15 -> Svertinis vidurkis****: | I3: =+GCF_2019_I_pusm!I15 -> 12.301919 | J3: =+GCF_2019_I_pusm!J15 -> 14.400263
A4: =+GCF_2019_I_pusm!A16 -> Luminor investicijų valdymas UAB | B4: =+GCF_2019_I_pusm!B16 -> LMN-82/88 | C4: =+GCF_2019_I_pusm!C16 -> Luminor 1982–1988 tikslinės grupės pensijų fondas | D4: =+GCF_2019_I_pusm!D16 -> 0.49589041 | E4: =+GCF_2019_I_pusm!E16 -> 90 | F4: =+GCF_2019_I_pusm!F16 -> 49.946327 | G4: =+GCF_2019_I_pusm!G16 -> 24695 | I4: =+GCF_2019_I_pusm!I16 -> 12.56 | J4: =+GCF_2019_I_pusm!J16 -> 14.349 | L4: =+GCF_2019_I_pusm!L16 -> 8.7168219 | M4: =+GCF_2019_I_pusm!M16 -> 13.629772
A5: =+GCF_2019_I_pusm!A17 -> UAB „INVL Asset Management“ | B5: =+GCF_2019_I_pusm!B17 -> INV-82/88 | C5: =+GCF_2019_I_pusm!C17 -> INVL pensija 1982–1988 | D5: =+GCF_2019_I_pusm!D17 -> 0.49589041 | E5: =+GCF_2019_I_pusm!E17 -> 97 | F5: =+GCF_2019_I_pusm!F17 -> 91.930357 | G5: =+GCF_2019_I_pusm!G17 -> 37324 | I5: =+GCF_2019_I_pusm!I17 -> 11.52 | J5: =+GCF_2019_I_pusm!J17 -> 14.0587 | L5: =+GCF_2019_I_pusm!L17 -> 11.539279 | M5: =+GCF_2019_I_pusm!M17 -> 13.913715
A6: =+GCF_2019_I_pusm!A18 -> UAB „SEB investicijų valdymas“ | B6: =+GCF_2019_I_pusm!B18 -> SBN-82/88 | C6: =+GCF_2019_I_pusm!C18 -> SEB 1982–1988 metų tikslinės grupės pensijų kaupimo fondas | D6: =+GCF_2019_I_pusm!D18 -> 0.49589041 | E6: =+GCF_2019_I_pusm!E18 -> 98 | F6: =+GCF_2019_I_pusm!F18 -> 142.59913 | G6: =+GCF_2019_I_pusm!G18 -> 66332 | I6: =+GCF_2019_I_pusm!I18 -> 13.55 | J6: =+GCF_2019_I_pusm!J18 -> 14.5133 | L6: =+GCF_2019_I_pusm!L18 -> 12.469694 | M6: =+GCF_2019_I_pusm!M18 -> 13.536476
A7: =+GCF_2019_I_pusm!A19 -> UAB „Swedbank investicijų valdymas“ | B7: =+GCF_2019_I_pusm!B19 -> SWD-82/88 | C7: =+GCF_2019_I_pusm!C19 -> Swedbank pensija 1982–1988******* | D7: =+GCF_2019_I_pusm!D19 -> 0.49589041 | E7: =+GCF_2019_I_pusm!E19 -> 90 | F7: =+GCF_2019_I_pusm!F19 -> 186.41144 | G7: =+GCF_2019_I_pusm!G19 -> 100798 | I7: =+GCF_2019_I_pusm!I19 -> 13.257615 | J7: =+GCF_2019_I_pusm!J19 -> 14.274787 | L7: =+GCF_2019_I_pusm!L19 -> 12.562916 | M7: =+GCF_2019_I_pusm!M19 -> 13.202445
A8: =+GCF_2019_I_pusm!A20 -> UAGDPB „Aviva Lietuva“ | B8: =+GCF_2019_I_pusm!B20 -> AVI-82/88 | C8: =+GCF_2019_I_pusm!C20 -> Aviva Y1 1982–1988 tikslinės grupės pensijų fondas | D8: =+GCF_2019_I_pusm!D20 -> 0.49589041 | E8: =+GCF_2019_I_pusm!E20 -> 90 | F8: =+GCF_2019_I_pusm!F20 -> 70.213076 | G8: =+GCF_2019_I_pusm!G20 -> 41303 | I8: =+GCF_2019_I_pusm!I20 -> 8.07 | J8: =+GCF_2019_I_pusm!J20 -> 14.9875 | L8: =+GCF_2019_I_pusm!L20 -> 12.010846 | M8: =+GCF_2019_I_pusm!M20 -> 14.461534
A10: =+GCF_2019_I_pusm!A54 -> Pastaba: praeities rezultatai negarantuoja, kad tokie patys ar panašūs rezultatai bus ir ateityje. Įtakos 2019 m. pirmojo pusmečio pensijų fondų rezultatams galėjo turėti skirtingu laiku vykdytas turto perkėlimas į tikslinės grupės ir turto išsaugojimo pensijų fondus bei skirtingas fondų dydis nagrinėjamu laikotarpiu.
A11: =+GCF_2019_I_pusm!A55 -> * Apskaitos vieneto vertės pokytis. Juo atsižvelgiama į atskaitymus nuo turto.
A12: =+GCF_2019_I_pusm!A56 -> ** Lyginamasis indeksas apibrėžiamas kaip pensijų kaupimo bendrovės pasirinktas orientacinis investicijų portfelis, atitinkantis fondo investavimo strategiją, su kurio vertės pokyčio reikšme lyginama fondo investicijų portfelio investicijų grąža.
A13: =+GCF_2019_I_pusm!A57 -> *** Rodikliui apskaičiuoti naudoti mėnesiniai apskaitos vieneto (lyginamojo indekso) verčių pokyčiai, rezultatas perskaičiuotas į metinį. Standartinis nuokrypis parodo, kaip intensyviai per laikotarpį svyruoja fondo investicinio vieneto vertė (lyginamojo indekso vertė). Kuo šis rodiklis didesnis, tuo didesnė rizika.
A14: =+GCF_2019_I_pusm!A58 -> **** Svertiniam vidurkiui apskaičiuoti naudotas 2019-06-30 dienos fondų grynųjų aktyvų dydis.
A15: =+GCF_2019_I_pusm!A59 -> ***** Investicijų į akcijas dalis. Rizikingų turto klasių dalis gali būti padidinta arba sumažinta iki 10 procentinių punktų.
A16: =+GCF_2019_I_pusm!A60 -> ****** Grynieji aktyvai – pensijų fondą sudarančio turto ir įsipareigojimų verčių skirtumas.
A17: =+GCF_2019_I_pusm!A61 -> ******* Šie UAB „Swedbank investicijų valdymas“ valdomi pensijų fondai pradėjo veiklą 2018-03-01, tačiau dėl 2019 m. sausio mėnesį įsigaliojusios pensijų pertvarkos pagal galiojančius teisės aktus buvo įsteigti iš naujo, todėl jų rezultatai skaičiuojami nuo 2019 m. sausio 1 d. (kaip ir visų II pakopos pensijų fondų).
A19: =+'1996-2002'!A19 -> Rizikos ir grąžos palyginimas
A20: =+'1996-2002'!A20 -> Kuo pensijų fondas paveiksle vaizduojamas aukščiau, tuo jo uždirbama grąža yra didesnė. Kuo žemiau – tuo grąža mažesnė.
A21: =+'1996-2002'!A21 -> Dešiniau pavaizduoti pensijų fondai prisiima didesnę riziką (jų vieneto vertės svyruoja daugiau). Kairiau – mažesnę (jų vieneto vertės svyruoja mažiau).
A29: Fondas | B29: Rizika | C29: Grąža
A30: =+B4 -> LMN-82/88 | B30: =+L4 -> 8.7168219 | C30: =+I4 -> 12.56
A31: =+B5 -> INV-82/88 | B31: =+L5 -> 11.539279 | C31: =+I5 -> 11.52
A32: =+B6 -> SBN-82/88 | B32: =+L6 -> 12.469694 | C32: =+I6 -> 13.55
A33: =+B7 -> SWD-82/88 | B33: =+L7 -> 12.562916 | C33: =+I7 -> 13.257615
A34: =+B8 -> AVI-82/88 | B34: =+L8 -> 12.010846 | C34: =+I8 -> 8.07
A51: =+'1996-2002'!A51 -> Dalyvių skaičiaus, grąžos ir fondo turto palyginimas
A52: =+'1996-2002'!A52 -> Kuo pensijų fondas paveiksle pavaizduotas aukščiau, tuo jo uždirbama grąža yra didesnė. Kuo žemiau – tuo grąža mažesnė.
A53: =+'1996-2002'!A53 -> Dešiniau pavaizduoti pensijų fondai turi daugiau dalyvių. Kairiau – mažiau.
A54: =+'1996-2002'!A54 -> Kuo didesnis fondą vaizduojančio skritulio dydis – tuo fondas turi daugiau turto. Kuo mažesnis – mažiau.
A59: Fondas | B59: Dalyvių sk. (tūkst.) | C59: Grąža (proc.) | D59: Fondo turtas (mln. Eur)
A60: =+B4 -> LMN-82/88 | B60: =+G4/1000 -> 24.695 | C60: =+I4 -> 12.56 | D60: =+F4 -> 49.946327
A61: =+B5 -> INV-82/88 | B61: =+G5/1000 -> 37.324 | C61: =+I5 -> 11.52 | D61: =+F5 -> 91.930357
A62: =+B6 -> SBN-82/88 | B62: =+G6/1000 -> 66.332 | C62: =+I6 -> 13.55 | D62: =+F6 -> 142.59913
A63: =+B7 -> SWD-82/88 | B63: =+G7/1000 -> 100.798 | C63: =+I7 -> 13.257615 | D63: =+F7 -> 186.41144
A64: =+B8 -> AVI-82/88 | B64: =+G8/1000 -> 41.303 | C64: =+I8 -> 8.07 | D64: =+F8 -> 70.213076

Sheet 1975-1981
A1: =+GCF_2019_I_pusm!A1 -> 43646 | C1: Grįžti į pagrindinį puslapį | D1: =+GCF_2019_I_pusm!D1 -> Veiklos laikotarpis, metais | E1: =+GCF_2019_I_pusm!E1 -> Strategija | F1: =+GCF_2019_I_pusm!F1 -> Grynųjų aktyvų****** vertė, mln. Eur | G1: =+GCF_2019_I_pusm!G1 -> Dalyvių skaičius | I1: =+GCF_2019_I_pusm!I1 -> Grąža | J1: =+GCF_2019_I_pusm!J1 -> 0 | L1: =+GCF_2019_I_pusm!L1 -> Rizika *** | M1: =+GCF_2019_I_pusm!M1 -> 0
A2: =+GCF_2019_I_pusm!A2 -> Pensijų kaupimo bendrovės pavadinimas | B2: =+GCF_2019_I_pusm!B2 -> Fondo kodas | C2: =+GCF_2019_I_pusm!C2 -> Pensijų fondo pavadinimas | D2: =+GCF_2019_I_pusm!D2 -> 0 | E2: =+GCF_2019_I_pusm!E2 -> rizikingų aktyvų dalis fonde, proc. ***** | F2: =+GCF_2019_I_pusm!F2 -> 0 | G2: =+GCF_2019_I_pusm!G2 -> 0 | I2: =+GCF_2019_I_pusm!I2 -> vieneto vertės pokytis nuo metų pradžios, proc.* | J2: =+GCF_2019_I_pusm!J2 -> lyginamojo indekso vertės pokytis nuo metų pradžios, proc.** | L2: =+GCF_2019_I_pusm!L2 -> vieneto vertės standartinis nuokrypis, nuo metų pradžios, proc. | M2: =+GCF_2019_I_pusm!M2 -> lyginamojo indekso standartinis nuokrypis, nuo metų pradžios, proc.
A3: =+GCF_2019_I_pusm!A21 -> Tikslinės pensijų fondų dalyvių grupės pensijų fondai, 1975-1981 | G3: =+GCF_2019_I_pusm!G21 -> Svertinis vidurkis****: | I3: =+GCF_2019_I_pusm!I21 -> 13.035929 | J3: =+GCF_2019_I_pusm!J21 -> 15.298515
A4: =+GCF_2019_I_pusm!A22 -> Luminor investicijų valdymas UAB | B4: =+GCF_2019_I_pusm!B22 -> LMN-75/81 | C4: =+GCF_2019_I_pusm!C22 -> Luminor 1975–1981 tikslinės grupės pensijų fondas | D4: =+GCF_2019_I_pusm!D22 -> 0.49589041 | E4: =+GCF_2019_I_pusm!E22 -> 90 | F4: =+GCF_2019_I_pusm!F22 -> 70.33041 | G4: =+GCF_2019_I_pusm!G22 -> 22441 | I4: =+GCF_2019_I_pusm!I22 -> 12.18 | J4: =+GCF_2019_I_pusm!J22 -> 14.349 | L4: =+GCF_2019_I_pusm!L22 -> 8.1280418 | M4: =+GCF_2019_I_pusm!M22 -> 13.629772
A5: =+GCF_2019_I_pusm!A23 -> UAB „INVL Asset Management“ | B5: =+GCF_2019_I_pusm!B23 -> INV-75/81 | C5: =+GCF_2019_I_pusm!C23 -> INVL pensija 1975–1981 | D5: =+GCF_2019_I_pusm!D23 -> 0.49589041 | E5: =+GCF_2019_I_pusm!E23 -> 97 | F5: =+GCF_2019_I_pusm!F23 -> 109.96911 | G5: =+GCF_2019_I_pusm!G23 -> 24964 | I5: =+GCF_2019_I_pusm!I23 -> 12.08 | J5: =+GCF_2019_I_pusm!J23 -> 14.0587 | L5: =+GCF_2019_I_pusm!L23 -> 11.917257 | M5: =+GCF_2019_I_pusm!M23 -> 13.913715
A6: =+GCF_2019_I_pusm!A24 -> UAB „SEB investicijų valdymas“ | B6: =+GCF_2019_I_pusm!B24 -> SBN-75/81 | C6: =+GCF_2019_I_pusm!C24 -> SEB 1975–1981 metų tikslinės grupės pensijų kaupimo fondas | D6: =+GCF_2019_I_pusm!D24 -> 0.49589041 | E6: =+GCF_2019_I_pusm!E24 -> 98 | F6: =+GCF_2019_I_pusm!F24 -> 213.10218 | G6: =+GCF_2019_I_pusm!G24 -> 60091 | I6: =+GCF_2019_I_pusm!I24 -> 15.97 | J6: =+GCF_2019_I_pusm!J24 -> 17.7318 | L6: =+GCF_2019_I_pusm!L24 -> 14.233434 | M6: =+GCF_2019_I_pusm!M24 -> 15.810854
A7: =+GCF_2019_I_pusm!A25 -> UAB „Swedbank investicijų valdymas“ | B7: =+GCF_2019_I_pusm!B25 -> SWD-75/81 | C7: =+GCF_2019_I_pusm!C25 -> Swedbank pensija 1975–1981******* | D7: =+GCF_2019_I_pusm!D25 -> 0.49589041 | E7: =+GCF_2019_I_pusm!E25 -> 90 | F7: =+GCF_2019_I_pusm!F25 -> 277.35841 | G7: =+GCF_2019_I_pusm!G25 -> 95386 | I7: =+GCF_2019_I_pusm!I25 -> 13.291925 | J7: =+GCF_2019_I_pusm!J25 -> 14.274787 | L7: =+GCF_2019_I_pusm!L25 -> 12.607081 | M7: =+GCF_2019_I_pusm!M25 -> 13.202445
A8: =+GCF_2019_I_pusm!A26 -> UAGDPB „Aviva Lietuva“ | B8: =+GCF_2019_I_pusm!B26 -> AVI-75/81 | C8: =+GCF_2019_I_pusm!C26 -> Aviva X3 1975–1981 tikslinės grupės pensijų fondas | D8: =+GCF_2019_I_pusm!D26 -> 0.49589041 | E8: =+GCF_2019_I_pusm!E26 -> 90 | F8: =+GCF_2019_I_pusm!F26 -> 101.20975 | G8: =+GCF_2019_I_pusm!G26 -> 39048 | I8: =+GCF_2019_I_pusm!I26 -> 7.79 | J8: =+GCF_2019_I_pusm!J26 -> 14.9875 | L8: =+GCF_2019_I_pusm!L26 -> 12.008808 | M8: =+GCF_2019_I_pusm!M26 -> 14.461534
A10: =+GCF_2019_I_pusm!A54 -> Pastaba: praeities rezultatai negarantuoja, kad tokie patys ar panašūs rezultatai bus ir ateityje. Įtakos 2019 m. pirmojo pusmečio pensijų fondų rezultatams galėjo turėti skirtingu laiku vykdytas turto perkėlimas į tikslinės grupės ir turto išsaugojimo pensijų fondus bei skirtingas fondų dydis nagrinėjamu laikotarpiu.
A11: =+GCF_2019_I_pusm!A55 -> * Apskaitos vieneto vertės pokytis. Juo atsižvelgiama į atskaitymus nuo turto.
A12: =+GCF_2019_I_pusm!A56 -> ** Lyginamasis indeksas apibrėžiamas kaip pensijų kaupimo bendrovės pasirinktas orientacinis investicijų portfelis, atitinkantis fondo investavimo strategiją, su kurio vertės pokyčio reikšme lyginama fondo investicijų portfelio investicijų grąža.
A13: =+GCF_2019_I_pusm!A57 -> *** Rodikliui apskaičiuoti naudoti mėnesiniai apskaitos vieneto (lyginamojo indekso) verčių pokyčiai, rezultatas perskaičiuotas į metinį. Standartinis nuokrypis parodo, kaip intensyviai per laikotarpį svyruoja fondo investicinio vieneto vertė (lyginamojo indekso vertė). Kuo šis rodiklis didesnis, tuo didesnė rizika.
A14: =+GCF_2019_I_pusm!A58 -> **** Svertiniam vidurkiui apskaičiuoti naudotas 2019-06-30 dienos fondų grynųjų aktyvų dydis.
A15: =+GCF_2019_I_pusm!A59 -> ***** Investicijų į akcijas dalis. Rizikingų turto klasių dalis gali būti padidinta arba sumažinta iki 10 procentinių punktų.
A16: =+GCF_2019_I_pusm!A60 -> ****** Grynieji aktyvai – pensijų fondą sudarančio turto ir įsipareigojimų verčių skirtumas.
A17: =+GCF_2019_I_pusm!A61 -> ******* Šie UAB „Swedbank investicijų valdymas“ valdomi pensijų fondai pradėjo veiklą 2018-03-01, tačiau dėl 2019 m. sausio mėnesį įsigaliojusios pensijų pertvarkos pagal galiojančius teisės aktus buvo įsteigti iš naujo, todėl jų rezultatai skaičiuojami nuo 2019 m. sausio 1 d. (kaip ir visų II pakopos pensijų fondų).
A19: =+'1996-2002'!A19 -> Rizikos ir grąžos palyginimas
A20: =+'1996-2002'!A20 -> Kuo pensijų fondas paveiksle vaizduojamas aukščiau, tuo jo uždirbama grąža yra didesnė. Kuo žemiau – tuo grąža mažesnė.
A21: =+'1996-2002'!A21 -> Dešiniau pavaizduoti pensijų fondai prisiima didesnę riziką (jų vieneto vertės svyruoja daugiau). Kairiau – mažesnę (jų vieneto vertės svyruoja mažiau).
A29: Fondas | B29: Rizika | C29: Grąža
A30: =+B4 -> LMN-75/81 | B30: =+L4 -> 8.1280418 | C30: =+I4 -> 12.18
A31: =+B5 -> INV-75/81 | B31: =+L5 -> 11.917257 | C31: =+I5 -> 12.08
A32: =+B6 -> SBN-75/81 | B32: =+L6 -> 14.233434 | C32: =+I6 -> 15.97
A33: =+B7 -> SWD-75/81 | B33: =+L7 -> 12.607081 | C33: =+I7 -> 13.291925
A34: =+B8 -> AVI-75/81 | B34: =+L8 -> 12.008808 | C34: =+I8 -> 7.79
A51: =+'1996-2002'!A51 -> Dalyvių skaičiaus, grąžos ir fondo turto palyginimas
A52: =+'1996-2002'!A52 -> Kuo pensijų fondas paveiksle pavaizduotas aukščiau, tuo jo uždirbama grąža yra didesnė. Kuo žemiau – tuo grąža mažesnė.
A53: =+'1996-2002'!A53 -> Dešiniau pavaizduoti pensijų fondai turi daugiau dalyvių. Kairiau – mažiau.
A54: =+'1996-2002'!A54 -> Kuo didesnis fondą vaizduojančio skritulio dydis – tuo fondas turi daugiau turto. Kuo mažesnis – mažiau.
A59: Fondas | B59: Dalyvių sk. (tūkst.) | C59: Grąža (proc.) | D59: Fondo turtas (mln. Eur)
A60: =+B5 -> INV-75/81 | B60: =+G5/1000 -> 24.964 | C60: =+I5 -> 12.08 | D60: =+F5 -> 109.96911
A61: =+B4 -> LMN-75/81 | B61: =+G4/1000 -> 22.441 | C61: =+I4 -> 12.18 | D61: =+F4 -> 70.33041
A62: =+B6 -> SBN-75/81 | B62: =+G6/1000 -> 60.091 | C62: =+I6 -> 15.97 | D62: =+F6 -> 213.10218
A63: =+B7 -> SWD-75/81 | B63: =+G7/1000 -> 95.386 | C63: =+I7 -> 13.291925 | D63: =+F7 -> 277.35841
A64: =+B8 -> AVI-75/81 | B64: =+G8/1000 -> 39.048 | C64: =+I8 -> 7.79 | D64: =+F8 -> 101.20975

Sheet 1968-1974
A1: =+GCF_2019_I_pusm!A1 -> 43646 | C1: Grįžti į pagrindinį puslapį | D1: =+GCF_2019_I_pusm!D1 -> Veiklos laikotarpis, metais | E1: =+GCF_2019_I_pusm!E1 -> Strategija | F1: =+GCF_2019_I_pusm!F1 -> Grynųjų aktyvų****** vertė, mln. Eur | G1: =+GCF_2019_I_pusm!G1 -> Dalyvių skaičius | I1: =+GCF_2019_I_pusm!I1 -> Grąža | J1: =+GCF_2019_I_pusm!J1 -> 0 | L1: =+GCF_2019_I_pusm!L1 -> Rizika *** | M1: =+GCF_2019_I_pusm!M1 -> 0
A2: =+GCF_2019_I_pusm!A2 -> Pensijų kaupimo bendrovės pavadinimas | B2: =+GCF_2019_I_pusm!B2 -> Fondo kodas | C2: =+GCF_2019_I_pusm!C2 -> Pensijų fondo pavadinimas | D2: =+GCF_2019_I_pusm!D2 -> 0 | E2: =+GCF_2019_I_pusm!E2 -> rizikingų aktyvų dalis fonde, proc. ***** | F2: =+GCF_2019_I_pusm!F2 -> 0 | G2: =+GCF_2019_I_pusm!G2 -> 0 | I2: =+GCF_2019_I_pusm!I2 -> vieneto vertės pokytis nuo metų pradžios, proc.* | J2: =+GCF_2019_I_pusm!J2 -> lyginamojo indekso vertės pokytis nuo metų pradžios, proc.** | L2: =+GCF_2019_I_pusm!L2 -> vieneto vertės standartinis nuokrypis, nuo metų pradžios, proc. | M2: =+GCF_2019_I_pusm!M2 -> lyginamojo indekso standartinis nuokrypis, nuo metų pradžios, proc.
A3: =+GCF_2019_I_pusm!A27 -> Tikslinės pensijų fondų dalyvių grupės pensijų fondai, 1968-1974 | G3: =+GCF_2019_I_pusm!G27 -> Svertinis vidurkis****: | I3: =+GCF_2019_I_pusm!I27 -> 12.090327 | J3: =+GCF_2019_I_pusm!J27 -> 14.139456
A4: =+GCF_2019_I_pusm!A28 -> Luminor investicijų valdymas UAB | B4: =+GCF_2019_I_pusm!B28 -> LMN-68/74 | C4: =+GCF_2019_I_pusm!C28 -> Luminor 1968–1974 tikslinės grupės pensijų fondas | D4: =+GCF_2019_I_pusm!D28 -> 0.49589041 | E4: =+GCF_2019_I_pusm!E28 -> 90 | F4: =+GCF_2019_I_pusm!F28 -> 74.372099 | G4: =+GCF_2019_I_pusm!G28 -> 22406 | I4: =+GCF_2019_I_pusm!I28 -> 12.72 | J4: =+GCF_2019_I_pusm!J28 -> 14.349 | L4: =+GCF_2019_I_pusm!L28 -> 8.2566888 | M4: =+GCF_2019_I_pusm!M28 -> 13.629772
A5: =+GCF_2019_I_pusm!A29 -> UAB „INVL Asset Management“ | B5: =+GCF_2019_I_pusm!B29 -> INV-68/74 | C5: =+GCF_2019_I_pusm!C29 -> INVL pensija 1968–1974 | D5: =+GCF_2019_I_pusm!D29 -> 0.49589041 | E5: =+GCF_2019_I_pusm!E29 -> 89 | F5: =+GCF_2019_I_pusm!F29 -> 103.64374 | G5: =+GCF_2019_I_pusm!G29 -> 22602 | I5: =+GCF_2019_I_pusm!I29 -> 12.02 | J5: =+GCF_2019_I_pusm!J29 -> 14.1045 | L5: =+GCF_2019_I_pusm!L29 -> 11.38819 | M5: =+GCF_2019_I_pusm!M29 -> 13.416322
A6: =+GCF_2019_I_pusm!A30 -> UAB „SEB investicijų valdymas“ | B6: =+GCF_2019_I_pusm!B30 -> SBN-68/74 | C6: =+GCF_2019_I_pusm!C30 -> SEB 1968–1974 metų tikslinės grupės pensijų kaupimo fondas | D6: =+GCF_2019_I_pusm!D30 -> 0.49589041 | E6: =+GCF_2019_I_pusm!E30 -> 92.9 | F6: =+GCF_2019_I_pusm!F30 -> 205.25631 | G6: =+GCF_2019_I_pusm!G30 -> 52661 | I6: =+GCF_2019_I_pusm!I30 -> 13.32 | J6: =+GCF_2019_I_pusm!J30 -> 14.0519 | L6: =+GCF_2019_I_pusm!L30 -> 12.358478 | M6: =+GCF_2019_I_pusm!M30 -> 12.876623
A7: =+GCF_2019_I_pusm!A31 -> UAB „Swedbank investicijų valdymas“ | B7: =+GCF_2019_I_pusm!B31 -> SWD-68/74 | C7: =+GCF_2019_I_pusm!C31 -> Swedbank pensija 1968–1974******* | D7: =+GCF_2019_I_pusm!D31 -> 0.49589041 | E7: =+GCF_2019_I_pusm!E31 -> 90 | F7: =+GCF_2019_I_pusm!F31 -> 297.90277 | G7: =+GCF_2019_I_pusm!G31 -> 95031 | I7: =+GCF_2019_I_pusm!I31 -> 13.330582 | J7: =+GCF_2019_I_pusm!J31 -> 14.274787 | L7: =+GCF_2019_I_pusm!L31 -> 12.643298 | M7: =+GCF_2019_I_pusm!M31 -> 13.202445
A8: =+GCF_2019_I_pusm!A32 -> UAGDPB „Aviva Lietuva“ | B8: =+GCF_2019_I_pusm!B32 -> AVI-68/74 | C8: =+GCF_2019_I_pusm!C32 -> Aviva X2 1968–1974 tikslinės grupės pensijų fondas | D8: =+GCF_2019_I_pusm!D32 -> 0.49589041 | E8: =+GCF_2019_I_pusm!E32 -> 83 | F8: =+GCF_2019_I_pusm!F32 -> 121.80008 | G8: =+GCF_2019_I_pusm!G32 -> 41303 | I8: =+GCF_2019_I_pusm!I32 -> 6.66 | J8: =+GCF_2019_I_pusm!J32 -> 13.8578 | L8: =+GCF_2019_I_pusm!L32 -> 11.042237 | M8: =+GCF_2019_I_pusm!M32 -> 13.343421
A10: =+GCF_2019_I_pusm!A54 -> Pastaba: praeities rezultatai negarantuoja, kad tokie patys ar panašūs rezultatai bus ir ateityje. Įtakos 2019 m. pirmojo pusmečio pensijų fondų rezultatams galėjo turėti skirtingu laiku vykdytas turto perkėlimas į tikslinės grupės ir turto išsaugojimo pensijų fondus bei skirtingas fondų dydis nagrinėjamu laikotarpiu.
A11: =+GCF_2019_I_pusm!A55 -> * Apskaitos vieneto vertės pokytis. Juo atsižvelgiama į atskaitymus nuo turto.
A12: =+GCF_2019_I_pusm!A56 -> ** Lyginamasis indeksas apibrėžiamas kaip pensijų kaupimo bendrovės pasirinktas orientacinis investicijų portfelis, atitinkantis fondo investavimo strategiją, su kurio vertės pokyčio reikšme lyginama fondo investicijų portfelio investicijų grąža.
A13: =+GCF_2019_I_pusm!A57 -> *** Rodikliui apskaičiuoti naudoti mėnesiniai apskaitos vieneto (lyginamojo indekso) verčių pokyčiai, rezultatas perskaičiuotas į metinį. Standartinis nuokrypis parodo, kaip intensyviai per laikotarpį svyruoja fondo investicinio vieneto vertė (lyginamojo indekso vertė). Kuo šis rodiklis didesnis, tuo didesnė rizika.
A14: =+GCF_2019_I_pusm!A58 -> **** Svertiniam vidurkiui apskaičiuoti naudotas 2019-06-30 dienos fondų grynųjų aktyvų dydis.
A15: =+GCF_2019_I_pusm!A59 -> ***** Investicijų į akcijas dalis. Rizikingų turto klasių dalis gali būti padidinta arba sumažinta iki 10 procentinių punktų.
A16: =+GCF_2019_I_pusm!A60 -> ****** Grynieji aktyvai – pensijų fondą sudarančio turto ir įsipareigojimų verčių skirtumas.
A17: =+GCF_2019_I_pusm!A61 -> ******* Šie UAB „Swedbank investicijų valdymas“ valdomi pensijų fondai pradėjo veiklą 2018-03-01, tačiau dėl 2019 m. sausio mėnesį įsigaliojusios pensijų pertvarkos pagal galiojančius teisės aktus buvo įsteigti iš naujo, todėl jų rezultatai skaičiuojami nuo 2019 m. sausio 1 d. (kaip ir visų II pakopos pensijų fondų).
A19: =+'1996-2002'!A19 -> Rizikos ir grąžos palyginimas
A20: =+'1996-2002'!A20 -> Kuo pensijų fondas paveiksle vaizduojamas aukščiau, tuo jo uždirbama grąža yra didesnė. Kuo žemiau – tuo grąža mažesnė.
A21: =+'1996-2002'!A21 -> Dešiniau pavaizduoti pensijų fondai prisiima didesnę riziką (jų vieneto vertės svyruoja daugiau). Kairiau – mažesnę (jų vieneto vertės svyruoja mažiau).
A29: Fondas | B29: Rizika | C29: Grąža
A30: =+B4 -> LMN-68/74 | B30: =+L4 -> 8.2566888 | C30: =+I4 -> 12.72
A31: =+B5 -> INV-68/74 | B31: =+L5 -> 11.38819 | C31: =+I5 -> 12.02
A32: =+B6 -> SBN-68/74 | B32: =+L6 -> 12.358478 | C32: =+I6 -> 13.32
A33: =+B7 -> SWD-68/74 | B33: =+L7 -> 12.643298 | C33: =+I7 -> 13.330582
A34: =+B8 -> AVI-68/74 | B34: =+L8 -> 11.042237 | C34: =+I8 -> 6.66
A51: =+'1996-2002'!A51 -> Dalyvių skaičiaus, grąžos ir fondo turto palyginimas
A52: =+'1996-2002'!A52 -> Kuo pensijų fondas paveiksle pavaizduotas aukščiau, tuo jo uždirbama grąža yra didesnė. Kuo žemiau – tuo grąža mažesnė.
A53: =+'1996-2002'!A53 -> Dešiniau pavaizduoti pensijų fondai turi daugiau dalyvių. Kairiau – mažiau.
A54: =+'1996-2002'!A54 -> Kuo didesnis fondą vaizduojančio skritulio dydis – tuo fondas turi daugiau turto. Kuo mažesnis – mažiau.
A59: Fondas | B59: Dalyvių sk. (tūkst.) | C59: Grąža (proc.) | D59: Fondo turtas (mln. Eur)
A60: =+B5 -> INV-68/74 | B60: =+G5/1000 -> 22.602 | C60: =+I5 -> 12.02 | D60: =+F5 -> 103.64374
A61: =+B4 -> LMN-68/74 | B61: =+G4/1000 -> 22.406 | C61: =+I4 -> 12.72 | D61: =+F4 -> 74.372099
A62: =+B6 -> SBN-68/74 | B62: =+G6/1000 -> 52.661 | C62: =+I6 -> 13.32 | D62: =+F6 -> 205.25631
A63: =+B7 -> SWD-68/74 | B63: =+G7/1000 -> 95.031 | C63: =+I7 -> 13.330582 | D63: =+F7 -> 297.90277
A64: =+B8 -> AVI-68/74 | B64: =+G8/1000 -> 41.303 | C64: =+I8 -> 6.66 | D64: =+F8 -> 121.80008

Sheet 1961-1967
A1: =+GCF_2019_I_pusm!A1 -> 43646 | C1: Grįžti į pagrindinį puslapį | D1: =+GCF_2019_I_pusm!D1 -> Veiklos laikotarpis, metais | E1: =+GCF_2019_I_pusm!E1 -> Strategija | F1: =+GCF_2019_I_pusm!F1 -> Grynųjų aktyvų****** vertė, mln. Eur | G1: =+GCF_2019_I_pusm!G1 -> Dalyvių skaičius | I1: =+GCF_2019_I_pusm!I1 -> Grąža | J1: =+GCF_2019_I_pusm!J1 -> 0 | L1: =+GCF_2019_I_pusm!L1 -> Rizika *** | M1: =+GCF_2019_I_pusm!M1 -> 0
A2: =+GCF_2019_I_pusm!A2 -> Pensijų kaupimo bendrovės pavadinimas | B2: =+GCF_2019_I_pusm!B2 -> Fondo kodas | C2: =+GCF_2019_I_pusm!C2 -> Pensijų fondo pavadinimas | D2: =+GCF_2019_I_pusm!D2 -> 0 | E2: =+GCF_2019_I_pusm!E2 -> rizikingų aktyvų dalis fonde, proc. ***** | F2: =+GCF_2019_I_pusm!F2 -> 0 | G2: =+GCF_2019_I_pusm!G2 -> 0 | I2: =+GCF_2019_I_pusm!I2 -> vieneto vertės pokytis nuo metų pradžios, proc.* | J2: =+GCF_2019_I_pusm!J2 -> lyginamojo indekso vertės pokytis nuo metų pradžios, proc.** | L2: =+GCF_2019_I_pusm!L2 -> vieneto vertės standartinis nuokrypis, nuo metų pradžios, proc. | M2: =+GCF_2019_I_pusm!M2 -> lyginamojo indekso standartinis nuokrypis, nuo metų pradžios, proc.
A3: =+GCF_2019_I_pusm!A33 -> Tikslinės pensijų fondų dalyvių grupės pensijų fondai, 1961-1967 | G3: =+GCF_2019_I_pusm!G33 -> Svertinis vidurkis****: | I3: =+GCF_2019_I_pusm!I33 -> 8.6872972 | J3: =+GCF_2019_I_pusm!J33 -> 10.362563
A4: =+GCF_2019_I_pusm!A34 -> Luminor investicijų valdymas UAB | B4: =+GCF_2019_I_pusm!B34 -> LMN-61/67 | C4: =+GCF_2019_I_pusm!C34 -> Luminor 1961–1967 tikslinės grupės pensijų fondas | D4: =+GCF_2019_I_pusm!D34 -> 0.49589041 | E4: =+GCF_2019_I_pusm!E34 -> 60 | F4: =+GCF_2019_I_pusm!F34 -> 68.052967 | G4: =+GCF_2019_I_pusm!G34 -> 20585 | I4: =+GCF_2019_I_pusm!I34 -> 9.46 | J4: =+GCF_2019_I_pusm!J34 -> 11.7499 | L4: =+GCF_2019_I_pusm!L34 -> 5.9337929 | M4: =+GCF_2019_I_pusm!M34 -> 9.3467927
A5: =+GCF_2019_I_pusm!A35 -> UAB „INVL Asset Management“ | B5: =+GCF_2019_I_pusm!B35 -> INV-61/67 | C5: =+GCF_2019_I_pusm!C35 -> INVL pensija 1961–1967 | D5: =+GCF_2019_I_pusm!D35 -> 0.49589041 | E5: =+GCF_2019_I_pusm!E35 -> 54 | F5: =+GCF_2019_I_pusm!F35 -> 78.231147 | G5: =+GCF_2019_I_pusm!G35 -> 18230 | I5: =+GCF_2019_I_pusm!I35 -> 8.86 | J5: =+GCF_2019_I_pusm!J35 -> 10.167 | L5: =+GCF_2019_I_pusm!L35 -> 7.0045938 | M5: =+GCF_2019_I_pusm!M35 -> 8.5709418
A6: =+GCF_2019_I_pusm!A36 -> UAB „SEB investicijų valdymas“ | B6: =+GCF_2019_I_pusm!B36 -> SBN-61/67 | C6: =+GCF_2019_I_pusm!C36 -> SEB 1961–1967 metų tikslinės grupės pensijų kaupimo fondas | D6: =+GCF_2019_I_pusm!D36 -> 0.49589041 | E6: =+GCF_2019_I_pusm!E36 -> 58.5 | F6: =+GCF_2019_I_pusm!F36 -> 181.86018 | G6: =+GCF_2019_I_pusm!G36 -> 46666 | I6: =+GCF_2019_I_pusm!I36 -> 9.58 | J6: =+GCF_2019_I_pusm!J36 -> 10.9504 | L6: =+GCF_2019_I_pusm!L36 -> 8.065854 | M6: =+GCF_2019_I_pusm!M36 -> 8.5639744
A7: =+GCF_2019_I_pusm!A37 -> UAB „Swedbank investicijų valdymas“ | B7: =+GCF_2019_I_pusm!B37 -> SWD-61/67 | C7: =+GCF_2019_I_pusm!C37 -> Swedbank pensija 1961–1967******* | D7: =+GCF_2019_I_pusm!D37 -> 0.49589041 | E7: =+GCF_2019_I_pusm!E37 -> 60 | F7: =+GCF_2019_I_pusm!F37 -> 263.13295 | G7: =+GCF_2019_I_pusm!G37 -> 84692 | I7: =+GCF_2019_I_pusm!I37 -> 9.5918367 | J7: =+GCF_2019_I_pusm!J37 -> 10.988503 | L7: =+GCF_2019_I_pusm!L37 -> 8.7057335 | M7: =+GCF_2019_I_pusm!M37 -> 9.0485297
A8: =+GCF_2019_I_pusm!A38 -> UAGDPB „Aviva Lietuva“ | B8: =+GCF_2019_I_pusm!B38 -> AVI-61/67 | C8: =+GCF_2019_I_pusm!C38 -> Aviva X1 1961–1967 tikslinės grupės pensijų fondas | D8: =+GCF_2019_I_pusm!D38 -> 0.49589041 | E8: =+GCF_2019_I_pusm!E38 -> 43 | F8: =+GCF_2019_I_pusm!F38 -> 124.14688 | G8: =+GCF_2019_I_pusm!G38 -> 39616 | I8: =+GCF_2019_I_pusm!I38 -> 4.93 | J8: =+GCF_2019_I_pusm!J38 -> 7.5375 | L8: =+GCF_2019_I_pusm!L38 -> 5.8826533 | M8: =+GCF_2019_I_pusm!M38 -> 6.9774488
A10: =+GCF_2019_I_pusm!A54 -> Pastaba: praeities rezultatai negarantuoja, kad tokie patys ar panašūs rezultatai bus ir ateityje. Įtakos 2019 m. pirmojo pusmečio pensijų fondų rezultatams galėjo turėti skirtingu laiku vykdytas turto perkėlimas į tikslinės grupės ir turto išsaugojimo pensijų fondus bei skirtingas fondų dydis nagrinėjamu laikotarpiu.
A11: =+GCF_2019_I_pusm!A55 -> * Apskaitos vieneto vertės pokytis. Juo atsižvelgiama į atskaitymus nuo turto.
A12: =+GCF_2019_I_pusm!A56 -> ** Lyginamasis indeksas apibrėžiamas kaip pensijų kaupimo bendrovės pasirinktas orientacinis investicijų portfelis, atitinkantis fondo investavimo strategiją, su kurio vertės pokyčio reikšme lyginama fondo investicijų portfelio investicijų grąža.
A13: =+GCF_2019_I_pusm!A57 -> *** Rodikliui apskaičiuoti naudoti mėnesiniai apskaitos vieneto (lyginamojo indekso) verčių pokyčiai, rezultatas perskaičiuotas į metinį. Standartinis nuokrypis parodo, kaip intensyviai per laikotarpį svyruoja fondo investicinio vieneto vertė (lyginamojo indekso vertė). Kuo šis rodiklis didesnis, tuo didesnė rizika.
A14: =+GCF_2019_I_pusm!A58 -> **** Svertiniam vidurkiui apskaičiuoti naudotas 2019-06-30 dienos fondų grynųjų aktyvų dydis.
A15: =+GCF_2019_I_pusm!A59 -> ***** Investicijų į akcijas dalis. Rizikingų turto klasių dalis gali būti padidinta arba sumažinta iki 10 procentinių punktų.
A16: =+GCF_2019_I_pusm!A60 -> ****** Grynieji aktyvai – pensijų fondą sudarančio turto ir įsipareigojimų verčių skirtumas.
A17: =+GCF_2019_I_pusm!A61 -> ******* Šie UAB „Swedbank investicijų valdymas“ valdomi pensijų fondai pradėjo veiklą 2018-03-01, tačiau dėl 2019 m. sausio mėnesį įsigaliojusios pensijų pertvarkos pagal galiojančius teisės aktus buvo įsteigti iš naujo, todėl jų rezultatai skaičiuojami nuo 2019 m. sausio 1 d. (kaip ir visų II pakopos pensijų fondų).
A19: =+'1996-2002'!A19 -> Rizikos ir grąžos palyginimas
A20: =+'1996-2002'!A20 -> Kuo pensijų fondas paveiksle vaizduojamas aukščiau, tuo jo uždirbama grąža yra didesnė. Kuo žemiau – tuo grąža mažesnė.
A21: =+'1996-2002'!A21 -> Dešiniau pavaizduoti pensijų fondai prisiima didesnę riziką (jų vieneto vertės svyruoja daugiau). Kairiau – mažesnę (jų vieneto vertės svyruoja mažiau).
A29: Fondas | B29: Rizika | C29: Grąža
A30: =+B4 -> LMN-61/67 | B30: =+L4 -> 5.9337929 | C30: =+I4 -> 9.46
A31: =+B5 -> INV-61/67 | B31: =+L5 -> 7.0045938 | C31: =+I5 -> 8.86
A32: =+B6 -> SBN-61/67 | B32: =+L6 -> 8.065854 | C32: =+I6 -> 9.58
A33: =+B7 -> SWD-61/67 | B33: =+L7 -> 8.7057335 | C33: =+I7 -> 9.5918367
A34: =+B8 -> AVI-61/67 | B34: =+L8 -> 5.8826533 | C34: =+I8 -> 4.93
A51: =+'1996-2002'!A51 -> Dalyvių skaičiaus, grąžos ir fondo turto palyginimas
A52: =+'1996-2002'!A52 -> Kuo pensijų fondas paveiksle pavaizduotas aukščiau, tuo jo uždirbama grąža yra didesnė. Kuo žemiau – tuo grąža mažesnė.
A53: =+'1996-2002'!A53 -> Dešiniau pavaizduoti pensijų fondai turi daugiau dalyvių. Kairiau – mažiau.
A54: =+'1996-2002'!A54 -> Kuo didesnis fondą vaizduojančio skritulio dydis – tuo fondas turi daugiau turto. Kuo mažesnis – mažiau.
A59: Fondas | B59: Dalyvių sk. (tūkst.) | C59: Grąža (proc.) | D59: Fondo turtas (mln. Eur)
A60: =+B4 -> LMN-61/67 | B60: =+G4/1000 -> 20.585 | C60: =+I4 -> 9.46 | D60: =+F4 -> 68.052967
A61: =+B5 -> INV-61/67 | B61: =+G5/1000 -> 18.23 | C61: =+I5 -> 8.86 | D61: =+F5 -> 78.231147
A62: =+B6 -> SBN-61/67 | B62: =+G6/1000 -> 46.666 | C62: =+I6 -> 9.58 | D62: =+F6 -> 181.86018
A63: =+B7 -> SWD-61/67 | B63: =+G7/1000 -> 84.692 | C63: =+I7 -> 9.5918367 | D63: =+F7 -> 263.13295
A64: =+B8 -> AVI-61/67 | B64: =+G8/1000 -> 39.616 | C64: =+I8 -> 4.93 | D64: =+F8 -> 124.14688

Sheet 1954-1960
